[2025-04-15T08:16:59.001+0000] {local_task_job_runner.py:123} INFO - ::group::Pre task execution logs
[2025-04-15T08:16:59.014+0000] {taskinstance.py:2612} INFO - Dependencies all met for dep_context=non-requeueable deps ti=<TaskInstance: StockELT_dbt.dbt_run manual__2025-04-15T08:16:58.024479+00:00 [queued]>
[2025-04-15T08:16:59.020+0000] {taskinstance.py:2612} INFO - Dependencies all met for dep_context=requeueable deps ti=<TaskInstance: StockELT_dbt.dbt_run manual__2025-04-15T08:16:58.024479+00:00 [queued]>
[2025-04-15T08:16:59.021+0000] {taskinstance.py:2865} INFO - Starting attempt 1 of 1
[2025-04-15T08:16:59.032+0000] {taskinstance.py:2888} INFO - Executing <Task(BashOperator): dbt_run> on 2025-04-15 08:16:58.024479+00:00
[2025-04-15T08:16:59.052+0000] {standard_task_runner.py:104} INFO - Running: ['***', 'tasks', 'run', 'StockELT_dbt', 'dbt_run', 'manual__2025-04-15T08:16:58.024479+00:00', '--job-id', '144', '--raw', '--subdir', 'DAGS_FOLDER/Lab2_elt_with_dbt .py', '--cfg-path', '/tmp/tmpmrgtjdwc']
[2025-04-15T08:16:59.057+0000] {standard_task_runner.py:105} INFO - Job 144: Subtask dbt_run
[2025-04-15T08:16:59.057+0000] {logging_mixin.py:190} WARNING - /home/***/.local/lib/python3.12/site-packages/***/task/task_runner/standard_task_runner.py:70 DeprecationWarning: This process (pid=1658) is multi-threaded, use of fork() may lead to deadlocks in the child.
[2025-04-15T08:16:59.059+0000] {standard_task_runner.py:72} INFO - Started process 1659 to run task
[2025-04-15T08:16:59.118+0000] {task_command.py:467} INFO - Running <TaskInstance: StockELT_dbt.dbt_run manual__2025-04-15T08:16:58.024479+00:00 [running]> on host 83ad2e5aff09
[2025-04-15T08:16:59.173+0000] {taskinstance.py:3131} INFO - Exporting env vars: AIRFLOW_CTX_DAG_OWNER='***' AIRFLOW_CTX_DAG_ID='StockELT_dbt' AIRFLOW_CTX_TASK_ID='dbt_run' AIRFLOW_CTX_EXECUTION_DATE='2025-04-15T08:16:58.024479+00:00' AIRFLOW_CTX_TRY_NUMBER='1' AIRFLOW_CTX_DAG_RUN_ID='manual__2025-04-15T08:16:58.024479+00:00'
[2025-04-15T08:16:59.173+0000] {taskinstance.py:731} INFO - ::endgroup::
[2025-04-15T08:16:59.187+0000] {subprocess.py:63} INFO - Tmp dir root location: /tmp
[2025-04-15T08:16:59.188+0000] {subprocess.py:75} INFO - Running command: ['/usr/bin/bash', '-c', '/home/***/.local/bin/dbt run --profiles-dir /opt/***/dbt_stock --project-dir /opt/***/dbt_stock']
[2025-04-15T08:16:59.194+0000] {subprocess.py:86} INFO - Output:
[2025-04-15T08:17:01.027+0000] {subprocess.py:93} INFO - [0m08:17:01  Running with dbt=1.8.7
[2025-04-15T08:17:01.793+0000] {subprocess.py:93} INFO - [0m08:17:01  Registered adapter: snowflake=1.8.4
[2025-04-15T08:17:01.968+0000] {subprocess.py:93} INFO - [0m08:17:01  Unable to do partial parsing because of a version mismatch
[2025-04-15T08:17:02.048+0000] {subprocess.py:93} INFO - [0m08:17:02  Encountered an error:
[2025-04-15T08:17:02.048+0000] {subprocess.py:93} INFO - Compilation Error
[2025-04-15T08:17:02.048+0000] {subprocess.py:93} INFO -   dbt found two macros named "snowflake__get_merge_sql" in the project
[2025-04-15T08:17:02.049+0000] {subprocess.py:93} INFO -   "dbt_snowflake".
[2025-04-15T08:17:02.049+0000] {subprocess.py:93} INFO -    To fix this error, rename or remove one of the following macros:
[2025-04-15T08:17:02.049+0000] {subprocess.py:93} INFO -       - macros/materializations/incremental/merge.sql
[2025-04-15T08:17:02.049+0000] {subprocess.py:93} INFO -       - macros/materializations/merge.sql
[2025-04-15T08:17:02.530+0000] {subprocess.py:93} INFO - Traceback (most recent call last):
[2025-04-15T08:17:02.531+0000] {subprocess.py:93} INFO -   File "/home/***/.local/lib/python3.12/site-packages/dbt/cli/requires.py", line 138, in wrapper
[2025-04-15T08:17:02.532+0000] {subprocess.py:93} INFO -     result, success = func(*args, **kwargs)
[2025-04-15T08:17:02.532+0000] {subprocess.py:93} INFO -                       ^^^^^^^^^^^^^^^^^^^^^
[2025-04-15T08:17:02.533+0000] {subprocess.py:93} INFO -   File "/home/***/.local/lib/python3.12/site-packages/dbt/cli/requires.py", line 101, in wrapper
[2025-04-15T08:17:02.533+0000] {subprocess.py:93} INFO -     return func(*args, **kwargs)
[2025-04-15T08:17:02.534+0000] {subprocess.py:93} INFO -            ^^^^^^^^^^^^^^^^^^^^^
[2025-04-15T08:17:02.534+0000] {subprocess.py:93} INFO -   File "/home/***/.local/lib/python3.12/site-packages/dbt/cli/requires.py", line 218, in wrapper
[2025-04-15T08:17:02.534+0000] {subprocess.py:93} INFO -     return func(*args, **kwargs)
[2025-04-15T08:17:02.535+0000] {subprocess.py:93} INFO -            ^^^^^^^^^^^^^^^^^^^^^
[2025-04-15T08:17:02.535+0000] {subprocess.py:93} INFO -   File "/home/***/.local/lib/python3.12/site-packages/dbt/cli/requires.py", line 247, in wrapper
[2025-04-15T08:17:02.536+0000] {subprocess.py:93} INFO -     return func(*args, **kwargs)
[2025-04-15T08:17:02.536+0000] {subprocess.py:93} INFO -            ^^^^^^^^^^^^^^^^^^^^^
[2025-04-15T08:17:02.536+0000] {subprocess.py:93} INFO -   File "/home/***/.local/lib/python3.12/site-packages/dbt/cli/requires.py", line 294, in wrapper
[2025-04-15T08:17:02.537+0000] {subprocess.py:93} INFO -     return func(*args, **kwargs)
[2025-04-15T08:17:02.537+0000] {subprocess.py:93} INFO -            ^^^^^^^^^^^^^^^^^^^^^
[2025-04-15T08:17:02.537+0000] {subprocess.py:93} INFO -   File "/home/***/.local/lib/python3.12/site-packages/dbt/cli/requires.py", line 320, in wrapper
[2025-04-15T08:17:02.539+0000] {subprocess.py:93} INFO -     ctx.obj["manifest"] = parse_manifest(
[2025-04-15T08:17:02.539+0000] {subprocess.py:93} INFO -                           ^^^^^^^^^^^^^^^
[2025-04-15T08:17:02.540+0000] {subprocess.py:93} INFO -   File "/home/***/.local/lib/python3.12/site-packages/dbt/parser/manifest.py", line 1898, in parse_manifest
[2025-04-15T08:17:02.540+0000] {subprocess.py:93} INFO -     manifest = ManifestLoader.get_full_manifest(
[2025-04-15T08:17:02.540+0000] {subprocess.py:93} INFO -                ^^^^^^^^^^^^^^^^^^^^^^^^^^^^^^^^^
[2025-04-15T08:17:02.540+0000] {subprocess.py:93} INFO -   File "/home/***/.local/lib/python3.12/site-packages/dbt/parser/manifest.py", line 330, in get_full_manifest
[2025-04-15T08:17:02.541+0000] {subprocess.py:93} INFO -     manifest = loader.load()
[2025-04-15T08:17:02.541+0000] {subprocess.py:93} INFO -                ^^^^^^^^^^^^^
[2025-04-15T08:17:02.541+0000] {subprocess.py:93} INFO -   File "/home/***/.local/lib/python3.12/site-packages/dbt/parser/manifest.py", line 399, in load
[2025-04-15T08:17:02.542+0000] {subprocess.py:93} INFO -     self.load_and_parse_macros(project_parser_files)
[2025-04-15T08:17:02.542+0000] {subprocess.py:93} INFO -   File "/home/***/.local/lib/python3.12/site-packages/dbt/parser/manifest.py", line 677, in load_and_parse_macros
[2025-04-15T08:17:02.543+0000] {subprocess.py:93} INFO -     parser.parse_file(block)
[2025-04-15T08:17:02.543+0000] {subprocess.py:93} INFO -   File "/home/***/.local/lib/python3.12/site-packages/dbt/parser/macros.py", line 119, in parse_file
[2025-04-15T08:17:02.543+0000] {subprocess.py:93} INFO -     self.manifest.add_macro(block.file, node)
[2025-04-15T08:17:02.544+0000] {subprocess.py:93} INFO -   File "/home/***/.local/lib/python3.12/site-packages/dbt/contracts/graph/manifest.py", line 1504, in add_macro
[2025-04-15T08:17:02.544+0000] {subprocess.py:93} INFO -     raise DuplicateMacroInPackageError(macro=macro, macro_mapping=self.macros)
[2025-04-15T08:17:02.544+0000] {subprocess.py:93} INFO - dbt.adapters.exceptions.compilation.DuplicateMacroInPackageError: Compilation Error
[2025-04-15T08:17:02.544+0000] {subprocess.py:93} INFO -   dbt found two macros named "snowflake__get_merge_sql" in the project
[2025-04-15T08:17:02.545+0000] {subprocess.py:93} INFO -   "dbt_snowflake".
[2025-04-15T08:17:02.545+0000] {subprocess.py:93} INFO -    To fix this error, rename or remove one of the following macros:
[2025-04-15T08:17:02.545+0000] {subprocess.py:93} INFO -       - macros/materializations/incremental/merge.sql
[2025-04-15T08:17:02.546+0000] {subprocess.py:93} INFO -       - macros/materializations/merge.sql
[2025-04-15T08:17:02.546+0000] {subprocess.py:93} INFO - 
[2025-04-15T08:17:02.546+0000] {subprocess.py:93} INFO - During handling of the above exception, another exception occurred:
[2025-04-15T08:17:02.547+0000] {subprocess.py:93} INFO - 
[2025-04-15T08:17:02.547+0000] {subprocess.py:93} INFO - Traceback (most recent call last):
[2025-04-15T08:17:02.547+0000] {subprocess.py:93} INFO -   File "/home/***/.local/lib/python3.12/site-packages/dbt/cli/requires.py", line 144, in wrapper
[2025-04-15T08:17:02.547+0000] {subprocess.py:93} INFO -     raise ExceptionExit(e)
[2025-04-15T08:17:02.548+0000] {subprocess.py:93} INFO - dbt.cli.exceptions.ExceptionExit: <exception str() failed>
[2025-04-15T08:17:02.548+0000] {subprocess.py:93} INFO - 
[2025-04-15T08:17:02.548+0000] {subprocess.py:93} INFO - During handling of the above exception, another exception occurred:
[2025-04-15T08:17:02.548+0000] {subprocess.py:93} INFO - 
[2025-04-15T08:17:02.549+0000] {subprocess.py:93} INFO - Traceback (most recent call last):
[2025-04-15T08:17:02.549+0000] {subprocess.py:93} INFO -   File "/home/***/.local/bin/dbt", line 8, in <module>
[2025-04-15T08:17:02.549+0000] {subprocess.py:93} INFO -     sys.exit(cli())
[2025-04-15T08:17:02.549+0000] {subprocess.py:93} INFO -              ^^^^^
[2025-04-15T08:17:02.550+0000] {subprocess.py:93} INFO -   File "/home/***/.local/lib/python3.12/site-packages/click/core.py", line 1157, in __call__
[2025-04-15T08:17:02.550+0000] {subprocess.py:93} INFO -     return self.main(*args, **kwargs)
[2025-04-15T08:17:02.550+0000] {subprocess.py:93} INFO -            ^^^^^^^^^^^^^^^^^^^^^^^^^^
[2025-04-15T08:17:02.550+0000] {subprocess.py:93} INFO -   File "/home/***/.local/lib/python3.12/site-packages/click/core.py", line 1078, in main
[2025-04-15T08:17:02.550+0000] {subprocess.py:93} INFO -     rv = self.invoke(ctx)
[2025-04-15T08:17:02.551+0000] {subprocess.py:93} INFO -          ^^^^^^^^^^^^^^^^
[2025-04-15T08:17:02.551+0000] {subprocess.py:93} INFO -   File "/home/***/.local/lib/python3.12/site-packages/click/core.py", line 1688, in invoke
[2025-04-15T08:17:02.551+0000] {subprocess.py:93} INFO -     return _process_result(sub_ctx.command.invoke(sub_ctx))
[2025-04-15T08:17:02.551+0000] {subprocess.py:93} INFO -                            ^^^^^^^^^^^^^^^^^^^^^^^^^^^^^^^
[2025-04-15T08:17:02.552+0000] {subprocess.py:93} INFO -   File "/home/***/.local/lib/python3.12/site-packages/click/core.py", line 1434, in invoke
[2025-04-15T08:17:02.552+0000] {subprocess.py:93} INFO -     return ctx.invoke(self.callback, **ctx.params)
[2025-04-15T08:17:02.552+0000] {subprocess.py:93} INFO -            ^^^^^^^^^^^^^^^^^^^^^^^^^^^^^^^^^^^^^^^
[2025-04-15T08:17:02.552+0000] {subprocess.py:93} INFO -   File "/home/***/.local/lib/python3.12/site-packages/click/core.py", line 783, in invoke
[2025-04-15T08:17:02.553+0000] {subprocess.py:93} INFO -     return __callback(*args, **kwargs)
[2025-04-15T08:17:02.553+0000] {subprocess.py:93} INFO -            ^^^^^^^^^^^^^^^^^^^^^^^^^^^
[2025-04-15T08:17:02.553+0000] {subprocess.py:93} INFO -   File "/home/***/.local/lib/python3.12/site-packages/click/decorators.py", line 33, in new_func
[2025-04-15T08:17:02.554+0000] {subprocess.py:93} INFO -     return f(get_current_context(), *args, **kwargs)
[2025-04-15T08:17:02.554+0000] {subprocess.py:93} INFO -            ^^^^^^^^^^^^^^^^^^^^^^^^^^^^^^^^^^^^^^^^^
[2025-04-15T08:17:02.554+0000] {subprocess.py:93} INFO -   File "/home/***/.local/lib/python3.12/site-packages/dbt/cli/main.py", line 148, in wrapper
[2025-04-15T08:17:02.554+0000] {subprocess.py:93} INFO -     return func(*args, **kwargs)
[2025-04-15T08:17:02.555+0000] {subprocess.py:93} INFO -            ^^^^^^^^^^^^^^^^^^^^^
[2025-04-15T08:17:02.555+0000] {subprocess.py:93} INFO -   File "/home/***/.local/lib/python3.12/site-packages/dbt/cli/requires.py", line 156, in wrapper
[2025-04-15T08:17:02.555+0000] {subprocess.py:93} INFO -     fire_event(
[2025-04-15T08:17:02.555+0000] {subprocess.py:93} INFO -   File "/home/***/.local/lib/python3.12/site-packages/dbt_common/events/functions.py", line 139, in fire_event
[2025-04-15T08:17:02.555+0000] {subprocess.py:93} INFO -     get_event_manager().fire_event(e, level=level)
[2025-04-15T08:17:02.556+0000] {subprocess.py:93} INFO -   File "/home/***/.local/lib/python3.12/site-packages/dbt_common/events/event_manager.py", line 15, in fire_event
[2025-04-15T08:17:02.556+0000] {subprocess.py:93} INFO -     msg = msg_from_base_event(e, level=level)
[2025-04-15T08:17:02.556+0000] {subprocess.py:93} INFO -           ^^^^^^^^^^^^^^^^^^^^^^^^^^^^^^^^^^^
[2025-04-15T08:17:02.556+0000] {subprocess.py:93} INFO -   File "/home/***/.local/lib/python3.12/site-packages/dbt_common/events/base_types.py", line 139, in msg_from_base_event
[2025-04-15T08:17:02.556+0000] {subprocess.py:93} INFO -     "msg": event.message(),
[2025-04-15T08:17:02.556+0000] {subprocess.py:93} INFO -            ^^^^^^^^^^^^^^^
[2025-04-15T08:17:02.557+0000] {subprocess.py:93} INFO -   File "/home/***/.local/lib/python3.12/site-packages/dbt/events/types.py", line 1990, in message
[2025-04-15T08:17:02.557+0000] {subprocess.py:93} INFO -     return f"Resource report: {self.to_json()}"
[2025-04-15T08:17:02.557+0000] {subprocess.py:93} INFO -                                ^^^^^^^^^^^^^^
[2025-04-15T08:17:02.557+0000] {subprocess.py:93} INFO -   File "/home/***/.local/lib/python3.12/site-packages/dbt_common/events/base_types.py", line 98, in to_json
[2025-04-15T08:17:02.558+0000] {subprocess.py:93} INFO -     return MessageToJson(
[2025-04-15T08:17:02.558+0000] {subprocess.py:93} INFO -            ^^^^^^^^^^^^^^
[2025-04-15T08:17:02.558+0000] {subprocess.py:93} INFO - TypeError: MessageToJson() got an unexpected keyword argument 'including_default_value_fields'
[2025-04-15T08:17:02.786+0000] {subprocess.py:97} INFO - Command exited with return code 1
[2025-04-15T08:17:02.837+0000] {taskinstance.py:3310} ERROR - Task failed with exception
Traceback (most recent call last):
  File "/home/airflow/.local/lib/python3.12/site-packages/airflow/models/taskinstance.py", line 767, in _execute_task
    result = _execute_callable(context=context, **execute_callable_kwargs)
             ^^^^^^^^^^^^^^^^^^^^^^^^^^^^^^^^^^^^^^^^^^^^^^^^^^^^^^^^^^^^^
  File "/home/airflow/.local/lib/python3.12/site-packages/airflow/models/taskinstance.py", line 733, in _execute_callable
    return ExecutionCallableRunner(
           ^^^^^^^^^^^^^^^^^^^^^^^^
  File "/home/airflow/.local/lib/python3.12/site-packages/airflow/utils/operator_helpers.py", line 252, in run
    return self.func(*args, **kwargs)
           ^^^^^^^^^^^^^^^^^^^^^^^^^^
  File "/home/airflow/.local/lib/python3.12/site-packages/airflow/models/baseoperator.py", line 406, in wrapper
    return func(self, *args, **kwargs)
           ^^^^^^^^^^^^^^^^^^^^^^^^^^^
  File "/home/airflow/.local/lib/python3.12/site-packages/airflow/operators/bash.py", line 249, in execute
    raise AirflowException(
airflow.exceptions.AirflowException: Bash command failed. The command returned a non-zero exit code 1.
[2025-04-15T08:17:02.843+0000] {taskinstance.py:1225} INFO - Marking task as FAILED. dag_id=StockELT_dbt, task_id=dbt_run, run_id=manual__2025-04-15T08:16:58.024479+00:00, execution_date=20250415T081658, start_date=20250415T081659, end_date=20250415T081702
[2025-04-15T08:17:02.862+0000] {taskinstance.py:340} INFO - ::group::Post task execution logs
[2025-04-15T08:17:02.863+0000] {standard_task_runner.py:124} ERROR - Failed to execute job 144 for task dbt_run (Bash command failed. The command returned a non-zero exit code 1.; 1659)
Traceback (most recent call last):
  File "/home/airflow/.local/lib/python3.12/site-packages/airflow/task/task_runner/standard_task_runner.py", line 117, in _start_by_fork
    ret = args.func(args, dag=self.dag)
          ^^^^^^^^^^^^^^^^^^^^^^^^^^^^^
  File "/home/airflow/.local/lib/python3.12/site-packages/airflow/cli/cli_config.py", line 49, in command
    return func(*args, **kwargs)
           ^^^^^^^^^^^^^^^^^^^^^
  File "/home/airflow/.local/lib/python3.12/site-packages/airflow/utils/cli.py", line 115, in wrapper
    return f(*args, **kwargs)
           ^^^^^^^^^^^^^^^^^^
  File "/home/airflow/.local/lib/python3.12/site-packages/airflow/cli/commands/task_command.py", line 483, in task_run
    task_return_code = _run_task_by_selected_method(args, _dag, ti)
                       ^^^^^^^^^^^^^^^^^^^^^^^^^^^^^^^^^^^^^^^^^^^^
  File "/home/airflow/.local/lib/python3.12/site-packages/airflow/cli/commands/task_command.py", line 256, in _run_task_by_selected_method
    return _run_raw_task(args, ti)
           ^^^^^^^^^^^^^^^^^^^^^^^
  File "/home/airflow/.local/lib/python3.12/site-packages/airflow/cli/commands/task_command.py", line 341, in _run_raw_task
    return ti._run_raw_task(
           ^^^^^^^^^^^^^^^^^
  File "/home/airflow/.local/lib/python3.12/site-packages/airflow/utils/session.py", line 97, in wrapper
    return func(*args, session=session, **kwargs)
           ^^^^^^^^^^^^^^^^^^^^^^^^^^^^^^^^^^^^^^
  File "/home/airflow/.local/lib/python3.12/site-packages/airflow/models/taskinstance.py", line 3004, in _run_raw_task
    return _run_raw_task(
           ^^^^^^^^^^^^^^
  File "/home/airflow/.local/lib/python3.12/site-packages/airflow/models/taskinstance.py", line 273, in _run_raw_task
    TaskInstance._execute_task_with_callbacks(
  File "/home/airflow/.local/lib/python3.12/site-packages/airflow/models/taskinstance.py", line 3158, in _execute_task_with_callbacks
    result = self._execute_task(context, task_orig)
             ^^^^^^^^^^^^^^^^^^^^^^^^^^^^^^^^^^^^^^
  File "/home/airflow/.local/lib/python3.12/site-packages/airflow/models/taskinstance.py", line 3182, in _execute_task
    return _execute_task(self, context, task_orig)
           ^^^^^^^^^^^^^^^^^^^^^^^^^^^^^^^^^^^^^^^
  File "/home/airflow/.local/lib/python3.12/site-packages/airflow/models/taskinstance.py", line 767, in _execute_task
    result = _execute_callable(context=context, **execute_callable_kwargs)
             ^^^^^^^^^^^^^^^^^^^^^^^^^^^^^^^^^^^^^^^^^^^^^^^^^^^^^^^^^^^^^
  File "/home/airflow/.local/lib/python3.12/site-packages/airflow/models/taskinstance.py", line 733, in _execute_callable
    return ExecutionCallableRunner(
           ^^^^^^^^^^^^^^^^^^^^^^^^
  File "/home/airflow/.local/lib/python3.12/site-packages/airflow/utils/operator_helpers.py", line 252, in run
    return self.func(*args, **kwargs)
           ^^^^^^^^^^^^^^^^^^^^^^^^^^
  File "/home/airflow/.local/lib/python3.12/site-packages/airflow/models/baseoperator.py", line 406, in wrapper
    return func(self, *args, **kwargs)
           ^^^^^^^^^^^^^^^^^^^^^^^^^^^
  File "/home/airflow/.local/lib/python3.12/site-packages/airflow/operators/bash.py", line 249, in execute
    raise AirflowException(
airflow.exceptions.AirflowException: Bash command failed. The command returned a non-zero exit code 1.
[2025-04-15T08:17:02.897+0000] {local_task_job_runner.py:266} INFO - Task exited with return code 1
[2025-04-15T08:17:02.942+0000] {taskinstance.py:3900} INFO - 0 downstream tasks scheduled from follow-on schedule check
[2025-04-15T08:17:02.950+0000] {local_task_job_runner.py:245} INFO - ::endgroup::
