[2025-04-15T19:17:20.323+0000] {local_task_job_runner.py:123} INFO - ::group::Pre task execution logs
[2025-04-15T19:17:20.358+0000] {taskinstance.py:2612} INFO - Dependencies all met for dep_context=non-requeueable deps ti=<TaskInstance: StockELT_dbt.dbt_snapshot manual__2025-04-15T19:16:27.909059+00:00 [queued]>
[2025-04-15T19:17:20.385+0000] {taskinstance.py:2612} INFO - Dependencies all met for dep_context=requeueable deps ti=<TaskInstance: StockELT_dbt.dbt_snapshot manual__2025-04-15T19:16:27.909059+00:00 [queued]>
[2025-04-15T19:17:20.387+0000] {taskinstance.py:2865} INFO - Starting attempt 1 of 1
[2025-04-15T19:17:20.411+0000] {taskinstance.py:2888} INFO - Executing <Task(BashOperator): dbt_snapshot> on 2025-04-15 19:16:27.909059+00:00
[2025-04-15T19:17:20.452+0000] {standard_task_runner.py:104} INFO - Running: ['***', 'tasks', 'run', 'StockELT_dbt', 'dbt_snapshot', 'manual__2025-04-15T19:16:27.909059+00:00', '--job-id', '149', '--raw', '--subdir', 'DAGS_FOLDER/Lab2_elt_with_dbt .py', '--cfg-path', '/tmp/tmpzvechi6y']
[2025-04-15T19:17:20.455+0000] {logging_mixin.py:190} WARNING - /home/***/.local/lib/python3.12/site-packages/***/task/task_runner/standard_task_runner.py:70 DeprecationWarning: This process (pid=912) is multi-threaded, use of fork() may lead to deadlocks in the child.
[2025-04-15T19:17:20.463+0000] {standard_task_runner.py:105} INFO - Job 149: Subtask dbt_snapshot
[2025-04-15T19:17:20.472+0000] {standard_task_runner.py:72} INFO - Started process 913 to run task
[2025-04-15T19:17:20.622+0000] {task_command.py:467} INFO - Running <TaskInstance: StockELT_dbt.dbt_snapshot manual__2025-04-15T19:16:27.909059+00:00 [running]> on host e3cb891c5fca
[2025-04-15T19:17:20.904+0000] {taskinstance.py:3131} INFO - Exporting env vars: AIRFLOW_CTX_DAG_OWNER='***' AIRFLOW_CTX_DAG_ID='StockELT_dbt' AIRFLOW_CTX_TASK_ID='dbt_snapshot' AIRFLOW_CTX_EXECUTION_DATE='2025-04-15T19:16:27.909059+00:00' AIRFLOW_CTX_TRY_NUMBER='1' AIRFLOW_CTX_DAG_RUN_ID='manual__2025-04-15T19:16:27.909059+00:00'
[2025-04-15T19:17:20.907+0000] {taskinstance.py:731} INFO - ::endgroup::
[2025-04-15T19:17:20.943+0000] {subprocess.py:63} INFO - Tmp dir root location: /tmp
[2025-04-15T19:17:20.954+0000] {subprocess.py:75} INFO - Running command: ['/usr/bin/bash', '-c', '/home/***/.local/bin/dbt snapshot --profiles-dir /opt/***/dbt_stock --project-dir /opt/***/dbt_stock']
[2025-04-15T19:17:20.995+0000] {subprocess.py:86} INFO - Output:
[2025-04-15T19:17:24.630+0000] {subprocess.py:93} INFO - [0m19:17:24  Running with dbt=1.8.7
[2025-04-15T19:17:25.833+0000] {subprocess.py:93} INFO - [0m19:17:25  Registered adapter: snowflake=1.8.4
[2025-04-15T19:17:26.593+0000] {subprocess.py:93} INFO - [0m19:17:26  Found 2 models, 1 snapshot, 4 data tests, 2 sources, 459 macros
[2025-04-15T19:17:26.602+0000] {subprocess.py:93} INFO - [0m19:17:26
[2025-04-15T19:17:29.265+0000] {subprocess.py:93} INFO - [0m19:17:29  Concurrency: 1 threads (target='dev')
[2025-04-15T19:17:29.273+0000] {subprocess.py:93} INFO - [0m19:17:29
[2025-04-15T19:17:29.294+0000] {subprocess.py:93} INFO - [0m19:17:29  1 of 1 START snapshot snapshot.snapshot_stock_analytics ........................ [RUN]
[2025-04-15T19:17:33.696+0000] {subprocess.py:93} INFO - [0m19:17:33  1 of 1 ERROR snapshotting snapshot.snapshot_stock_analytics .................... [[31mERROR[0m in 4.39s]
[2025-04-15T19:17:33.742+0000] {subprocess.py:93} INFO - [0m19:17:33
[2025-04-15T19:17:33.743+0000] {subprocess.py:93} INFO - [0m19:17:33  Finished running 1 snapshot in 0 hours 0 minutes and 7.13 seconds (7.13s).
[2025-04-15T19:17:33.909+0000] {subprocess.py:93} INFO - [0m19:17:33
[2025-04-15T19:17:33.910+0000] {subprocess.py:93} INFO - [0m19:17:33  [31mCompleted with 1 error and 0 warnings:[0m
[2025-04-15T19:17:33.910+0000] {subprocess.py:93} INFO - [0m19:17:33
[2025-04-15T19:17:33.911+0000] {subprocess.py:93} INFO - [0m19:17:33    Database Error in snapshot snapshot_stock_analytics (snapshots/snapshot_stock_analytics.sql)
[2025-04-15T19:17:33.912+0000] {subprocess.py:93} INFO -   100090 (42P18): Duplicate row detected during DML action
[2025-04-15T19:17:33.913+0000] {subprocess.py:93} INFO -   Row Values: [redacted]
[2025-04-15T19:17:33.913+0000] {subprocess.py:93} INFO -   compiled code at target/run/dbt_stock/snapshots/snapshot_stock_analytics.sql
[2025-04-15T19:17:33.913+0000] {subprocess.py:93} INFO - [0m19:17:33
[2025-04-15T19:17:33.914+0000] {subprocess.py:93} INFO - [0m19:17:33  Done. PASS=0 WARN=0 ERROR=1 SKIP=0 TOTAL=1
[2025-04-15T19:17:36.230+0000] {subprocess.py:97} INFO - Command exited with return code 1
[2025-04-15T19:17:36.308+0000] {taskinstance.py:3310} ERROR - Task failed with exception
Traceback (most recent call last):
  File "/home/airflow/.local/lib/python3.12/site-packages/airflow/models/taskinstance.py", line 767, in _execute_task
    result = _execute_callable(context=context, **execute_callable_kwargs)
             ^^^^^^^^^^^^^^^^^^^^^^^^^^^^^^^^^^^^^^^^^^^^^^^^^^^^^^^^^^^^^
  File "/home/airflow/.local/lib/python3.12/site-packages/airflow/models/taskinstance.py", line 733, in _execute_callable
    return ExecutionCallableRunner(
           ^^^^^^^^^^^^^^^^^^^^^^^^
  File "/home/airflow/.local/lib/python3.12/site-packages/airflow/utils/operator_helpers.py", line 252, in run
    return self.func(*args, **kwargs)
           ^^^^^^^^^^^^^^^^^^^^^^^^^^
  File "/home/airflow/.local/lib/python3.12/site-packages/airflow/models/baseoperator.py", line 406, in wrapper
    return func(self, *args, **kwargs)
           ^^^^^^^^^^^^^^^^^^^^^^^^^^^
  File "/home/airflow/.local/lib/python3.12/site-packages/airflow/operators/bash.py", line 249, in execute
    raise AirflowException(
airflow.exceptions.AirflowException: Bash command failed. The command returned a non-zero exit code 1.
[2025-04-15T19:17:36.332+0000] {taskinstance.py:1225} INFO - Marking task as FAILED. dag_id=StockELT_dbt, task_id=dbt_snapshot, run_id=manual__2025-04-15T19:16:27.909059+00:00, execution_date=20250415T191627, start_date=20250415T191720, end_date=20250415T191736
[2025-04-15T19:17:36.370+0000] {taskinstance.py:340} INFO - ::group::Post task execution logs
[2025-04-15T19:17:36.377+0000] {standard_task_runner.py:124} ERROR - Failed to execute job 149 for task dbt_snapshot (Bash command failed. The command returned a non-zero exit code 1.; 913)
Traceback (most recent call last):
  File "/home/airflow/.local/lib/python3.12/site-packages/airflow/task/task_runner/standard_task_runner.py", line 117, in _start_by_fork
    ret = args.func(args, dag=self.dag)
          ^^^^^^^^^^^^^^^^^^^^^^^^^^^^^
  File "/home/airflow/.local/lib/python3.12/site-packages/airflow/cli/cli_config.py", line 49, in command
    return func(*args, **kwargs)
           ^^^^^^^^^^^^^^^^^^^^^
  File "/home/airflow/.local/lib/python3.12/site-packages/airflow/utils/cli.py", line 115, in wrapper
    return f(*args, **kwargs)
           ^^^^^^^^^^^^^^^^^^
  File "/home/airflow/.local/lib/python3.12/site-packages/airflow/cli/commands/task_command.py", line 483, in task_run
    task_return_code = _run_task_by_selected_method(args, _dag, ti)
                       ^^^^^^^^^^^^^^^^^^^^^^^^^^^^^^^^^^^^^^^^^^^^
  File "/home/airflow/.local/lib/python3.12/site-packages/airflow/cli/commands/task_command.py", line 256, in _run_task_by_selected_method
    return _run_raw_task(args, ti)
           ^^^^^^^^^^^^^^^^^^^^^^^
  File "/home/airflow/.local/lib/python3.12/site-packages/airflow/cli/commands/task_command.py", line 341, in _run_raw_task
    return ti._run_raw_task(
           ^^^^^^^^^^^^^^^^^
  File "/home/airflow/.local/lib/python3.12/site-packages/airflow/utils/session.py", line 97, in wrapper
    return func(*args, session=session, **kwargs)
           ^^^^^^^^^^^^^^^^^^^^^^^^^^^^^^^^^^^^^^
  File "/home/airflow/.local/lib/python3.12/site-packages/airflow/models/taskinstance.py", line 3004, in _run_raw_task
    return _run_raw_task(
           ^^^^^^^^^^^^^^
  File "/home/airflow/.local/lib/python3.12/site-packages/airflow/models/taskinstance.py", line 273, in _run_raw_task
    TaskInstance._execute_task_with_callbacks(
  File "/home/airflow/.local/lib/python3.12/site-packages/airflow/models/taskinstance.py", line 3158, in _execute_task_with_callbacks
    result = self._execute_task(context, task_orig)
             ^^^^^^^^^^^^^^^^^^^^^^^^^^^^^^^^^^^^^^
  File "/home/airflow/.local/lib/python3.12/site-packages/airflow/models/taskinstance.py", line 3182, in _execute_task
    return _execute_task(self, context, task_orig)
           ^^^^^^^^^^^^^^^^^^^^^^^^^^^^^^^^^^^^^^^
  File "/home/airflow/.local/lib/python3.12/site-packages/airflow/models/taskinstance.py", line 767, in _execute_task
    result = _execute_callable(context=context, **execute_callable_kwargs)
             ^^^^^^^^^^^^^^^^^^^^^^^^^^^^^^^^^^^^^^^^^^^^^^^^^^^^^^^^^^^^^
  File "/home/airflow/.local/lib/python3.12/site-packages/airflow/models/taskinstance.py", line 733, in _execute_callable
    return ExecutionCallableRunner(
           ^^^^^^^^^^^^^^^^^^^^^^^^
  File "/home/airflow/.local/lib/python3.12/site-packages/airflow/utils/operator_helpers.py", line 252, in run
    return self.func(*args, **kwargs)
           ^^^^^^^^^^^^^^^^^^^^^^^^^^
  File "/home/airflow/.local/lib/python3.12/site-packages/airflow/models/baseoperator.py", line 406, in wrapper
    return func(self, *args, **kwargs)
           ^^^^^^^^^^^^^^^^^^^^^^^^^^^
  File "/home/airflow/.local/lib/python3.12/site-packages/airflow/operators/bash.py", line 249, in execute
    raise AirflowException(
airflow.exceptions.AirflowException: Bash command failed. The command returned a non-zero exit code 1.
[2025-04-15T19:17:36.469+0000] {local_task_job_runner.py:266} INFO - Task exited with return code 1
[2025-04-15T19:17:36.563+0000] {taskinstance.py:3900} INFO - 0 downstream tasks scheduled from follow-on schedule check
[2025-04-15T19:17:36.572+0000] {local_task_job_runner.py:245} INFO - ::endgroup::
