[2025-04-15T08:07:14.380+0000] {local_task_job_runner.py:123} INFO - ::group::Pre task execution logs
[2025-04-15T08:07:14.398+0000] {taskinstance.py:2612} INFO - Dependencies all met for dep_context=non-requeueable deps ti=<TaskInstance: StockELT_dbt.dbt_run manual__2025-04-15T08:07:13.323766+00:00 [queued]>
[2025-04-15T08:07:14.405+0000] {taskinstance.py:2612} INFO - Dependencies all met for dep_context=requeueable deps ti=<TaskInstance: StockELT_dbt.dbt_run manual__2025-04-15T08:07:13.323766+00:00 [queued]>
[2025-04-15T08:07:14.406+0000] {taskinstance.py:2865} INFO - Starting attempt 1 of 1
[2025-04-15T08:07:14.432+0000] {taskinstance.py:2888} INFO - Executing <Task(BashOperator): dbt_run> on 2025-04-15 08:07:13.323766+00:00
[2025-04-15T08:07:14.462+0000] {standard_task_runner.py:104} INFO - Running: ['***', 'tasks', 'run', 'StockELT_dbt', 'dbt_run', 'manual__2025-04-15T08:07:13.323766+00:00', '--job-id', '142', '--raw', '--subdir', 'DAGS_FOLDER/Lab2_elt_with_dbt .py', '--cfg-path', '/tmp/tmp02mfi593']
[2025-04-15T08:07:14.470+0000] {standard_task_runner.py:105} INFO - Job 142: Subtask dbt_run
[2025-04-15T08:07:14.476+0000] {logging_mixin.py:190} WARNING - /home/***/.local/lib/python3.12/site-packages/***/task/task_runner/standard_task_runner.py:70 DeprecationWarning: This process (pid=662) is multi-threaded, use of fork() may lead to deadlocks in the child.
[2025-04-15T08:07:14.477+0000] {standard_task_runner.py:72} INFO - Started process 663 to run task
[2025-04-15T08:07:14.553+0000] {task_command.py:467} INFO - Running <TaskInstance: StockELT_dbt.dbt_run manual__2025-04-15T08:07:13.323766+00:00 [running]> on host 83ad2e5aff09
[2025-04-15T08:07:14.661+0000] {taskinstance.py:3131} INFO - Exporting env vars: AIRFLOW_CTX_DAG_OWNER='***' AIRFLOW_CTX_DAG_ID='StockELT_dbt' AIRFLOW_CTX_TASK_ID='dbt_run' AIRFLOW_CTX_EXECUTION_DATE='2025-04-15T08:07:13.323766+00:00' AIRFLOW_CTX_TRY_NUMBER='1' AIRFLOW_CTX_DAG_RUN_ID='manual__2025-04-15T08:07:13.323766+00:00'
[2025-04-15T08:07:14.662+0000] {taskinstance.py:731} INFO - ::endgroup::
[2025-04-15T08:07:14.699+0000] {subprocess.py:63} INFO - Tmp dir root location: /tmp
[2025-04-15T08:07:14.700+0000] {subprocess.py:75} INFO - Running command: ['/usr/bin/bash', '-c', '/home/***/.local/bin/dbt run --profiles-dir /opt/***/dbt_stock --project-dir /opt/***/dbt_stock']
[2025-04-15T08:07:14.712+0000] {subprocess.py:86} INFO - Output:
[2025-04-15T08:07:18.042+0000] {subprocess.py:93} INFO - [0m08:07:18  Running with dbt=1.8.7
[2025-04-15T08:07:18.055+0000] {subprocess.py:93} INFO - [0m08:07:18  Encountered an error:
[2025-04-15T08:07:18.056+0000] {subprocess.py:93} INFO - Runtime Error
[2025-04-15T08:07:18.057+0000] {subprocess.py:93} INFO -   Could not find profile named 'dbt_stock'
[2025-04-15T08:07:18.563+0000] {subprocess.py:93} INFO - Traceback (most recent call last):
[2025-04-15T08:07:18.564+0000] {subprocess.py:93} INFO -   File "/home/***/.local/lib/python3.12/site-packages/dbt/cli/requires.py", line 138, in wrapper
[2025-04-15T08:07:18.564+0000] {subprocess.py:93} INFO -     result, success = func(*args, **kwargs)
[2025-04-15T08:07:18.565+0000] {subprocess.py:93} INFO -                       ^^^^^^^^^^^^^^^^^^^^^
[2025-04-15T08:07:18.565+0000] {subprocess.py:93} INFO -   File "/home/***/.local/lib/python3.12/site-packages/dbt/cli/requires.py", line 101, in wrapper
[2025-04-15T08:07:18.565+0000] {subprocess.py:93} INFO -     return func(*args, **kwargs)
[2025-04-15T08:07:18.565+0000] {subprocess.py:93} INFO -            ^^^^^^^^^^^^^^^^^^^^^
[2025-04-15T08:07:18.566+0000] {subprocess.py:93} INFO -   File "/home/***/.local/lib/python3.12/site-packages/dbt/cli/requires.py", line 215, in wrapper
[2025-04-15T08:07:18.566+0000] {subprocess.py:93} INFO -     profile = load_profile(flags.PROJECT_DIR, flags.VARS, flags.PROFILE, flags.TARGET, threads)
[2025-04-15T08:07:18.566+0000] {subprocess.py:93} INFO -               ^^^^^^^^^^^^^^^^^^^^^^^^^^^^^^^^^^^^^^^^^^^^^^^^^^^^^^^^^^^^^^^^^^^^^^^^^^^^^^^^^
[2025-04-15T08:07:18.566+0000] {subprocess.py:93} INFO -   File "/home/***/.local/lib/python3.12/site-packages/dbt/config/runtime.py", line 71, in load_profile
[2025-04-15T08:07:18.567+0000] {subprocess.py:93} INFO -     profile = Profile.render(
[2025-04-15T08:07:18.567+0000] {subprocess.py:93} INFO -               ^^^^^^^^^^^^^^^
[2025-04-15T08:07:18.567+0000] {subprocess.py:93} INFO -   File "/home/***/.local/lib/python3.12/site-packages/dbt/config/profile.py", line 403, in render
[2025-04-15T08:07:18.567+0000] {subprocess.py:93} INFO -     return cls.from_raw_profiles(
[2025-04-15T08:07:18.567+0000] {subprocess.py:93} INFO -            ^^^^^^^^^^^^^^^^^^^^^^
[2025-04-15T08:07:18.568+0000] {subprocess.py:93} INFO -   File "/home/***/.local/lib/python3.12/site-packages/dbt/config/profile.py", line 360, in from_raw_profiles
[2025-04-15T08:07:18.568+0000] {subprocess.py:93} INFO -     raise DbtProjectError("Could not find profile named '{}'".format(profile_name))
[2025-04-15T08:07:18.568+0000] {subprocess.py:93} INFO - dbt.exceptions.DbtProjectError: Runtime Error
[2025-04-15T08:07:18.568+0000] {subprocess.py:93} INFO -   Could not find profile named 'dbt_stock'
[2025-04-15T08:07:18.569+0000] {subprocess.py:93} INFO - 
[2025-04-15T08:07:18.569+0000] {subprocess.py:93} INFO - During handling of the above exception, another exception occurred:
[2025-04-15T08:07:18.569+0000] {subprocess.py:93} INFO - 
[2025-04-15T08:07:18.569+0000] {subprocess.py:93} INFO - Traceback (most recent call last):
[2025-04-15T08:07:18.569+0000] {subprocess.py:93} INFO -   File "/home/***/.local/lib/python3.12/site-packages/dbt/cli/requires.py", line 144, in wrapper
[2025-04-15T08:07:18.570+0000] {subprocess.py:93} INFO -     raise ExceptionExit(e)
[2025-04-15T08:07:18.570+0000] {subprocess.py:93} INFO - dbt.cli.exceptions.ExceptionExit: <exception str() failed>
[2025-04-15T08:07:18.570+0000] {subprocess.py:93} INFO - 
[2025-04-15T08:07:18.570+0000] {subprocess.py:93} INFO - During handling of the above exception, another exception occurred:
[2025-04-15T08:07:18.571+0000] {subprocess.py:93} INFO - 
[2025-04-15T08:07:18.573+0000] {subprocess.py:93} INFO - Traceback (most recent call last):
[2025-04-15T08:07:18.573+0000] {subprocess.py:93} INFO -   File "/home/***/.local/bin/dbt", line 8, in <module>
[2025-04-15T08:07:18.575+0000] {subprocess.py:93} INFO -     sys.exit(cli())
[2025-04-15T08:07:18.575+0000] {subprocess.py:93} INFO -              ^^^^^
[2025-04-15T08:07:18.576+0000] {subprocess.py:93} INFO -   File "/home/***/.local/lib/python3.12/site-packages/click/core.py", line 1157, in __call__
[2025-04-15T08:07:18.577+0000] {subprocess.py:93} INFO -     return self.main(*args, **kwargs)
[2025-04-15T08:07:18.578+0000] {subprocess.py:93} INFO -            ^^^^^^^^^^^^^^^^^^^^^^^^^^
[2025-04-15T08:07:18.579+0000] {subprocess.py:93} INFO -   File "/home/***/.local/lib/python3.12/site-packages/click/core.py", line 1078, in main
[2025-04-15T08:07:18.582+0000] {subprocess.py:93} INFO -     rv = self.invoke(ctx)
[2025-04-15T08:07:18.582+0000] {subprocess.py:93} INFO -          ^^^^^^^^^^^^^^^^
[2025-04-15T08:07:18.584+0000] {subprocess.py:93} INFO -   File "/home/***/.local/lib/python3.12/site-packages/click/core.py", line 1688, in invoke
[2025-04-15T08:07:18.584+0000] {subprocess.py:93} INFO -     return _process_result(sub_ctx.command.invoke(sub_ctx))
[2025-04-15T08:07:18.585+0000] {subprocess.py:93} INFO -                            ^^^^^^^^^^^^^^^^^^^^^^^^^^^^^^^
[2025-04-15T08:07:18.585+0000] {subprocess.py:93} INFO -   File "/home/***/.local/lib/python3.12/site-packages/click/core.py", line 1434, in invoke
[2025-04-15T08:07:18.586+0000] {subprocess.py:93} INFO -     return ctx.invoke(self.callback, **ctx.params)
[2025-04-15T08:07:18.586+0000] {subprocess.py:93} INFO -            ^^^^^^^^^^^^^^^^^^^^^^^^^^^^^^^^^^^^^^^
[2025-04-15T08:07:18.586+0000] {subprocess.py:93} INFO -   File "/home/***/.local/lib/python3.12/site-packages/click/core.py", line 783, in invoke
[2025-04-15T08:07:18.586+0000] {subprocess.py:93} INFO -     return __callback(*args, **kwargs)
[2025-04-15T08:07:18.587+0000] {subprocess.py:93} INFO -            ^^^^^^^^^^^^^^^^^^^^^^^^^^^
[2025-04-15T08:07:18.587+0000] {subprocess.py:93} INFO -   File "/home/***/.local/lib/python3.12/site-packages/click/decorators.py", line 33, in new_func
[2025-04-15T08:07:18.587+0000] {subprocess.py:93} INFO -     return f(get_current_context(), *args, **kwargs)
[2025-04-15T08:07:18.588+0000] {subprocess.py:93} INFO -            ^^^^^^^^^^^^^^^^^^^^^^^^^^^^^^^^^^^^^^^^^
[2025-04-15T08:07:18.588+0000] {subprocess.py:93} INFO -   File "/home/***/.local/lib/python3.12/site-packages/dbt/cli/main.py", line 148, in wrapper
[2025-04-15T08:07:18.588+0000] {subprocess.py:93} INFO -     return func(*args, **kwargs)
[2025-04-15T08:07:18.588+0000] {subprocess.py:93} INFO -            ^^^^^^^^^^^^^^^^^^^^^
[2025-04-15T08:07:18.588+0000] {subprocess.py:93} INFO -   File "/home/***/.local/lib/python3.12/site-packages/dbt/cli/requires.py", line 156, in wrapper
[2025-04-15T08:07:18.589+0000] {subprocess.py:93} INFO -     fire_event(
[2025-04-15T08:07:18.589+0000] {subprocess.py:93} INFO -   File "/home/***/.local/lib/python3.12/site-packages/dbt_common/events/functions.py", line 139, in fire_event
[2025-04-15T08:07:18.590+0000] {subprocess.py:93} INFO -     get_event_manager().fire_event(e, level=level)
[2025-04-15T08:07:18.590+0000] {subprocess.py:93} INFO -   File "/home/***/.local/lib/python3.12/site-packages/dbt_common/events/event_manager.py", line 15, in fire_event
[2025-04-15T08:07:18.590+0000] {subprocess.py:93} INFO -     msg = msg_from_base_event(e, level=level)
[2025-04-15T08:07:18.591+0000] {subprocess.py:93} INFO -           ^^^^^^^^^^^^^^^^^^^^^^^^^^^^^^^^^^^
[2025-04-15T08:07:18.591+0000] {subprocess.py:93} INFO -   File "/home/***/.local/lib/python3.12/site-packages/dbt_common/events/base_types.py", line 139, in msg_from_base_event
[2025-04-15T08:07:18.591+0000] {subprocess.py:93} INFO -     "msg": event.message(),
[2025-04-15T08:07:18.591+0000] {subprocess.py:93} INFO -            ^^^^^^^^^^^^^^^
[2025-04-15T08:07:18.592+0000] {subprocess.py:93} INFO -   File "/home/***/.local/lib/python3.12/site-packages/dbt/events/types.py", line 1990, in message
[2025-04-15T08:07:18.592+0000] {subprocess.py:93} INFO -     return f"Resource report: {self.to_json()}"
[2025-04-15T08:07:18.592+0000] {subprocess.py:93} INFO -                                ^^^^^^^^^^^^^^
[2025-04-15T08:07:18.593+0000] {subprocess.py:93} INFO -   File "/home/***/.local/lib/python3.12/site-packages/dbt_common/events/base_types.py", line 98, in to_json
[2025-04-15T08:07:18.593+0000] {subprocess.py:93} INFO -     return MessageToJson(
[2025-04-15T08:07:18.593+0000] {subprocess.py:93} INFO -            ^^^^^^^^^^^^^^
[2025-04-15T08:07:18.593+0000] {subprocess.py:93} INFO - TypeError: MessageToJson() got an unexpected keyword argument 'including_default_value_fields'
[2025-04-15T08:07:18.963+0000] {subprocess.py:97} INFO - Command exited with return code 1
[2025-04-15T08:07:19.027+0000] {taskinstance.py:3310} ERROR - Task failed with exception
Traceback (most recent call last):
  File "/home/airflow/.local/lib/python3.12/site-packages/airflow/models/taskinstance.py", line 767, in _execute_task
    result = _execute_callable(context=context, **execute_callable_kwargs)
             ^^^^^^^^^^^^^^^^^^^^^^^^^^^^^^^^^^^^^^^^^^^^^^^^^^^^^^^^^^^^^
  File "/home/airflow/.local/lib/python3.12/site-packages/airflow/models/taskinstance.py", line 733, in _execute_callable
    return ExecutionCallableRunner(
           ^^^^^^^^^^^^^^^^^^^^^^^^
  File "/home/airflow/.local/lib/python3.12/site-packages/airflow/utils/operator_helpers.py", line 252, in run
    return self.func(*args, **kwargs)
           ^^^^^^^^^^^^^^^^^^^^^^^^^^
  File "/home/airflow/.local/lib/python3.12/site-packages/airflow/models/baseoperator.py", line 406, in wrapper
    return func(self, *args, **kwargs)
           ^^^^^^^^^^^^^^^^^^^^^^^^^^^
  File "/home/airflow/.local/lib/python3.12/site-packages/airflow/operators/bash.py", line 249, in execute
    raise AirflowException(
airflow.exceptions.AirflowException: Bash command failed. The command returned a non-zero exit code 1.
[2025-04-15T08:07:19.052+0000] {taskinstance.py:1225} INFO - Marking task as FAILED. dag_id=StockELT_dbt, task_id=dbt_run, run_id=manual__2025-04-15T08:07:13.323766+00:00, execution_date=20250415T080713, start_date=20250415T080714, end_date=20250415T080719
[2025-04-15T08:07:19.079+0000] {taskinstance.py:340} INFO - ::group::Post task execution logs
[2025-04-15T08:07:19.079+0000] {standard_task_runner.py:124} ERROR - Failed to execute job 142 for task dbt_run (Bash command failed. The command returned a non-zero exit code 1.; 663)
Traceback (most recent call last):
  File "/home/airflow/.local/lib/python3.12/site-packages/airflow/task/task_runner/standard_task_runner.py", line 117, in _start_by_fork
    ret = args.func(args, dag=self.dag)
          ^^^^^^^^^^^^^^^^^^^^^^^^^^^^^
  File "/home/airflow/.local/lib/python3.12/site-packages/airflow/cli/cli_config.py", line 49, in command
    return func(*args, **kwargs)
           ^^^^^^^^^^^^^^^^^^^^^
  File "/home/airflow/.local/lib/python3.12/site-packages/airflow/utils/cli.py", line 115, in wrapper
    return f(*args, **kwargs)
           ^^^^^^^^^^^^^^^^^^
  File "/home/airflow/.local/lib/python3.12/site-packages/airflow/cli/commands/task_command.py", line 483, in task_run
    task_return_code = _run_task_by_selected_method(args, _dag, ti)
                       ^^^^^^^^^^^^^^^^^^^^^^^^^^^^^^^^^^^^^^^^^^^^
  File "/home/airflow/.local/lib/python3.12/site-packages/airflow/cli/commands/task_command.py", line 256, in _run_task_by_selected_method
    return _run_raw_task(args, ti)
           ^^^^^^^^^^^^^^^^^^^^^^^
  File "/home/airflow/.local/lib/python3.12/site-packages/airflow/cli/commands/task_command.py", line 341, in _run_raw_task
    return ti._run_raw_task(
           ^^^^^^^^^^^^^^^^^
  File "/home/airflow/.local/lib/python3.12/site-packages/airflow/utils/session.py", line 97, in wrapper
    return func(*args, session=session, **kwargs)
           ^^^^^^^^^^^^^^^^^^^^^^^^^^^^^^^^^^^^^^
  File "/home/airflow/.local/lib/python3.12/site-packages/airflow/models/taskinstance.py", line 3004, in _run_raw_task
    return _run_raw_task(
           ^^^^^^^^^^^^^^
  File "/home/airflow/.local/lib/python3.12/site-packages/airflow/models/taskinstance.py", line 273, in _run_raw_task
    TaskInstance._execute_task_with_callbacks(
  File "/home/airflow/.local/lib/python3.12/site-packages/airflow/models/taskinstance.py", line 3158, in _execute_task_with_callbacks
    result = self._execute_task(context, task_orig)
             ^^^^^^^^^^^^^^^^^^^^^^^^^^^^^^^^^^^^^^
  File "/home/airflow/.local/lib/python3.12/site-packages/airflow/models/taskinstance.py", line 3182, in _execute_task
    return _execute_task(self, context, task_orig)
           ^^^^^^^^^^^^^^^^^^^^^^^^^^^^^^^^^^^^^^^
  File "/home/airflow/.local/lib/python3.12/site-packages/airflow/models/taskinstance.py", line 767, in _execute_task
    result = _execute_callable(context=context, **execute_callable_kwargs)
             ^^^^^^^^^^^^^^^^^^^^^^^^^^^^^^^^^^^^^^^^^^^^^^^^^^^^^^^^^^^^^
  File "/home/airflow/.local/lib/python3.12/site-packages/airflow/models/taskinstance.py", line 733, in _execute_callable
    return ExecutionCallableRunner(
           ^^^^^^^^^^^^^^^^^^^^^^^^
  File "/home/airflow/.local/lib/python3.12/site-packages/airflow/utils/operator_helpers.py", line 252, in run
    return self.func(*args, **kwargs)
           ^^^^^^^^^^^^^^^^^^^^^^^^^^
  File "/home/airflow/.local/lib/python3.12/site-packages/airflow/models/baseoperator.py", line 406, in wrapper
    return func(self, *args, **kwargs)
           ^^^^^^^^^^^^^^^^^^^^^^^^^^^
  File "/home/airflow/.local/lib/python3.12/site-packages/airflow/operators/bash.py", line 249, in execute
    raise AirflowException(
airflow.exceptions.AirflowException: Bash command failed. The command returned a non-zero exit code 1.
[2025-04-15T08:07:19.150+0000] {local_task_job_runner.py:266} INFO - Task exited with return code 1
[2025-04-15T08:07:19.199+0000] {taskinstance.py:3900} INFO - 0 downstream tasks scheduled from follow-on schedule check
[2025-04-15T08:07:19.203+0000] {local_task_job_runner.py:245} INFO - ::endgroup::
