[2025-04-15T07:19:03.476+0000] {local_task_job_runner.py:123} INFO - ::group::Pre task execution logs
[2025-04-15T07:19:03.537+0000] {taskinstance.py:2612} INFO - Dependencies all met for dep_context=non-requeueable deps ti=<TaskInstance: StockELT_dbt.dbt_run manual__2025-04-15T07:18:59.694313+00:00 [queued]>
[2025-04-15T07:19:03.572+0000] {taskinstance.py:2612} INFO - Dependencies all met for dep_context=requeueable deps ti=<TaskInstance: StockELT_dbt.dbt_run manual__2025-04-15T07:18:59.694313+00:00 [queued]>
[2025-04-15T07:19:03.573+0000] {taskinstance.py:2865} INFO - Starting attempt 1 of 1
[2025-04-15T07:19:03.622+0000] {taskinstance.py:2888} INFO - Executing <Task(BashOperator): dbt_run> on 2025-04-15 07:18:59.694313+00:00
[2025-04-15T07:19:03.734+0000] {standard_task_runner.py:104} INFO - Running: ['***', 'tasks', 'run', 'StockELT_dbt', 'dbt_run', 'manual__2025-04-15T07:18:59.694313+00:00', '--job-id', '139', '--raw', '--subdir', 'DAGS_FOLDER/Lab2_elt_with_dbt .py', '--cfg-path', '/tmp/tmpldwilvv2']
[2025-04-15T07:19:03.741+0000] {standard_task_runner.py:105} INFO - Job 139: Subtask dbt_run
[2025-04-15T07:19:03.741+0000] {logging_mixin.py:190} WARNING - /home/***/.local/lib/python3.12/site-packages/***/task/task_runner/standard_task_runner.py:70 DeprecationWarning: This process (pid=8748) is multi-threaded, use of fork() may lead to deadlocks in the child.
[2025-04-15T07:19:03.745+0000] {standard_task_runner.py:72} INFO - Started process 8749 to run task
[2025-04-15T07:19:03.964+0000] {task_command.py:467} INFO - Running <TaskInstance: StockELT_dbt.dbt_run manual__2025-04-15T07:18:59.694313+00:00 [running]> on host a14e9c397055
[2025-04-15T07:19:04.317+0000] {taskinstance.py:3131} INFO - Exporting env vars: AIRFLOW_CTX_DAG_OWNER='***' AIRFLOW_CTX_DAG_ID='StockELT_dbt' AIRFLOW_CTX_TASK_ID='dbt_run' AIRFLOW_CTX_EXECUTION_DATE='2025-04-15T07:18:59.694313+00:00' AIRFLOW_CTX_TRY_NUMBER='1' AIRFLOW_CTX_DAG_RUN_ID='manual__2025-04-15T07:18:59.694313+00:00'
[2025-04-15T07:19:04.321+0000] {taskinstance.py:731} INFO - ::endgroup::
[2025-04-15T07:19:04.387+0000] {subprocess.py:63} INFO - Tmp dir root location: /tmp
[2025-04-15T07:19:04.391+0000] {subprocess.py:75} INFO - Running command: ['/usr/bin/bash', '-c', '/home/***/.local/bin/dbt run --profiles-dir /opt/***/dbt_stock --project-dir /opt/***/dbt_stock']
[2025-04-15T07:19:04.473+0000] {subprocess.py:86} INFO - Output:
[2025-04-15T07:19:10.815+0000] {subprocess.py:93} INFO - [0m07:19:10  Running with dbt=1.8.7
[2025-04-15T07:19:10.821+0000] {subprocess.py:93} INFO - [0m07:19:10  Encountered an error:
[2025-04-15T07:19:10.822+0000] {subprocess.py:93} INFO - Runtime Error
[2025-04-15T07:19:10.822+0000] {subprocess.py:93} INFO -   No dbt_project.yml found at expected path /opt/***/dbt_stock/dbt_project.yml
[2025-04-15T07:19:10.823+0000] {subprocess.py:93} INFO -   Verify that each entry within packages.yml (and their transitive dependencies) contains a file named dbt_project.yml
[2025-04-15T07:19:10.824+0000] {subprocess.py:93} INFO - 
[2025-04-15T07:19:11.777+0000] {subprocess.py:97} INFO - Command exited with return code 2
[2025-04-15T07:19:11.868+0000] {taskinstance.py:3310} ERROR - Task failed with exception
Traceback (most recent call last):
  File "/home/airflow/.local/lib/python3.12/site-packages/airflow/models/taskinstance.py", line 767, in _execute_task
    result = _execute_callable(context=context, **execute_callable_kwargs)
             ^^^^^^^^^^^^^^^^^^^^^^^^^^^^^^^^^^^^^^^^^^^^^^^^^^^^^^^^^^^^^
  File "/home/airflow/.local/lib/python3.12/site-packages/airflow/models/taskinstance.py", line 733, in _execute_callable
    return ExecutionCallableRunner(
           ^^^^^^^^^^^^^^^^^^^^^^^^
  File "/home/airflow/.local/lib/python3.12/site-packages/airflow/utils/operator_helpers.py", line 252, in run
    return self.func(*args, **kwargs)
           ^^^^^^^^^^^^^^^^^^^^^^^^^^
  File "/home/airflow/.local/lib/python3.12/site-packages/airflow/models/baseoperator.py", line 406, in wrapper
    return func(self, *args, **kwargs)
           ^^^^^^^^^^^^^^^^^^^^^^^^^^^
  File "/home/airflow/.local/lib/python3.12/site-packages/airflow/operators/bash.py", line 249, in execute
    raise AirflowException(
airflow.exceptions.AirflowException: Bash command failed. The command returned a non-zero exit code 2.
[2025-04-15T07:19:11.886+0000] {taskinstance.py:1225} INFO - Marking task as FAILED. dag_id=StockELT_dbt, task_id=dbt_run, run_id=manual__2025-04-15T07:18:59.694313+00:00, execution_date=20250415T071859, start_date=20250415T071903, end_date=20250415T071911
[2025-04-15T07:19:11.975+0000] {taskinstance.py:340} INFO - ::group::Post task execution logs
[2025-04-15T07:19:11.978+0000] {standard_task_runner.py:124} ERROR - Failed to execute job 139 for task dbt_run (Bash command failed. The command returned a non-zero exit code 2.; 8749)
Traceback (most recent call last):
  File "/home/airflow/.local/lib/python3.12/site-packages/airflow/task/task_runner/standard_task_runner.py", line 117, in _start_by_fork
    ret = args.func(args, dag=self.dag)
          ^^^^^^^^^^^^^^^^^^^^^^^^^^^^^
  File "/home/airflow/.local/lib/python3.12/site-packages/airflow/cli/cli_config.py", line 49, in command
    return func(*args, **kwargs)
           ^^^^^^^^^^^^^^^^^^^^^
  File "/home/airflow/.local/lib/python3.12/site-packages/airflow/utils/cli.py", line 115, in wrapper
    return f(*args, **kwargs)
           ^^^^^^^^^^^^^^^^^^
  File "/home/airflow/.local/lib/python3.12/site-packages/airflow/cli/commands/task_command.py", line 483, in task_run
    task_return_code = _run_task_by_selected_method(args, _dag, ti)
                       ^^^^^^^^^^^^^^^^^^^^^^^^^^^^^^^^^^^^^^^^^^^^
  File "/home/airflow/.local/lib/python3.12/site-packages/airflow/cli/commands/task_command.py", line 256, in _run_task_by_selected_method
    return _run_raw_task(args, ti)
           ^^^^^^^^^^^^^^^^^^^^^^^
  File "/home/airflow/.local/lib/python3.12/site-packages/airflow/cli/commands/task_command.py", line 341, in _run_raw_task
    return ti._run_raw_task(
           ^^^^^^^^^^^^^^^^^
  File "/home/airflow/.local/lib/python3.12/site-packages/airflow/utils/session.py", line 97, in wrapper
    return func(*args, session=session, **kwargs)
           ^^^^^^^^^^^^^^^^^^^^^^^^^^^^^^^^^^^^^^
  File "/home/airflow/.local/lib/python3.12/site-packages/airflow/models/taskinstance.py", line 3004, in _run_raw_task
    return _run_raw_task(
           ^^^^^^^^^^^^^^
  File "/home/airflow/.local/lib/python3.12/site-packages/airflow/models/taskinstance.py", line 273, in _run_raw_task
    TaskInstance._execute_task_with_callbacks(
  File "/home/airflow/.local/lib/python3.12/site-packages/airflow/models/taskinstance.py", line 3158, in _execute_task_with_callbacks
    result = self._execute_task(context, task_orig)
             ^^^^^^^^^^^^^^^^^^^^^^^^^^^^^^^^^^^^^^
  File "/home/airflow/.local/lib/python3.12/site-packages/airflow/models/taskinstance.py", line 3182, in _execute_task
    return _execute_task(self, context, task_orig)
           ^^^^^^^^^^^^^^^^^^^^^^^^^^^^^^^^^^^^^^^
  File "/home/airflow/.local/lib/python3.12/site-packages/airflow/models/taskinstance.py", line 767, in _execute_task
    result = _execute_callable(context=context, **execute_callable_kwargs)
             ^^^^^^^^^^^^^^^^^^^^^^^^^^^^^^^^^^^^^^^^^^^^^^^^^^^^^^^^^^^^^
  File "/home/airflow/.local/lib/python3.12/site-packages/airflow/models/taskinstance.py", line 733, in _execute_callable
    return ExecutionCallableRunner(
           ^^^^^^^^^^^^^^^^^^^^^^^^
  File "/home/airflow/.local/lib/python3.12/site-packages/airflow/utils/operator_helpers.py", line 252, in run
    return self.func(*args, **kwargs)
           ^^^^^^^^^^^^^^^^^^^^^^^^^^
  File "/home/airflow/.local/lib/python3.12/site-packages/airflow/models/baseoperator.py", line 406, in wrapper
    return func(self, *args, **kwargs)
           ^^^^^^^^^^^^^^^^^^^^^^^^^^^
  File "/home/airflow/.local/lib/python3.12/site-packages/airflow/operators/bash.py", line 249, in execute
    raise AirflowException(
airflow.exceptions.AirflowException: Bash command failed. The command returned a non-zero exit code 2.
[2025-04-15T07:19:12.068+0000] {local_task_job_runner.py:266} INFO - Task exited with return code 1
[2025-04-15T07:19:12.180+0000] {taskinstance.py:3900} INFO - 0 downstream tasks scheduled from follow-on schedule check
[2025-04-15T07:19:12.187+0000] {local_task_job_runner.py:245} INFO - ::endgroup::
