[2025-03-06T22:51:01.761+0000] {processor.py:186} INFO - Started process (PID=199) to work on /opt/airflow/dags/lab1_ML.py
[2025-03-06T22:51:01.765+0000] {processor.py:914} INFO - Processing file /opt/airflow/dags/lab1_ML.py for tasks to queue
[2025-03-06T22:51:01.769+0000] {logging_mixin.py:190} INFO - [2025-03-06T22:51:01.768+0000] {dagbag.py:587} INFO - Filling up the DagBag from /opt/airflow/dags/lab1_ML.py
[2025-03-06T22:51:01.801+0000] {logging_mixin.py:190} INFO - [2025-03-06T22:51:01.800+0000] {base.py:84} INFO - Retrieving connection 'snowflake_conn'
[2025-03-06T22:51:01.805+0000] {logging_mixin.py:190} INFO - [2025-03-06T22:51:01.804+0000] {connection.py:413} INFO - Snowflake Connector for Python Version: 3.12.1, Python Version: 3.12.5, Platform: Linux-6.12.5-linuxkit-aarch64-with-glibc2.36
[2025-03-06T22:51:01.808+0000] {logging_mixin.py:190} INFO - [2025-03-06T22:51:01.808+0000] {connection.py:1196} INFO - Connecting to GLOBAL Snowflake domain
[2025-03-06T22:51:01.808+0000] {logging_mixin.py:190} INFO - [2025-03-06T22:51:01.808+0000] {connection.py:1277} INFO - This connection is in OCSP Fail Open Mode. TLS Certificates would be checked for validity and revocation status. Any other Certificate Revocation related exceptions or OCSP Responder failures would be disregarded in favor of connectivity.
[2025-03-06T22:51:02.400+0000] {logging_mixin.py:190} INFO - [2025-03-06T22:51:02.399+0000] {dagbag.py:386} ERROR - Failed to import: /opt/airflow/dags/lab1_ML.py
Traceback (most recent call last):
  File "/home/airflow/.local/lib/python3.12/site-packages/airflow/models/dagbag.py", line 382, in parse
    loader.exec_module(new_module)
  File "<frozen importlib._bootstrap_external>", line 995, in exec_module
  File "<frozen importlib._bootstrap>", line 488, in _call_with_frames_removed
  File "/opt/airflow/dags/lab1_ML.py", line 91, in <module>
    cur = return_snowflake_conn()
          ^^^^^^^^^^^^^^^^^^^^^^^
  File "/opt/airflow/dags/lab1_ML.py", line 13, in return_snowflake_conn
    conn = hook.get_conn()
           ^^^^^^^^^^^^^^^
  File "/home/airflow/.local/lib/python3.12/site-packages/airflow/providers/snowflake/hooks/snowflake.py", line 300, in get_conn
    conn = connector.connect(**conn_config)
           ^^^^^^^^^^^^^^^^^^^^^^^^^^^^^^^^
  File "/home/airflow/.local/lib/python3.12/site-packages/snowflake/connector/__init__.py", line 55, in Connect
    return SnowflakeConnection(**kwargs)
           ^^^^^^^^^^^^^^^^^^^^^^^^^^^^^
  File "/home/airflow/.local/lib/python3.12/site-packages/snowflake/connector/connection.py", line 456, in __init__
    self.connect(**kwargs)
  File "/home/airflow/.local/lib/python3.12/site-packages/snowflake/connector/connection.py", line 771, in connect
    self.__open_connection()
  File "/home/airflow/.local/lib/python3.12/site-packages/snowflake/connector/connection.py", line 1099, in __open_connection
    self.authenticate_with_retry(self.auth_class)
  File "/home/airflow/.local/lib/python3.12/site-packages/snowflake/connector/connection.py", line 1386, in authenticate_with_retry
    self._authenticate(auth_instance)
  File "/home/airflow/.local/lib/python3.12/site-packages/snowflake/connector/connection.py", line 1414, in _authenticate
    auth.authenticate(
  File "/home/airflow/.local/lib/python3.12/site-packages/snowflake/connector/auth/_auth.py", line 401, in authenticate
    Error.errorhandler_wrapper(
  File "/home/airflow/.local/lib/python3.12/site-packages/snowflake/connector/errors.py", line 284, in errorhandler_wrapper
    handed_over = Error.hand_to_other_handler(
                  ^^^^^^^^^^^^^^^^^^^^^^^^^^^^
  File "/home/airflow/.local/lib/python3.12/site-packages/snowflake/connector/errors.py", line 342, in hand_to_other_handler
    connection.errorhandler(connection, cursor, error_class, error_value)
  File "/home/airflow/.local/lib/python3.12/site-packages/snowflake/connector/errors.py", line 215, in default_errorhandler
    raise error_class(
snowflake.connector.errors.DatabaseError: 250001 (08001): None: Failed to connect to DB: wbb10936.snowflakecomputing.com:443. Your free trial has ended and all of your virtual warehouses have been suspended. Add billing information in the Snowflake web UI to continue using the full set of Snowflake features.
[2025-03-06T22:51:02.401+0000] {processor.py:927} WARNING - No viable dags retrieved from /opt/airflow/dags/lab1_ML.py
[2025-03-06T22:51:02.423+0000] {processor.py:208} INFO - Processing /opt/airflow/dags/lab1_ML.py took 0.668 seconds
[2025-03-06T22:51:32.928+0000] {processor.py:186} INFO - Started process (PID=258) to work on /opt/airflow/dags/lab1_ML.py
[2025-03-06T22:51:32.929+0000] {processor.py:914} INFO - Processing file /opt/airflow/dags/lab1_ML.py for tasks to queue
[2025-03-06T22:51:32.933+0000] {logging_mixin.py:190} INFO - [2025-03-06T22:51:32.933+0000] {dagbag.py:587} INFO - Filling up the DagBag from /opt/airflow/dags/lab1_ML.py
[2025-03-06T22:51:32.966+0000] {logging_mixin.py:190} INFO - [2025-03-06T22:51:32.966+0000] {base.py:84} INFO - Retrieving connection 'snowflake_conn'
[2025-03-06T22:51:32.969+0000] {logging_mixin.py:190} INFO - [2025-03-06T22:51:32.969+0000] {connection.py:413} INFO - Snowflake Connector for Python Version: 3.12.1, Python Version: 3.12.5, Platform: Linux-6.12.5-linuxkit-aarch64-with-glibc2.36
[2025-03-06T22:51:32.969+0000] {logging_mixin.py:190} INFO - [2025-03-06T22:51:32.969+0000] {connection.py:1196} INFO - Connecting to GLOBAL Snowflake domain
[2025-03-06T22:51:32.970+0000] {logging_mixin.py:190} INFO - [2025-03-06T22:51:32.970+0000] {connection.py:1277} INFO - This connection is in OCSP Fail Open Mode. TLS Certificates would be checked for validity and revocation status. Any other Certificate Revocation related exceptions or OCSP Responder failures would be disregarded in favor of connectivity.
[2025-03-06T22:51:33.379+0000] {logging_mixin.py:190} INFO - [2025-03-06T22:51:33.376+0000] {dagbag.py:386} ERROR - Failed to import: /opt/airflow/dags/lab1_ML.py
Traceback (most recent call last):
  File "/home/airflow/.local/lib/python3.12/site-packages/airflow/models/dagbag.py", line 382, in parse
    loader.exec_module(new_module)
  File "<frozen importlib._bootstrap_external>", line 995, in exec_module
  File "<frozen importlib._bootstrap>", line 488, in _call_with_frames_removed
  File "/opt/airflow/dags/lab1_ML.py", line 91, in <module>
    cur = return_snowflake_conn()
          ^^^^^^^^^^^^^^^^^^^^^^^
  File "/opt/airflow/dags/lab1_ML.py", line 13, in return_snowflake_conn
    conn = hook.get_conn()
           ^^^^^^^^^^^^^^^
  File "/home/airflow/.local/lib/python3.12/site-packages/airflow/providers/snowflake/hooks/snowflake.py", line 300, in get_conn
    conn = connector.connect(**conn_config)
           ^^^^^^^^^^^^^^^^^^^^^^^^^^^^^^^^
  File "/home/airflow/.local/lib/python3.12/site-packages/snowflake/connector/__init__.py", line 55, in Connect
    return SnowflakeConnection(**kwargs)
           ^^^^^^^^^^^^^^^^^^^^^^^^^^^^^
  File "/home/airflow/.local/lib/python3.12/site-packages/snowflake/connector/connection.py", line 456, in __init__
    self.connect(**kwargs)
  File "/home/airflow/.local/lib/python3.12/site-packages/snowflake/connector/connection.py", line 771, in connect
    self.__open_connection()
  File "/home/airflow/.local/lib/python3.12/site-packages/snowflake/connector/connection.py", line 1099, in __open_connection
    self.authenticate_with_retry(self.auth_class)
  File "/home/airflow/.local/lib/python3.12/site-packages/snowflake/connector/connection.py", line 1386, in authenticate_with_retry
    self._authenticate(auth_instance)
  File "/home/airflow/.local/lib/python3.12/site-packages/snowflake/connector/connection.py", line 1414, in _authenticate
    auth.authenticate(
  File "/home/airflow/.local/lib/python3.12/site-packages/snowflake/connector/auth/_auth.py", line 401, in authenticate
    Error.errorhandler_wrapper(
  File "/home/airflow/.local/lib/python3.12/site-packages/snowflake/connector/errors.py", line 284, in errorhandler_wrapper
    handed_over = Error.hand_to_other_handler(
                  ^^^^^^^^^^^^^^^^^^^^^^^^^^^^
  File "/home/airflow/.local/lib/python3.12/site-packages/snowflake/connector/errors.py", line 342, in hand_to_other_handler
    connection.errorhandler(connection, cursor, error_class, error_value)
  File "/home/airflow/.local/lib/python3.12/site-packages/snowflake/connector/errors.py", line 215, in default_errorhandler
    raise error_class(
snowflake.connector.errors.DatabaseError: 250001 (08001): None: Failed to connect to DB: wbb10936.snowflakecomputing.com:443. Your free trial has ended and all of your virtual warehouses have been suspended. Add billing information in the Snowflake web UI to continue using the full set of Snowflake features.
[2025-03-06T22:51:33.382+0000] {processor.py:927} WARNING - No viable dags retrieved from /opt/airflow/dags/lab1_ML.py
[2025-03-06T22:51:33.393+0000] {processor.py:208} INFO - Processing /opt/airflow/dags/lab1_ML.py took 0.472 seconds
[2025-03-06T22:52:03.885+0000] {processor.py:186} INFO - Started process (PID=290) to work on /opt/airflow/dags/lab1_ML.py
[2025-03-06T22:52:03.886+0000] {processor.py:914} INFO - Processing file /opt/airflow/dags/lab1_ML.py for tasks to queue
[2025-03-06T22:52:03.888+0000] {logging_mixin.py:190} INFO - [2025-03-06T22:52:03.887+0000] {dagbag.py:587} INFO - Filling up the DagBag from /opt/airflow/dags/lab1_ML.py
[2025-03-06T22:52:03.923+0000] {logging_mixin.py:190} INFO - [2025-03-06T22:52:03.923+0000] {base.py:84} INFO - Retrieving connection 'snowflake_conn'
[2025-03-06T22:52:03.924+0000] {logging_mixin.py:190} INFO - [2025-03-06T22:52:03.924+0000] {connection.py:413} INFO - Snowflake Connector for Python Version: 3.12.1, Python Version: 3.12.5, Platform: Linux-6.12.5-linuxkit-aarch64-with-glibc2.36
[2025-03-06T22:52:03.926+0000] {logging_mixin.py:190} INFO - [2025-03-06T22:52:03.926+0000] {connection.py:1196} INFO - Connecting to GLOBAL Snowflake domain
[2025-03-06T22:52:03.926+0000] {logging_mixin.py:190} INFO - [2025-03-06T22:52:03.926+0000] {connection.py:1277} INFO - This connection is in OCSP Fail Open Mode. TLS Certificates would be checked for validity and revocation status. Any other Certificate Revocation related exceptions or OCSP Responder failures would be disregarded in favor of connectivity.
[2025-03-06T22:52:04.224+0000] {logging_mixin.py:190} INFO - [2025-03-06T22:52:04.222+0000] {dagbag.py:386} ERROR - Failed to import: /opt/airflow/dags/lab1_ML.py
Traceback (most recent call last):
  File "/home/airflow/.local/lib/python3.12/site-packages/airflow/models/dagbag.py", line 382, in parse
    loader.exec_module(new_module)
  File "<frozen importlib._bootstrap_external>", line 995, in exec_module
  File "<frozen importlib._bootstrap>", line 488, in _call_with_frames_removed
  File "/opt/airflow/dags/lab1_ML.py", line 91, in <module>
    cur = return_snowflake_conn()
          ^^^^^^^^^^^^^^^^^^^^^^^
  File "/opt/airflow/dags/lab1_ML.py", line 13, in return_snowflake_conn
    conn = hook.get_conn()
           ^^^^^^^^^^^^^^^
  File "/home/airflow/.local/lib/python3.12/site-packages/airflow/providers/snowflake/hooks/snowflake.py", line 300, in get_conn
    conn = connector.connect(**conn_config)
           ^^^^^^^^^^^^^^^^^^^^^^^^^^^^^^^^
  File "/home/airflow/.local/lib/python3.12/site-packages/snowflake/connector/__init__.py", line 55, in Connect
    return SnowflakeConnection(**kwargs)
           ^^^^^^^^^^^^^^^^^^^^^^^^^^^^^
  File "/home/airflow/.local/lib/python3.12/site-packages/snowflake/connector/connection.py", line 456, in __init__
    self.connect(**kwargs)
  File "/home/airflow/.local/lib/python3.12/site-packages/snowflake/connector/connection.py", line 771, in connect
    self.__open_connection()
  File "/home/airflow/.local/lib/python3.12/site-packages/snowflake/connector/connection.py", line 1099, in __open_connection
    self.authenticate_with_retry(self.auth_class)
  File "/home/airflow/.local/lib/python3.12/site-packages/snowflake/connector/connection.py", line 1386, in authenticate_with_retry
    self._authenticate(auth_instance)
  File "/home/airflow/.local/lib/python3.12/site-packages/snowflake/connector/connection.py", line 1414, in _authenticate
    auth.authenticate(
  File "/home/airflow/.local/lib/python3.12/site-packages/snowflake/connector/auth/_auth.py", line 401, in authenticate
    Error.errorhandler_wrapper(
  File "/home/airflow/.local/lib/python3.12/site-packages/snowflake/connector/errors.py", line 284, in errorhandler_wrapper
    handed_over = Error.hand_to_other_handler(
                  ^^^^^^^^^^^^^^^^^^^^^^^^^^^^
  File "/home/airflow/.local/lib/python3.12/site-packages/snowflake/connector/errors.py", line 342, in hand_to_other_handler
    connection.errorhandler(connection, cursor, error_class, error_value)
  File "/home/airflow/.local/lib/python3.12/site-packages/snowflake/connector/errors.py", line 215, in default_errorhandler
    raise error_class(
snowflake.connector.errors.DatabaseError: 250001 (08001): None: Failed to connect to DB: wbb10936.snowflakecomputing.com:443. Your free trial has ended and all of your virtual warehouses have been suspended. Add billing information in the Snowflake web UI to continue using the full set of Snowflake features.
[2025-03-06T22:52:04.225+0000] {processor.py:927} WARNING - No viable dags retrieved from /opt/airflow/dags/lab1_ML.py
[2025-03-06T22:52:04.233+0000] {processor.py:208} INFO - Processing /opt/airflow/dags/lab1_ML.py took 0.368 seconds
[2025-03-06T22:52:34.717+0000] {processor.py:186} INFO - Started process (PID=311) to work on /opt/airflow/dags/lab1_ML.py
[2025-03-06T22:52:34.722+0000] {processor.py:914} INFO - Processing file /opt/airflow/dags/lab1_ML.py for tasks to queue
[2025-03-06T22:52:34.727+0000] {logging_mixin.py:190} INFO - [2025-03-06T22:52:34.725+0000] {dagbag.py:587} INFO - Filling up the DagBag from /opt/airflow/dags/lab1_ML.py
[2025-03-06T22:52:34.753+0000] {logging_mixin.py:190} INFO - [2025-03-06T22:52:34.753+0000] {base.py:84} INFO - Retrieving connection 'snowflake_conn'
[2025-03-06T22:52:34.754+0000] {logging_mixin.py:190} INFO - [2025-03-06T22:52:34.754+0000] {connection.py:413} INFO - Snowflake Connector for Python Version: 3.12.1, Python Version: 3.12.5, Platform: Linux-6.12.5-linuxkit-aarch64-with-glibc2.36
[2025-03-06T22:52:34.755+0000] {logging_mixin.py:190} INFO - [2025-03-06T22:52:34.755+0000] {connection.py:1196} INFO - Connecting to GLOBAL Snowflake domain
[2025-03-06T22:52:34.755+0000] {logging_mixin.py:190} INFO - [2025-03-06T22:52:34.755+0000] {connection.py:1277} INFO - This connection is in OCSP Fail Open Mode. TLS Certificates would be checked for validity and revocation status. Any other Certificate Revocation related exceptions or OCSP Responder failures would be disregarded in favor of connectivity.
[2025-03-06T22:52:35.023+0000] {logging_mixin.py:190} INFO - [2025-03-06T22:52:35.021+0000] {dagbag.py:386} ERROR - Failed to import: /opt/airflow/dags/lab1_ML.py
Traceback (most recent call last):
  File "/home/airflow/.local/lib/python3.12/site-packages/airflow/models/dagbag.py", line 382, in parse
    loader.exec_module(new_module)
  File "<frozen importlib._bootstrap_external>", line 995, in exec_module
  File "<frozen importlib._bootstrap>", line 488, in _call_with_frames_removed
  File "/opt/airflow/dags/lab1_ML.py", line 91, in <module>
    cur = return_snowflake_conn()
          ^^^^^^^^^^^^^^^^^^^^^^^
  File "/opt/airflow/dags/lab1_ML.py", line 13, in return_snowflake_conn
    conn = hook.get_conn()
           ^^^^^^^^^^^^^^^
  File "/home/airflow/.local/lib/python3.12/site-packages/airflow/providers/snowflake/hooks/snowflake.py", line 300, in get_conn
    conn = connector.connect(**conn_config)
           ^^^^^^^^^^^^^^^^^^^^^^^^^^^^^^^^
  File "/home/airflow/.local/lib/python3.12/site-packages/snowflake/connector/__init__.py", line 55, in Connect
    return SnowflakeConnection(**kwargs)
           ^^^^^^^^^^^^^^^^^^^^^^^^^^^^^
  File "/home/airflow/.local/lib/python3.12/site-packages/snowflake/connector/connection.py", line 456, in __init__
    self.connect(**kwargs)
  File "/home/airflow/.local/lib/python3.12/site-packages/snowflake/connector/connection.py", line 771, in connect
    self.__open_connection()
  File "/home/airflow/.local/lib/python3.12/site-packages/snowflake/connector/connection.py", line 1099, in __open_connection
    self.authenticate_with_retry(self.auth_class)
  File "/home/airflow/.local/lib/python3.12/site-packages/snowflake/connector/connection.py", line 1386, in authenticate_with_retry
    self._authenticate(auth_instance)
  File "/home/airflow/.local/lib/python3.12/site-packages/snowflake/connector/connection.py", line 1414, in _authenticate
    auth.authenticate(
  File "/home/airflow/.local/lib/python3.12/site-packages/snowflake/connector/auth/_auth.py", line 401, in authenticate
    Error.errorhandler_wrapper(
  File "/home/airflow/.local/lib/python3.12/site-packages/snowflake/connector/errors.py", line 284, in errorhandler_wrapper
    handed_over = Error.hand_to_other_handler(
                  ^^^^^^^^^^^^^^^^^^^^^^^^^^^^
  File "/home/airflow/.local/lib/python3.12/site-packages/snowflake/connector/errors.py", line 342, in hand_to_other_handler
    connection.errorhandler(connection, cursor, error_class, error_value)
  File "/home/airflow/.local/lib/python3.12/site-packages/snowflake/connector/errors.py", line 215, in default_errorhandler
    raise error_class(
snowflake.connector.errors.DatabaseError: 250001 (08001): None: Failed to connect to DB: wbb10936.snowflakecomputing.com:443. Your free trial has ended and all of your virtual warehouses have been suspended. Add billing information in the Snowflake web UI to continue using the full set of Snowflake features.
[2025-03-06T22:52:35.024+0000] {processor.py:927} WARNING - No viable dags retrieved from /opt/airflow/dags/lab1_ML.py
[2025-03-06T22:52:35.033+0000] {processor.py:208} INFO - Processing /opt/airflow/dags/lab1_ML.py took 0.325 seconds
[2025-03-06T22:53:05.524+0000] {processor.py:186} INFO - Started process (PID=332) to work on /opt/airflow/dags/lab1_ML.py
[2025-03-06T22:53:05.525+0000] {processor.py:914} INFO - Processing file /opt/airflow/dags/lab1_ML.py for tasks to queue
[2025-03-06T22:53:05.526+0000] {logging_mixin.py:190} INFO - [2025-03-06T22:53:05.526+0000] {dagbag.py:587} INFO - Filling up the DagBag from /opt/airflow/dags/lab1_ML.py
[2025-03-06T22:53:05.552+0000] {logging_mixin.py:190} INFO - [2025-03-06T22:53:05.551+0000] {base.py:84} INFO - Retrieving connection 'snowflake_conn'
[2025-03-06T22:53:05.554+0000] {logging_mixin.py:190} INFO - [2025-03-06T22:53:05.554+0000] {connection.py:413} INFO - Snowflake Connector for Python Version: 3.12.1, Python Version: 3.12.5, Platform: Linux-6.12.5-linuxkit-aarch64-with-glibc2.36
[2025-03-06T22:53:05.558+0000] {logging_mixin.py:190} INFO - [2025-03-06T22:53:05.558+0000] {connection.py:1196} INFO - Connecting to GLOBAL Snowflake domain
[2025-03-06T22:53:05.559+0000] {logging_mixin.py:190} INFO - [2025-03-06T22:53:05.559+0000] {connection.py:1277} INFO - This connection is in OCSP Fail Open Mode. TLS Certificates would be checked for validity and revocation status. Any other Certificate Revocation related exceptions or OCSP Responder failures would be disregarded in favor of connectivity.
[2025-03-06T22:53:05.842+0000] {logging_mixin.py:190} INFO - [2025-03-06T22:53:05.841+0000] {dagbag.py:386} ERROR - Failed to import: /opt/airflow/dags/lab1_ML.py
Traceback (most recent call last):
  File "/home/airflow/.local/lib/python3.12/site-packages/airflow/models/dagbag.py", line 382, in parse
    loader.exec_module(new_module)
  File "<frozen importlib._bootstrap_external>", line 995, in exec_module
  File "<frozen importlib._bootstrap>", line 488, in _call_with_frames_removed
  File "/opt/airflow/dags/lab1_ML.py", line 91, in <module>
    cur = return_snowflake_conn()
          ^^^^^^^^^^^^^^^^^^^^^^^
  File "/opt/airflow/dags/lab1_ML.py", line 13, in return_snowflake_conn
    conn = hook.get_conn()
           ^^^^^^^^^^^^^^^
  File "/home/airflow/.local/lib/python3.12/site-packages/airflow/providers/snowflake/hooks/snowflake.py", line 300, in get_conn
    conn = connector.connect(**conn_config)
           ^^^^^^^^^^^^^^^^^^^^^^^^^^^^^^^^
  File "/home/airflow/.local/lib/python3.12/site-packages/snowflake/connector/__init__.py", line 55, in Connect
    return SnowflakeConnection(**kwargs)
           ^^^^^^^^^^^^^^^^^^^^^^^^^^^^^
  File "/home/airflow/.local/lib/python3.12/site-packages/snowflake/connector/connection.py", line 456, in __init__
    self.connect(**kwargs)
  File "/home/airflow/.local/lib/python3.12/site-packages/snowflake/connector/connection.py", line 771, in connect
    self.__open_connection()
  File "/home/airflow/.local/lib/python3.12/site-packages/snowflake/connector/connection.py", line 1099, in __open_connection
    self.authenticate_with_retry(self.auth_class)
  File "/home/airflow/.local/lib/python3.12/site-packages/snowflake/connector/connection.py", line 1386, in authenticate_with_retry
    self._authenticate(auth_instance)
  File "/home/airflow/.local/lib/python3.12/site-packages/snowflake/connector/connection.py", line 1414, in _authenticate
    auth.authenticate(
  File "/home/airflow/.local/lib/python3.12/site-packages/snowflake/connector/auth/_auth.py", line 401, in authenticate
    Error.errorhandler_wrapper(
  File "/home/airflow/.local/lib/python3.12/site-packages/snowflake/connector/errors.py", line 284, in errorhandler_wrapper
    handed_over = Error.hand_to_other_handler(
                  ^^^^^^^^^^^^^^^^^^^^^^^^^^^^
  File "/home/airflow/.local/lib/python3.12/site-packages/snowflake/connector/errors.py", line 342, in hand_to_other_handler
    connection.errorhandler(connection, cursor, error_class, error_value)
  File "/home/airflow/.local/lib/python3.12/site-packages/snowflake/connector/errors.py", line 215, in default_errorhandler
    raise error_class(
snowflake.connector.errors.DatabaseError: 250001 (08001): None: Failed to connect to DB: wbb10936.snowflakecomputing.com:443. Your free trial has ended and all of your virtual warehouses have been suspended. Add billing information in the Snowflake web UI to continue using the full set of Snowflake features.
[2025-03-06T22:53:05.844+0000] {processor.py:927} WARNING - No viable dags retrieved from /opt/airflow/dags/lab1_ML.py
[2025-03-06T22:53:05.853+0000] {processor.py:208} INFO - Processing /opt/airflow/dags/lab1_ML.py took 0.335 seconds
[2025-03-06T22:53:36.386+0000] {processor.py:186} INFO - Started process (PID=353) to work on /opt/airflow/dags/lab1_ML.py
[2025-03-06T22:53:36.410+0000] {processor.py:914} INFO - Processing file /opt/airflow/dags/lab1_ML.py for tasks to queue
[2025-03-06T22:53:36.412+0000] {logging_mixin.py:190} INFO - [2025-03-06T22:53:36.412+0000] {dagbag.py:587} INFO - Filling up the DagBag from /opt/airflow/dags/lab1_ML.py
[2025-03-06T22:53:36.472+0000] {logging_mixin.py:190} INFO - [2025-03-06T22:53:36.471+0000] {base.py:84} INFO - Retrieving connection 'snowflake_conn'
[2025-03-06T22:53:36.473+0000] {logging_mixin.py:190} INFO - [2025-03-06T22:53:36.473+0000] {connection.py:413} INFO - Snowflake Connector for Python Version: 3.12.1, Python Version: 3.12.5, Platform: Linux-6.12.5-linuxkit-aarch64-with-glibc2.36
[2025-03-06T22:53:36.475+0000] {logging_mixin.py:190} INFO - [2025-03-06T22:53:36.475+0000] {connection.py:1196} INFO - Connecting to GLOBAL Snowflake domain
[2025-03-06T22:53:36.477+0000] {logging_mixin.py:190} INFO - [2025-03-06T22:53:36.477+0000] {connection.py:1277} INFO - This connection is in OCSP Fail Open Mode. TLS Certificates would be checked for validity and revocation status. Any other Certificate Revocation related exceptions or OCSP Responder failures would be disregarded in favor of connectivity.
[2025-03-06T22:53:36.852+0000] {logging_mixin.py:190} INFO - [2025-03-06T22:53:36.851+0000] {dagbag.py:386} ERROR - Failed to import: /opt/airflow/dags/lab1_ML.py
Traceback (most recent call last):
  File "/home/airflow/.local/lib/python3.12/site-packages/airflow/models/dagbag.py", line 382, in parse
    loader.exec_module(new_module)
  File "<frozen importlib._bootstrap_external>", line 995, in exec_module
  File "<frozen importlib._bootstrap>", line 488, in _call_with_frames_removed
  File "/opt/airflow/dags/lab1_ML.py", line 91, in <module>
    cur = return_snowflake_conn()
          ^^^^^^^^^^^^^^^^^^^^^^^
  File "/opt/airflow/dags/lab1_ML.py", line 13, in return_snowflake_conn
    conn = hook.get_conn()
           ^^^^^^^^^^^^^^^
  File "/home/airflow/.local/lib/python3.12/site-packages/airflow/providers/snowflake/hooks/snowflake.py", line 300, in get_conn
    conn = connector.connect(**conn_config)
           ^^^^^^^^^^^^^^^^^^^^^^^^^^^^^^^^
  File "/home/airflow/.local/lib/python3.12/site-packages/snowflake/connector/__init__.py", line 55, in Connect
    return SnowflakeConnection(**kwargs)
           ^^^^^^^^^^^^^^^^^^^^^^^^^^^^^
  File "/home/airflow/.local/lib/python3.12/site-packages/snowflake/connector/connection.py", line 456, in __init__
    self.connect(**kwargs)
  File "/home/airflow/.local/lib/python3.12/site-packages/snowflake/connector/connection.py", line 771, in connect
    self.__open_connection()
  File "/home/airflow/.local/lib/python3.12/site-packages/snowflake/connector/connection.py", line 1099, in __open_connection
    self.authenticate_with_retry(self.auth_class)
  File "/home/airflow/.local/lib/python3.12/site-packages/snowflake/connector/connection.py", line 1386, in authenticate_with_retry
    self._authenticate(auth_instance)
  File "/home/airflow/.local/lib/python3.12/site-packages/snowflake/connector/connection.py", line 1414, in _authenticate
    auth.authenticate(
  File "/home/airflow/.local/lib/python3.12/site-packages/snowflake/connector/auth/_auth.py", line 401, in authenticate
    Error.errorhandler_wrapper(
  File "/home/airflow/.local/lib/python3.12/site-packages/snowflake/connector/errors.py", line 284, in errorhandler_wrapper
    handed_over = Error.hand_to_other_handler(
                  ^^^^^^^^^^^^^^^^^^^^^^^^^^^^
  File "/home/airflow/.local/lib/python3.12/site-packages/snowflake/connector/errors.py", line 342, in hand_to_other_handler
    connection.errorhandler(connection, cursor, error_class, error_value)
  File "/home/airflow/.local/lib/python3.12/site-packages/snowflake/connector/errors.py", line 215, in default_errorhandler
    raise error_class(
snowflake.connector.errors.DatabaseError: 250001 (08001): None: Failed to connect to DB: wbb10936.snowflakecomputing.com:443. Your free trial has ended and all of your virtual warehouses have been suspended. Add billing information in the Snowflake web UI to continue using the full set of Snowflake features.
[2025-03-06T22:53:36.852+0000] {processor.py:927} WARNING - No viable dags retrieved from /opt/airflow/dags/lab1_ML.py
[2025-03-06T22:53:36.858+0000] {processor.py:208} INFO - Processing /opt/airflow/dags/lab1_ML.py took 0.485 seconds
[2025-03-06T22:54:07.384+0000] {processor.py:186} INFO - Started process (PID=374) to work on /opt/airflow/dags/lab1_ML.py
[2025-03-06T22:54:07.385+0000] {processor.py:914} INFO - Processing file /opt/airflow/dags/lab1_ML.py for tasks to queue
[2025-03-06T22:54:07.387+0000] {logging_mixin.py:190} INFO - [2025-03-06T22:54:07.386+0000] {dagbag.py:587} INFO - Filling up the DagBag from /opt/airflow/dags/lab1_ML.py
[2025-03-06T22:54:07.415+0000] {logging_mixin.py:190} INFO - [2025-03-06T22:54:07.415+0000] {base.py:84} INFO - Retrieving connection 'snowflake_conn'
[2025-03-06T22:54:07.417+0000] {logging_mixin.py:190} INFO - [2025-03-06T22:54:07.416+0000] {connection.py:413} INFO - Snowflake Connector for Python Version: 3.12.1, Python Version: 3.12.5, Platform: Linux-6.12.5-linuxkit-aarch64-with-glibc2.36
[2025-03-06T22:54:07.417+0000] {logging_mixin.py:190} INFO - [2025-03-06T22:54:07.417+0000] {connection.py:1196} INFO - Connecting to GLOBAL Snowflake domain
[2025-03-06T22:54:07.418+0000] {logging_mixin.py:190} INFO - [2025-03-06T22:54:07.418+0000] {connection.py:1277} INFO - This connection is in OCSP Fail Open Mode. TLS Certificates would be checked for validity and revocation status. Any other Certificate Revocation related exceptions or OCSP Responder failures would be disregarded in favor of connectivity.
[2025-03-06T22:54:07.929+0000] {logging_mixin.py:190} INFO - [2025-03-06T22:54:07.926+0000] {dagbag.py:386} ERROR - Failed to import: /opt/airflow/dags/lab1_ML.py
Traceback (most recent call last):
  File "/home/airflow/.local/lib/python3.12/site-packages/airflow/models/dagbag.py", line 382, in parse
    loader.exec_module(new_module)
  File "<frozen importlib._bootstrap_external>", line 995, in exec_module
  File "<frozen importlib._bootstrap>", line 488, in _call_with_frames_removed
  File "/opt/airflow/dags/lab1_ML.py", line 91, in <module>
    cur = return_snowflake_conn()
          ^^^^^^^^^^^^^^^^^^^^^^^
  File "/opt/airflow/dags/lab1_ML.py", line 13, in return_snowflake_conn
    conn = hook.get_conn()
           ^^^^^^^^^^^^^^^
  File "/home/airflow/.local/lib/python3.12/site-packages/airflow/providers/snowflake/hooks/snowflake.py", line 300, in get_conn
    conn = connector.connect(**conn_config)
           ^^^^^^^^^^^^^^^^^^^^^^^^^^^^^^^^
  File "/home/airflow/.local/lib/python3.12/site-packages/snowflake/connector/__init__.py", line 55, in Connect
    return SnowflakeConnection(**kwargs)
           ^^^^^^^^^^^^^^^^^^^^^^^^^^^^^
  File "/home/airflow/.local/lib/python3.12/site-packages/snowflake/connector/connection.py", line 456, in __init__
    self.connect(**kwargs)
  File "/home/airflow/.local/lib/python3.12/site-packages/snowflake/connector/connection.py", line 771, in connect
    self.__open_connection()
  File "/home/airflow/.local/lib/python3.12/site-packages/snowflake/connector/connection.py", line 1099, in __open_connection
    self.authenticate_with_retry(self.auth_class)
  File "/home/airflow/.local/lib/python3.12/site-packages/snowflake/connector/connection.py", line 1386, in authenticate_with_retry
    self._authenticate(auth_instance)
  File "/home/airflow/.local/lib/python3.12/site-packages/snowflake/connector/connection.py", line 1414, in _authenticate
    auth.authenticate(
  File "/home/airflow/.local/lib/python3.12/site-packages/snowflake/connector/auth/_auth.py", line 401, in authenticate
    Error.errorhandler_wrapper(
  File "/home/airflow/.local/lib/python3.12/site-packages/snowflake/connector/errors.py", line 284, in errorhandler_wrapper
    handed_over = Error.hand_to_other_handler(
                  ^^^^^^^^^^^^^^^^^^^^^^^^^^^^
  File "/home/airflow/.local/lib/python3.12/site-packages/snowflake/connector/errors.py", line 342, in hand_to_other_handler
    connection.errorhandler(connection, cursor, error_class, error_value)
  File "/home/airflow/.local/lib/python3.12/site-packages/snowflake/connector/errors.py", line 215, in default_errorhandler
    raise error_class(
snowflake.connector.errors.DatabaseError: 250001 (08001): None: Failed to connect to DB: wbb10936.snowflakecomputing.com:443. Your free trial has ended and all of your virtual warehouses have been suspended. Add billing information in the Snowflake web UI to continue using the full set of Snowflake features.
[2025-03-06T22:54:07.931+0000] {processor.py:927} WARNING - No viable dags retrieved from /opt/airflow/dags/lab1_ML.py
[2025-03-06T22:54:07.944+0000] {processor.py:208} INFO - Processing /opt/airflow/dags/lab1_ML.py took 0.568 seconds
[2025-03-06T22:54:38.358+0000] {processor.py:186} INFO - Started process (PID=395) to work on /opt/airflow/dags/lab1_ML.py
[2025-03-06T22:54:38.359+0000] {processor.py:914} INFO - Processing file /opt/airflow/dags/lab1_ML.py for tasks to queue
[2025-03-06T22:54:38.360+0000] {logging_mixin.py:190} INFO - [2025-03-06T22:54:38.360+0000] {dagbag.py:587} INFO - Filling up the DagBag from /opt/airflow/dags/lab1_ML.py
[2025-03-06T22:54:38.400+0000] {logging_mixin.py:190} INFO - [2025-03-06T22:54:38.399+0000] {base.py:84} INFO - Retrieving connection 'snowflake_conn'
[2025-03-06T22:54:38.401+0000] {logging_mixin.py:190} INFO - [2025-03-06T22:54:38.401+0000] {connection.py:413} INFO - Snowflake Connector for Python Version: 3.12.1, Python Version: 3.12.5, Platform: Linux-6.12.5-linuxkit-aarch64-with-glibc2.36
[2025-03-06T22:54:38.402+0000] {logging_mixin.py:190} INFO - [2025-03-06T22:54:38.402+0000] {connection.py:1196} INFO - Connecting to GLOBAL Snowflake domain
[2025-03-06T22:54:38.402+0000] {logging_mixin.py:190} INFO - [2025-03-06T22:54:38.402+0000] {connection.py:1277} INFO - This connection is in OCSP Fail Open Mode. TLS Certificates would be checked for validity and revocation status. Any other Certificate Revocation related exceptions or OCSP Responder failures would be disregarded in favor of connectivity.
[2025-03-06T22:54:38.710+0000] {logging_mixin.py:190} INFO - [2025-03-06T22:54:38.704+0000] {dagbag.py:386} ERROR - Failed to import: /opt/airflow/dags/lab1_ML.py
Traceback (most recent call last):
  File "/home/airflow/.local/lib/python3.12/site-packages/airflow/models/dagbag.py", line 382, in parse
    loader.exec_module(new_module)
  File "<frozen importlib._bootstrap_external>", line 995, in exec_module
  File "<frozen importlib._bootstrap>", line 488, in _call_with_frames_removed
  File "/opt/airflow/dags/lab1_ML.py", line 91, in <module>
    cur = return_snowflake_conn()
          ^^^^^^^^^^^^^^^^^^^^^^^
  File "/opt/airflow/dags/lab1_ML.py", line 13, in return_snowflake_conn
    conn = hook.get_conn()
           ^^^^^^^^^^^^^^^
  File "/home/airflow/.local/lib/python3.12/site-packages/airflow/providers/snowflake/hooks/snowflake.py", line 300, in get_conn
    conn = connector.connect(**conn_config)
           ^^^^^^^^^^^^^^^^^^^^^^^^^^^^^^^^
  File "/home/airflow/.local/lib/python3.12/site-packages/snowflake/connector/__init__.py", line 55, in Connect
    return SnowflakeConnection(**kwargs)
           ^^^^^^^^^^^^^^^^^^^^^^^^^^^^^
  File "/home/airflow/.local/lib/python3.12/site-packages/snowflake/connector/connection.py", line 456, in __init__
    self.connect(**kwargs)
  File "/home/airflow/.local/lib/python3.12/site-packages/snowflake/connector/connection.py", line 771, in connect
    self.__open_connection()
  File "/home/airflow/.local/lib/python3.12/site-packages/snowflake/connector/connection.py", line 1099, in __open_connection
    self.authenticate_with_retry(self.auth_class)
  File "/home/airflow/.local/lib/python3.12/site-packages/snowflake/connector/connection.py", line 1386, in authenticate_with_retry
    self._authenticate(auth_instance)
  File "/home/airflow/.local/lib/python3.12/site-packages/snowflake/connector/connection.py", line 1414, in _authenticate
    auth.authenticate(
  File "/home/airflow/.local/lib/python3.12/site-packages/snowflake/connector/auth/_auth.py", line 401, in authenticate
    Error.errorhandler_wrapper(
  File "/home/airflow/.local/lib/python3.12/site-packages/snowflake/connector/errors.py", line 284, in errorhandler_wrapper
    handed_over = Error.hand_to_other_handler(
                  ^^^^^^^^^^^^^^^^^^^^^^^^^^^^
  File "/home/airflow/.local/lib/python3.12/site-packages/snowflake/connector/errors.py", line 342, in hand_to_other_handler
    connection.errorhandler(connection, cursor, error_class, error_value)
  File "/home/airflow/.local/lib/python3.12/site-packages/snowflake/connector/errors.py", line 215, in default_errorhandler
    raise error_class(
snowflake.connector.errors.DatabaseError: 250001 (08001): None: Failed to connect to DB: wbb10936.snowflakecomputing.com:443. Your free trial has ended and all of your virtual warehouses have been suspended. Add billing information in the Snowflake web UI to continue using the full set of Snowflake features.
[2025-03-06T22:54:38.711+0000] {processor.py:927} WARNING - No viable dags retrieved from /opt/airflow/dags/lab1_ML.py
[2025-03-06T22:54:38.720+0000] {processor.py:208} INFO - Processing /opt/airflow/dags/lab1_ML.py took 0.373 seconds
[2025-03-06T22:55:09.271+0000] {processor.py:186} INFO - Started process (PID=416) to work on /opt/airflow/dags/lab1_ML.py
[2025-03-06T22:55:09.274+0000] {processor.py:914} INFO - Processing file /opt/airflow/dags/lab1_ML.py for tasks to queue
[2025-03-06T22:55:09.278+0000] {logging_mixin.py:190} INFO - [2025-03-06T22:55:09.277+0000] {dagbag.py:587} INFO - Filling up the DagBag from /opt/airflow/dags/lab1_ML.py
[2025-03-06T22:55:09.318+0000] {logging_mixin.py:190} INFO - [2025-03-06T22:55:09.318+0000] {base.py:84} INFO - Retrieving connection 'snowflake_conn'
[2025-03-06T22:55:09.319+0000] {logging_mixin.py:190} INFO - [2025-03-06T22:55:09.319+0000] {connection.py:413} INFO - Snowflake Connector for Python Version: 3.12.1, Python Version: 3.12.5, Platform: Linux-6.12.5-linuxkit-aarch64-with-glibc2.36
[2025-03-06T22:55:09.320+0000] {logging_mixin.py:190} INFO - [2025-03-06T22:55:09.320+0000] {connection.py:1196} INFO - Connecting to GLOBAL Snowflake domain
[2025-03-06T22:55:09.320+0000] {logging_mixin.py:190} INFO - [2025-03-06T22:55:09.320+0000] {connection.py:1277} INFO - This connection is in OCSP Fail Open Mode. TLS Certificates would be checked for validity and revocation status. Any other Certificate Revocation related exceptions or OCSP Responder failures would be disregarded in favor of connectivity.
[2025-03-06T22:55:09.640+0000] {logging_mixin.py:190} INFO - [2025-03-06T22:55:09.639+0000] {dagbag.py:386} ERROR - Failed to import: /opt/airflow/dags/lab1_ML.py
Traceback (most recent call last):
  File "/home/airflow/.local/lib/python3.12/site-packages/airflow/models/dagbag.py", line 382, in parse
    loader.exec_module(new_module)
  File "<frozen importlib._bootstrap_external>", line 995, in exec_module
  File "<frozen importlib._bootstrap>", line 488, in _call_with_frames_removed
  File "/opt/airflow/dags/lab1_ML.py", line 91, in <module>
    cur = return_snowflake_conn()
          ^^^^^^^^^^^^^^^^^^^^^^^
  File "/opt/airflow/dags/lab1_ML.py", line 13, in return_snowflake_conn
    conn = hook.get_conn()
           ^^^^^^^^^^^^^^^
  File "/home/airflow/.local/lib/python3.12/site-packages/airflow/providers/snowflake/hooks/snowflake.py", line 300, in get_conn
    conn = connector.connect(**conn_config)
           ^^^^^^^^^^^^^^^^^^^^^^^^^^^^^^^^
  File "/home/airflow/.local/lib/python3.12/site-packages/snowflake/connector/__init__.py", line 55, in Connect
    return SnowflakeConnection(**kwargs)
           ^^^^^^^^^^^^^^^^^^^^^^^^^^^^^
  File "/home/airflow/.local/lib/python3.12/site-packages/snowflake/connector/connection.py", line 456, in __init__
    self.connect(**kwargs)
  File "/home/airflow/.local/lib/python3.12/site-packages/snowflake/connector/connection.py", line 771, in connect
    self.__open_connection()
  File "/home/airflow/.local/lib/python3.12/site-packages/snowflake/connector/connection.py", line 1099, in __open_connection
    self.authenticate_with_retry(self.auth_class)
  File "/home/airflow/.local/lib/python3.12/site-packages/snowflake/connector/connection.py", line 1386, in authenticate_with_retry
    self._authenticate(auth_instance)
  File "/home/airflow/.local/lib/python3.12/site-packages/snowflake/connector/connection.py", line 1414, in _authenticate
    auth.authenticate(
  File "/home/airflow/.local/lib/python3.12/site-packages/snowflake/connector/auth/_auth.py", line 401, in authenticate
    Error.errorhandler_wrapper(
  File "/home/airflow/.local/lib/python3.12/site-packages/snowflake/connector/errors.py", line 284, in errorhandler_wrapper
    handed_over = Error.hand_to_other_handler(
                  ^^^^^^^^^^^^^^^^^^^^^^^^^^^^
  File "/home/airflow/.local/lib/python3.12/site-packages/snowflake/connector/errors.py", line 342, in hand_to_other_handler
    connection.errorhandler(connection, cursor, error_class, error_value)
  File "/home/airflow/.local/lib/python3.12/site-packages/snowflake/connector/errors.py", line 215, in default_errorhandler
    raise error_class(
snowflake.connector.errors.DatabaseError: 250001 (08001): None: Failed to connect to DB: wbb10936.snowflakecomputing.com:443. Your free trial has ended and all of your virtual warehouses have been suspended. Add billing information in the Snowflake web UI to continue using the full set of Snowflake features.
[2025-03-06T22:55:09.643+0000] {processor.py:927} WARNING - No viable dags retrieved from /opt/airflow/dags/lab1_ML.py
[2025-03-06T22:55:09.653+0000] {processor.py:208} INFO - Processing /opt/airflow/dags/lab1_ML.py took 0.391 seconds
[2025-03-06T22:55:40.154+0000] {processor.py:186} INFO - Started process (PID=437) to work on /opt/airflow/dags/lab1_ML.py
[2025-03-06T22:55:40.157+0000] {processor.py:914} INFO - Processing file /opt/airflow/dags/lab1_ML.py for tasks to queue
[2025-03-06T22:55:40.161+0000] {logging_mixin.py:190} INFO - [2025-03-06T22:55:40.160+0000] {dagbag.py:587} INFO - Filling up the DagBag from /opt/airflow/dags/lab1_ML.py
[2025-03-06T22:55:40.230+0000] {logging_mixin.py:190} INFO - [2025-03-06T22:55:40.230+0000] {base.py:84} INFO - Retrieving connection 'snowflake_conn'
[2025-03-06T22:55:40.231+0000] {logging_mixin.py:190} INFO - [2025-03-06T22:55:40.231+0000] {connection.py:413} INFO - Snowflake Connector for Python Version: 3.12.1, Python Version: 3.12.5, Platform: Linux-6.12.5-linuxkit-aarch64-with-glibc2.36
[2025-03-06T22:55:40.232+0000] {logging_mixin.py:190} INFO - [2025-03-06T22:55:40.232+0000] {connection.py:1196} INFO - Connecting to GLOBAL Snowflake domain
[2025-03-06T22:55:40.233+0000] {logging_mixin.py:190} INFO - [2025-03-06T22:55:40.232+0000] {connection.py:1277} INFO - This connection is in OCSP Fail Open Mode. TLS Certificates would be checked for validity and revocation status. Any other Certificate Revocation related exceptions or OCSP Responder failures would be disregarded in favor of connectivity.
[2025-03-06T22:55:40.556+0000] {logging_mixin.py:190} INFO - [2025-03-06T22:55:40.554+0000] {dagbag.py:386} ERROR - Failed to import: /opt/airflow/dags/lab1_ML.py
Traceback (most recent call last):
  File "/home/airflow/.local/lib/python3.12/site-packages/airflow/models/dagbag.py", line 382, in parse
    loader.exec_module(new_module)
  File "<frozen importlib._bootstrap_external>", line 995, in exec_module
  File "<frozen importlib._bootstrap>", line 488, in _call_with_frames_removed
  File "/opt/airflow/dags/lab1_ML.py", line 91, in <module>
    cur = return_snowflake_conn()
          ^^^^^^^^^^^^^^^^^^^^^^^
  File "/opt/airflow/dags/lab1_ML.py", line 13, in return_snowflake_conn
    conn = hook.get_conn()
           ^^^^^^^^^^^^^^^
  File "/home/airflow/.local/lib/python3.12/site-packages/airflow/providers/snowflake/hooks/snowflake.py", line 300, in get_conn
    conn = connector.connect(**conn_config)
           ^^^^^^^^^^^^^^^^^^^^^^^^^^^^^^^^
  File "/home/airflow/.local/lib/python3.12/site-packages/snowflake/connector/__init__.py", line 55, in Connect
    return SnowflakeConnection(**kwargs)
           ^^^^^^^^^^^^^^^^^^^^^^^^^^^^^
  File "/home/airflow/.local/lib/python3.12/site-packages/snowflake/connector/connection.py", line 456, in __init__
    self.connect(**kwargs)
  File "/home/airflow/.local/lib/python3.12/site-packages/snowflake/connector/connection.py", line 771, in connect
    self.__open_connection()
  File "/home/airflow/.local/lib/python3.12/site-packages/snowflake/connector/connection.py", line 1099, in __open_connection
    self.authenticate_with_retry(self.auth_class)
  File "/home/airflow/.local/lib/python3.12/site-packages/snowflake/connector/connection.py", line 1386, in authenticate_with_retry
    self._authenticate(auth_instance)
  File "/home/airflow/.local/lib/python3.12/site-packages/snowflake/connector/connection.py", line 1414, in _authenticate
    auth.authenticate(
  File "/home/airflow/.local/lib/python3.12/site-packages/snowflake/connector/auth/_auth.py", line 401, in authenticate
    Error.errorhandler_wrapper(
  File "/home/airflow/.local/lib/python3.12/site-packages/snowflake/connector/errors.py", line 284, in errorhandler_wrapper
    handed_over = Error.hand_to_other_handler(
                  ^^^^^^^^^^^^^^^^^^^^^^^^^^^^
  File "/home/airflow/.local/lib/python3.12/site-packages/snowflake/connector/errors.py", line 342, in hand_to_other_handler
    connection.errorhandler(connection, cursor, error_class, error_value)
  File "/home/airflow/.local/lib/python3.12/site-packages/snowflake/connector/errors.py", line 215, in default_errorhandler
    raise error_class(
snowflake.connector.errors.DatabaseError: 250001 (08001): None: Failed to connect to DB: wbb10936.snowflakecomputing.com:443. Your free trial has ended and all of your virtual warehouses have been suspended. Add billing information in the Snowflake web UI to continue using the full set of Snowflake features.
[2025-03-06T22:55:40.558+0000] {processor.py:927} WARNING - No viable dags retrieved from /opt/airflow/dags/lab1_ML.py
[2025-03-06T22:55:40.571+0000] {processor.py:208} INFO - Processing /opt/airflow/dags/lab1_ML.py took 0.430 seconds
[2025-03-06T22:56:11.040+0000] {processor.py:186} INFO - Started process (PID=464) to work on /opt/airflow/dags/lab1_ML.py
[2025-03-06T22:56:11.041+0000] {processor.py:914} INFO - Processing file /opt/airflow/dags/lab1_ML.py for tasks to queue
[2025-03-06T22:56:11.043+0000] {logging_mixin.py:190} INFO - [2025-03-06T22:56:11.043+0000] {dagbag.py:587} INFO - Filling up the DagBag from /opt/airflow/dags/lab1_ML.py
[2025-03-06T22:56:11.070+0000] {logging_mixin.py:190} INFO - [2025-03-06T22:56:11.070+0000] {base.py:84} INFO - Retrieving connection 'snowflake_conn'
[2025-03-06T22:56:11.072+0000] {logging_mixin.py:190} INFO - [2025-03-06T22:56:11.071+0000] {connection.py:413} INFO - Snowflake Connector for Python Version: 3.12.1, Python Version: 3.12.5, Platform: Linux-6.12.5-linuxkit-aarch64-with-glibc2.36
[2025-03-06T22:56:11.072+0000] {logging_mixin.py:190} INFO - [2025-03-06T22:56:11.072+0000] {connection.py:1196} INFO - Connecting to GLOBAL Snowflake domain
[2025-03-06T22:56:11.073+0000] {logging_mixin.py:190} INFO - [2025-03-06T22:56:11.073+0000] {connection.py:1277} INFO - This connection is in OCSP Fail Open Mode. TLS Certificates would be checked for validity and revocation status. Any other Certificate Revocation related exceptions or OCSP Responder failures would be disregarded in favor of connectivity.
[2025-03-06T22:56:11.396+0000] {logging_mixin.py:190} INFO - [2025-03-06T22:56:11.394+0000] {dagbag.py:386} ERROR - Failed to import: /opt/airflow/dags/lab1_ML.py
Traceback (most recent call last):
  File "/home/airflow/.local/lib/python3.12/site-packages/airflow/models/dagbag.py", line 382, in parse
    loader.exec_module(new_module)
  File "<frozen importlib._bootstrap_external>", line 995, in exec_module
  File "<frozen importlib._bootstrap>", line 488, in _call_with_frames_removed
  File "/opt/airflow/dags/lab1_ML.py", line 91, in <module>
    cur = return_snowflake_conn()
          ^^^^^^^^^^^^^^^^^^^^^^^
  File "/opt/airflow/dags/lab1_ML.py", line 13, in return_snowflake_conn
    conn = hook.get_conn()
           ^^^^^^^^^^^^^^^
  File "/home/airflow/.local/lib/python3.12/site-packages/airflow/providers/snowflake/hooks/snowflake.py", line 300, in get_conn
    conn = connector.connect(**conn_config)
           ^^^^^^^^^^^^^^^^^^^^^^^^^^^^^^^^
  File "/home/airflow/.local/lib/python3.12/site-packages/snowflake/connector/__init__.py", line 55, in Connect
    return SnowflakeConnection(**kwargs)
           ^^^^^^^^^^^^^^^^^^^^^^^^^^^^^
  File "/home/airflow/.local/lib/python3.12/site-packages/snowflake/connector/connection.py", line 456, in __init__
    self.connect(**kwargs)
  File "/home/airflow/.local/lib/python3.12/site-packages/snowflake/connector/connection.py", line 771, in connect
    self.__open_connection()
  File "/home/airflow/.local/lib/python3.12/site-packages/snowflake/connector/connection.py", line 1099, in __open_connection
    self.authenticate_with_retry(self.auth_class)
  File "/home/airflow/.local/lib/python3.12/site-packages/snowflake/connector/connection.py", line 1386, in authenticate_with_retry
    self._authenticate(auth_instance)
  File "/home/airflow/.local/lib/python3.12/site-packages/snowflake/connector/connection.py", line 1414, in _authenticate
    auth.authenticate(
  File "/home/airflow/.local/lib/python3.12/site-packages/snowflake/connector/auth/_auth.py", line 401, in authenticate
    Error.errorhandler_wrapper(
  File "/home/airflow/.local/lib/python3.12/site-packages/snowflake/connector/errors.py", line 284, in errorhandler_wrapper
    handed_over = Error.hand_to_other_handler(
                  ^^^^^^^^^^^^^^^^^^^^^^^^^^^^
  File "/home/airflow/.local/lib/python3.12/site-packages/snowflake/connector/errors.py", line 342, in hand_to_other_handler
    connection.errorhandler(connection, cursor, error_class, error_value)
  File "/home/airflow/.local/lib/python3.12/site-packages/snowflake/connector/errors.py", line 215, in default_errorhandler
    raise error_class(
snowflake.connector.errors.DatabaseError: 250001 (08001): None: Failed to connect to DB: wbb10936.snowflakecomputing.com:443. Your free trial has ended and all of your virtual warehouses have been suspended. Add billing information in the Snowflake web UI to continue using the full set of Snowflake features.
[2025-03-06T22:56:11.398+0000] {processor.py:927} WARNING - No viable dags retrieved from /opt/airflow/dags/lab1_ML.py
[2025-03-06T22:56:11.411+0000] {processor.py:208} INFO - Processing /opt/airflow/dags/lab1_ML.py took 0.386 seconds
[2025-03-06T22:56:41.897+0000] {processor.py:186} INFO - Started process (PID=485) to work on /opt/airflow/dags/lab1_ML.py
[2025-03-06T22:56:41.900+0000] {processor.py:914} INFO - Processing file /opt/airflow/dags/lab1_ML.py for tasks to queue
[2025-03-06T22:56:41.902+0000] {logging_mixin.py:190} INFO - [2025-03-06T22:56:41.901+0000] {dagbag.py:587} INFO - Filling up the DagBag from /opt/airflow/dags/lab1_ML.py
[2025-03-06T22:56:41.934+0000] {logging_mixin.py:190} INFO - [2025-03-06T22:56:41.933+0000] {base.py:84} INFO - Retrieving connection 'snowflake_conn'
[2025-03-06T22:56:41.935+0000] {logging_mixin.py:190} INFO - [2025-03-06T22:56:41.935+0000] {connection.py:413} INFO - Snowflake Connector for Python Version: 3.12.1, Python Version: 3.12.5, Platform: Linux-6.12.5-linuxkit-aarch64-with-glibc2.36
[2025-03-06T22:56:41.936+0000] {logging_mixin.py:190} INFO - [2025-03-06T22:56:41.936+0000] {connection.py:1196} INFO - Connecting to GLOBAL Snowflake domain
[2025-03-06T22:56:41.936+0000] {logging_mixin.py:190} INFO - [2025-03-06T22:56:41.936+0000] {connection.py:1277} INFO - This connection is in OCSP Fail Open Mode. TLS Certificates would be checked for validity and revocation status. Any other Certificate Revocation related exceptions or OCSP Responder failures would be disregarded in favor of connectivity.
[2025-03-06T22:56:42.223+0000] {logging_mixin.py:190} INFO - [2025-03-06T22:56:42.222+0000] {dagbag.py:386} ERROR - Failed to import: /opt/airflow/dags/lab1_ML.py
Traceback (most recent call last):
  File "/home/airflow/.local/lib/python3.12/site-packages/airflow/models/dagbag.py", line 382, in parse
    loader.exec_module(new_module)
  File "<frozen importlib._bootstrap_external>", line 995, in exec_module
  File "<frozen importlib._bootstrap>", line 488, in _call_with_frames_removed
  File "/opt/airflow/dags/lab1_ML.py", line 91, in <module>
    cur = return_snowflake_conn()
          ^^^^^^^^^^^^^^^^^^^^^^^
  File "/opt/airflow/dags/lab1_ML.py", line 13, in return_snowflake_conn
    conn = hook.get_conn()
           ^^^^^^^^^^^^^^^
  File "/home/airflow/.local/lib/python3.12/site-packages/airflow/providers/snowflake/hooks/snowflake.py", line 300, in get_conn
    conn = connector.connect(**conn_config)
           ^^^^^^^^^^^^^^^^^^^^^^^^^^^^^^^^
  File "/home/airflow/.local/lib/python3.12/site-packages/snowflake/connector/__init__.py", line 55, in Connect
    return SnowflakeConnection(**kwargs)
           ^^^^^^^^^^^^^^^^^^^^^^^^^^^^^
  File "/home/airflow/.local/lib/python3.12/site-packages/snowflake/connector/connection.py", line 456, in __init__
    self.connect(**kwargs)
  File "/home/airflow/.local/lib/python3.12/site-packages/snowflake/connector/connection.py", line 771, in connect
    self.__open_connection()
  File "/home/airflow/.local/lib/python3.12/site-packages/snowflake/connector/connection.py", line 1099, in __open_connection
    self.authenticate_with_retry(self.auth_class)
  File "/home/airflow/.local/lib/python3.12/site-packages/snowflake/connector/connection.py", line 1386, in authenticate_with_retry
    self._authenticate(auth_instance)
  File "/home/airflow/.local/lib/python3.12/site-packages/snowflake/connector/connection.py", line 1414, in _authenticate
    auth.authenticate(
  File "/home/airflow/.local/lib/python3.12/site-packages/snowflake/connector/auth/_auth.py", line 401, in authenticate
    Error.errorhandler_wrapper(
  File "/home/airflow/.local/lib/python3.12/site-packages/snowflake/connector/errors.py", line 284, in errorhandler_wrapper
    handed_over = Error.hand_to_other_handler(
                  ^^^^^^^^^^^^^^^^^^^^^^^^^^^^
  File "/home/airflow/.local/lib/python3.12/site-packages/snowflake/connector/errors.py", line 342, in hand_to_other_handler
    connection.errorhandler(connection, cursor, error_class, error_value)
  File "/home/airflow/.local/lib/python3.12/site-packages/snowflake/connector/errors.py", line 215, in default_errorhandler
    raise error_class(
snowflake.connector.errors.DatabaseError: 250001 (08001): None: Failed to connect to DB: wbb10936.snowflakecomputing.com:443. Your free trial has ended and all of your virtual warehouses have been suspended. Add billing information in the Snowflake web UI to continue using the full set of Snowflake features.
[2025-03-06T22:56:42.224+0000] {processor.py:927} WARNING - No viable dags retrieved from /opt/airflow/dags/lab1_ML.py
[2025-03-06T22:56:42.233+0000] {processor.py:208} INFO - Processing /opt/airflow/dags/lab1_ML.py took 0.362 seconds
[2025-03-06T22:57:12.650+0000] {processor.py:186} INFO - Started process (PID=506) to work on /opt/airflow/dags/lab1_ML.py
[2025-03-06T22:57:12.652+0000] {processor.py:914} INFO - Processing file /opt/airflow/dags/lab1_ML.py for tasks to queue
[2025-03-06T22:57:12.653+0000] {logging_mixin.py:190} INFO - [2025-03-06T22:57:12.653+0000] {dagbag.py:587} INFO - Filling up the DagBag from /opt/airflow/dags/lab1_ML.py
[2025-03-06T22:57:12.695+0000] {logging_mixin.py:190} INFO - [2025-03-06T22:57:12.695+0000] {base.py:84} INFO - Retrieving connection 'snowflake_conn'
[2025-03-06T22:57:12.696+0000] {logging_mixin.py:190} INFO - [2025-03-06T22:57:12.696+0000] {connection.py:413} INFO - Snowflake Connector for Python Version: 3.12.1, Python Version: 3.12.5, Platform: Linux-6.12.5-linuxkit-aarch64-with-glibc2.36
[2025-03-06T22:57:12.697+0000] {logging_mixin.py:190} INFO - [2025-03-06T22:57:12.697+0000] {connection.py:1196} INFO - Connecting to GLOBAL Snowflake domain
[2025-03-06T22:57:12.697+0000] {logging_mixin.py:190} INFO - [2025-03-06T22:57:12.697+0000] {connection.py:1277} INFO - This connection is in OCSP Fail Open Mode. TLS Certificates would be checked for validity and revocation status. Any other Certificate Revocation related exceptions or OCSP Responder failures would be disregarded in favor of connectivity.
[2025-03-06T22:57:13.021+0000] {logging_mixin.py:190} INFO - [2025-03-06T22:57:13.019+0000] {dagbag.py:386} ERROR - Failed to import: /opt/airflow/dags/lab1_ML.py
Traceback (most recent call last):
  File "/home/airflow/.local/lib/python3.12/site-packages/airflow/models/dagbag.py", line 382, in parse
    loader.exec_module(new_module)
  File "<frozen importlib._bootstrap_external>", line 995, in exec_module
  File "<frozen importlib._bootstrap>", line 488, in _call_with_frames_removed
  File "/opt/airflow/dags/lab1_ML.py", line 91, in <module>
    cur = return_snowflake_conn()
          ^^^^^^^^^^^^^^^^^^^^^^^
  File "/opt/airflow/dags/lab1_ML.py", line 13, in return_snowflake_conn
    conn = hook.get_conn()
           ^^^^^^^^^^^^^^^
  File "/home/airflow/.local/lib/python3.12/site-packages/airflow/providers/snowflake/hooks/snowflake.py", line 300, in get_conn
    conn = connector.connect(**conn_config)
           ^^^^^^^^^^^^^^^^^^^^^^^^^^^^^^^^
  File "/home/airflow/.local/lib/python3.12/site-packages/snowflake/connector/__init__.py", line 55, in Connect
    return SnowflakeConnection(**kwargs)
           ^^^^^^^^^^^^^^^^^^^^^^^^^^^^^
  File "/home/airflow/.local/lib/python3.12/site-packages/snowflake/connector/connection.py", line 456, in __init__
    self.connect(**kwargs)
  File "/home/airflow/.local/lib/python3.12/site-packages/snowflake/connector/connection.py", line 771, in connect
    self.__open_connection()
  File "/home/airflow/.local/lib/python3.12/site-packages/snowflake/connector/connection.py", line 1099, in __open_connection
    self.authenticate_with_retry(self.auth_class)
  File "/home/airflow/.local/lib/python3.12/site-packages/snowflake/connector/connection.py", line 1386, in authenticate_with_retry
    self._authenticate(auth_instance)
  File "/home/airflow/.local/lib/python3.12/site-packages/snowflake/connector/connection.py", line 1414, in _authenticate
    auth.authenticate(
  File "/home/airflow/.local/lib/python3.12/site-packages/snowflake/connector/auth/_auth.py", line 401, in authenticate
    Error.errorhandler_wrapper(
  File "/home/airflow/.local/lib/python3.12/site-packages/snowflake/connector/errors.py", line 284, in errorhandler_wrapper
    handed_over = Error.hand_to_other_handler(
                  ^^^^^^^^^^^^^^^^^^^^^^^^^^^^
  File "/home/airflow/.local/lib/python3.12/site-packages/snowflake/connector/errors.py", line 342, in hand_to_other_handler
    connection.errorhandler(connection, cursor, error_class, error_value)
  File "/home/airflow/.local/lib/python3.12/site-packages/snowflake/connector/errors.py", line 215, in default_errorhandler
    raise error_class(
snowflake.connector.errors.DatabaseError: 250001 (08001): None: Failed to connect to DB: wbb10936.snowflakecomputing.com:443. Your free trial has ended and all of your virtual warehouses have been suspended. Add billing information in the Snowflake web UI to continue using the full set of Snowflake features.
[2025-03-06T22:57:13.023+0000] {processor.py:927} WARNING - No viable dags retrieved from /opt/airflow/dags/lab1_ML.py
[2025-03-06T22:57:13.036+0000] {processor.py:208} INFO - Processing /opt/airflow/dags/lab1_ML.py took 0.395 seconds
[2025-03-06T22:57:43.361+0000] {processor.py:186} INFO - Started process (PID=527) to work on /opt/airflow/dags/lab1_ML.py
[2025-03-06T22:57:43.362+0000] {processor.py:914} INFO - Processing file /opt/airflow/dags/lab1_ML.py for tasks to queue
[2025-03-06T22:57:43.363+0000] {logging_mixin.py:190} INFO - [2025-03-06T22:57:43.362+0000] {dagbag.py:587} INFO - Filling up the DagBag from /opt/airflow/dags/lab1_ML.py
[2025-03-06T22:57:43.385+0000] {logging_mixin.py:190} INFO - [2025-03-06T22:57:43.385+0000] {base.py:84} INFO - Retrieving connection 'snowflake_conn'
[2025-03-06T22:57:43.386+0000] {logging_mixin.py:190} INFO - [2025-03-06T22:57:43.386+0000] {connection.py:413} INFO - Snowflake Connector for Python Version: 3.12.1, Python Version: 3.12.5, Platform: Linux-6.12.5-linuxkit-aarch64-with-glibc2.36
[2025-03-06T22:57:43.387+0000] {logging_mixin.py:190} INFO - [2025-03-06T22:57:43.387+0000] {connection.py:1196} INFO - Connecting to GLOBAL Snowflake domain
[2025-03-06T22:57:43.387+0000] {logging_mixin.py:190} INFO - [2025-03-06T22:57:43.387+0000] {connection.py:1277} INFO - This connection is in OCSP Fail Open Mode. TLS Certificates would be checked for validity and revocation status. Any other Certificate Revocation related exceptions or OCSP Responder failures would be disregarded in favor of connectivity.
[2025-03-06T22:57:43.682+0000] {logging_mixin.py:190} INFO - [2025-03-06T22:57:43.681+0000] {dagbag.py:386} ERROR - Failed to import: /opt/airflow/dags/lab1_ML.py
Traceback (most recent call last):
  File "/home/airflow/.local/lib/python3.12/site-packages/airflow/models/dagbag.py", line 382, in parse
    loader.exec_module(new_module)
  File "<frozen importlib._bootstrap_external>", line 995, in exec_module
  File "<frozen importlib._bootstrap>", line 488, in _call_with_frames_removed
  File "/opt/airflow/dags/lab1_ML.py", line 91, in <module>
    cur = return_snowflake_conn()
          ^^^^^^^^^^^^^^^^^^^^^^^
  File "/opt/airflow/dags/lab1_ML.py", line 13, in return_snowflake_conn
    conn = hook.get_conn()
           ^^^^^^^^^^^^^^^
  File "/home/airflow/.local/lib/python3.12/site-packages/airflow/providers/snowflake/hooks/snowflake.py", line 300, in get_conn
    conn = connector.connect(**conn_config)
           ^^^^^^^^^^^^^^^^^^^^^^^^^^^^^^^^
  File "/home/airflow/.local/lib/python3.12/site-packages/snowflake/connector/__init__.py", line 55, in Connect
    return SnowflakeConnection(**kwargs)
           ^^^^^^^^^^^^^^^^^^^^^^^^^^^^^
  File "/home/airflow/.local/lib/python3.12/site-packages/snowflake/connector/connection.py", line 456, in __init__
    self.connect(**kwargs)
  File "/home/airflow/.local/lib/python3.12/site-packages/snowflake/connector/connection.py", line 771, in connect
    self.__open_connection()
  File "/home/airflow/.local/lib/python3.12/site-packages/snowflake/connector/connection.py", line 1099, in __open_connection
    self.authenticate_with_retry(self.auth_class)
  File "/home/airflow/.local/lib/python3.12/site-packages/snowflake/connector/connection.py", line 1386, in authenticate_with_retry
    self._authenticate(auth_instance)
  File "/home/airflow/.local/lib/python3.12/site-packages/snowflake/connector/connection.py", line 1414, in _authenticate
    auth.authenticate(
  File "/home/airflow/.local/lib/python3.12/site-packages/snowflake/connector/auth/_auth.py", line 401, in authenticate
    Error.errorhandler_wrapper(
  File "/home/airflow/.local/lib/python3.12/site-packages/snowflake/connector/errors.py", line 284, in errorhandler_wrapper
    handed_over = Error.hand_to_other_handler(
                  ^^^^^^^^^^^^^^^^^^^^^^^^^^^^
  File "/home/airflow/.local/lib/python3.12/site-packages/snowflake/connector/errors.py", line 342, in hand_to_other_handler
    connection.errorhandler(connection, cursor, error_class, error_value)
  File "/home/airflow/.local/lib/python3.12/site-packages/snowflake/connector/errors.py", line 215, in default_errorhandler
    raise error_class(
snowflake.connector.errors.DatabaseError: 250001 (08001): None: Failed to connect to DB: wbb10936.snowflakecomputing.com:443. Your free trial has ended and all of your virtual warehouses have been suspended. Add billing information in the Snowflake web UI to continue using the full set of Snowflake features.
[2025-03-06T22:57:43.683+0000] {processor.py:927} WARNING - No viable dags retrieved from /opt/airflow/dags/lab1_ML.py
[2025-03-06T22:57:43.689+0000] {processor.py:208} INFO - Processing /opt/airflow/dags/lab1_ML.py took 0.338 seconds
[2025-03-06T22:58:14.078+0000] {processor.py:186} INFO - Started process (PID=548) to work on /opt/airflow/dags/lab1_ML.py
[2025-03-06T22:58:14.080+0000] {processor.py:914} INFO - Processing file /opt/airflow/dags/lab1_ML.py for tasks to queue
[2025-03-06T22:58:14.082+0000] {logging_mixin.py:190} INFO - [2025-03-06T22:58:14.081+0000] {dagbag.py:587} INFO - Filling up the DagBag from /opt/airflow/dags/lab1_ML.py
[2025-03-06T22:58:14.123+0000] {logging_mixin.py:190} INFO - [2025-03-06T22:58:14.123+0000] {base.py:84} INFO - Retrieving connection 'snowflake_conn'
[2025-03-06T22:58:14.124+0000] {logging_mixin.py:190} INFO - [2025-03-06T22:58:14.124+0000] {connection.py:413} INFO - Snowflake Connector for Python Version: 3.12.1, Python Version: 3.12.5, Platform: Linux-6.12.5-linuxkit-aarch64-with-glibc2.36
[2025-03-06T22:58:14.125+0000] {logging_mixin.py:190} INFO - [2025-03-06T22:58:14.125+0000] {connection.py:1196} INFO - Connecting to GLOBAL Snowflake domain
[2025-03-06T22:58:14.125+0000] {logging_mixin.py:190} INFO - [2025-03-06T22:58:14.125+0000] {connection.py:1277} INFO - This connection is in OCSP Fail Open Mode. TLS Certificates would be checked for validity and revocation status. Any other Certificate Revocation related exceptions or OCSP Responder failures would be disregarded in favor of connectivity.
[2025-03-06T22:58:14.427+0000] {logging_mixin.py:190} INFO - [2025-03-06T22:58:14.425+0000] {dagbag.py:386} ERROR - Failed to import: /opt/airflow/dags/lab1_ML.py
Traceback (most recent call last):
  File "/home/airflow/.local/lib/python3.12/site-packages/airflow/models/dagbag.py", line 382, in parse
    loader.exec_module(new_module)
  File "<frozen importlib._bootstrap_external>", line 995, in exec_module
  File "<frozen importlib._bootstrap>", line 488, in _call_with_frames_removed
  File "/opt/airflow/dags/lab1_ML.py", line 91, in <module>
    cur = return_snowflake_conn()
          ^^^^^^^^^^^^^^^^^^^^^^^
  File "/opt/airflow/dags/lab1_ML.py", line 13, in return_snowflake_conn
    conn = hook.get_conn()
           ^^^^^^^^^^^^^^^
  File "/home/airflow/.local/lib/python3.12/site-packages/airflow/providers/snowflake/hooks/snowflake.py", line 300, in get_conn
    conn = connector.connect(**conn_config)
           ^^^^^^^^^^^^^^^^^^^^^^^^^^^^^^^^
  File "/home/airflow/.local/lib/python3.12/site-packages/snowflake/connector/__init__.py", line 55, in Connect
    return SnowflakeConnection(**kwargs)
           ^^^^^^^^^^^^^^^^^^^^^^^^^^^^^
  File "/home/airflow/.local/lib/python3.12/site-packages/snowflake/connector/connection.py", line 456, in __init__
    self.connect(**kwargs)
  File "/home/airflow/.local/lib/python3.12/site-packages/snowflake/connector/connection.py", line 771, in connect
    self.__open_connection()
  File "/home/airflow/.local/lib/python3.12/site-packages/snowflake/connector/connection.py", line 1099, in __open_connection
    self.authenticate_with_retry(self.auth_class)
  File "/home/airflow/.local/lib/python3.12/site-packages/snowflake/connector/connection.py", line 1386, in authenticate_with_retry
    self._authenticate(auth_instance)
  File "/home/airflow/.local/lib/python3.12/site-packages/snowflake/connector/connection.py", line 1414, in _authenticate
    auth.authenticate(
  File "/home/airflow/.local/lib/python3.12/site-packages/snowflake/connector/auth/_auth.py", line 401, in authenticate
    Error.errorhandler_wrapper(
  File "/home/airflow/.local/lib/python3.12/site-packages/snowflake/connector/errors.py", line 284, in errorhandler_wrapper
    handed_over = Error.hand_to_other_handler(
                  ^^^^^^^^^^^^^^^^^^^^^^^^^^^^
  File "/home/airflow/.local/lib/python3.12/site-packages/snowflake/connector/errors.py", line 342, in hand_to_other_handler
    connection.errorhandler(connection, cursor, error_class, error_value)
  File "/home/airflow/.local/lib/python3.12/site-packages/snowflake/connector/errors.py", line 215, in default_errorhandler
    raise error_class(
snowflake.connector.errors.DatabaseError: 250001 (08001): None: Failed to connect to DB: wbb10936.snowflakecomputing.com:443. Your free trial has ended and all of your virtual warehouses have been suspended. Add billing information in the Snowflake web UI to continue using the full set of Snowflake features.
[2025-03-06T22:58:14.429+0000] {processor.py:927} WARNING - No viable dags retrieved from /opt/airflow/dags/lab1_ML.py
[2025-03-06T22:58:14.439+0000] {processor.py:208} INFO - Processing /opt/airflow/dags/lab1_ML.py took 0.372 seconds
[2025-03-06T22:58:44.827+0000] {processor.py:186} INFO - Started process (PID=569) to work on /opt/airflow/dags/lab1_ML.py
[2025-03-06T22:58:44.829+0000] {processor.py:914} INFO - Processing file /opt/airflow/dags/lab1_ML.py for tasks to queue
[2025-03-06T22:58:44.830+0000] {logging_mixin.py:190} INFO - [2025-03-06T22:58:44.829+0000] {dagbag.py:587} INFO - Filling up the DagBag from /opt/airflow/dags/lab1_ML.py
[2025-03-06T22:58:44.861+0000] {logging_mixin.py:190} INFO - [2025-03-06T22:58:44.861+0000] {base.py:84} INFO - Retrieving connection 'snowflake_conn'
[2025-03-06T22:58:44.862+0000] {logging_mixin.py:190} INFO - [2025-03-06T22:58:44.862+0000] {connection.py:413} INFO - Snowflake Connector for Python Version: 3.12.1, Python Version: 3.12.5, Platform: Linux-6.12.5-linuxkit-aarch64-with-glibc2.36
[2025-03-06T22:58:44.863+0000] {logging_mixin.py:190} INFO - [2025-03-06T22:58:44.863+0000] {connection.py:1196} INFO - Connecting to GLOBAL Snowflake domain
[2025-03-06T22:58:44.864+0000] {logging_mixin.py:190} INFO - [2025-03-06T22:58:44.863+0000] {connection.py:1277} INFO - This connection is in OCSP Fail Open Mode. TLS Certificates would be checked for validity and revocation status. Any other Certificate Revocation related exceptions or OCSP Responder failures would be disregarded in favor of connectivity.
[2025-03-06T22:58:45.167+0000] {logging_mixin.py:190} INFO - [2025-03-06T22:58:45.161+0000] {dagbag.py:386} ERROR - Failed to import: /opt/airflow/dags/lab1_ML.py
Traceback (most recent call last):
  File "/home/airflow/.local/lib/python3.12/site-packages/airflow/models/dagbag.py", line 382, in parse
    loader.exec_module(new_module)
  File "<frozen importlib._bootstrap_external>", line 995, in exec_module
  File "<frozen importlib._bootstrap>", line 488, in _call_with_frames_removed
  File "/opt/airflow/dags/lab1_ML.py", line 91, in <module>
    cur = return_snowflake_conn()
          ^^^^^^^^^^^^^^^^^^^^^^^
  File "/opt/airflow/dags/lab1_ML.py", line 13, in return_snowflake_conn
    conn = hook.get_conn()
           ^^^^^^^^^^^^^^^
  File "/home/airflow/.local/lib/python3.12/site-packages/airflow/providers/snowflake/hooks/snowflake.py", line 300, in get_conn
    conn = connector.connect(**conn_config)
           ^^^^^^^^^^^^^^^^^^^^^^^^^^^^^^^^
  File "/home/airflow/.local/lib/python3.12/site-packages/snowflake/connector/__init__.py", line 55, in Connect
    return SnowflakeConnection(**kwargs)
           ^^^^^^^^^^^^^^^^^^^^^^^^^^^^^
  File "/home/airflow/.local/lib/python3.12/site-packages/snowflake/connector/connection.py", line 456, in __init__
    self.connect(**kwargs)
  File "/home/airflow/.local/lib/python3.12/site-packages/snowflake/connector/connection.py", line 771, in connect
    self.__open_connection()
  File "/home/airflow/.local/lib/python3.12/site-packages/snowflake/connector/connection.py", line 1099, in __open_connection
    self.authenticate_with_retry(self.auth_class)
  File "/home/airflow/.local/lib/python3.12/site-packages/snowflake/connector/connection.py", line 1386, in authenticate_with_retry
    self._authenticate(auth_instance)
  File "/home/airflow/.local/lib/python3.12/site-packages/snowflake/connector/connection.py", line 1414, in _authenticate
    auth.authenticate(
  File "/home/airflow/.local/lib/python3.12/site-packages/snowflake/connector/auth/_auth.py", line 401, in authenticate
    Error.errorhandler_wrapper(
  File "/home/airflow/.local/lib/python3.12/site-packages/snowflake/connector/errors.py", line 284, in errorhandler_wrapper
    handed_over = Error.hand_to_other_handler(
                  ^^^^^^^^^^^^^^^^^^^^^^^^^^^^
  File "/home/airflow/.local/lib/python3.12/site-packages/snowflake/connector/errors.py", line 342, in hand_to_other_handler
    connection.errorhandler(connection, cursor, error_class, error_value)
  File "/home/airflow/.local/lib/python3.12/site-packages/snowflake/connector/errors.py", line 215, in default_errorhandler
    raise error_class(
snowflake.connector.errors.DatabaseError: 250001 (08001): None: Failed to connect to DB: wbb10936.snowflakecomputing.com:443. Your free trial has ended and all of your virtual warehouses have been suspended. Add billing information in the Snowflake web UI to continue using the full set of Snowflake features.
[2025-03-06T22:58:45.168+0000] {processor.py:927} WARNING - No viable dags retrieved from /opt/airflow/dags/lab1_ML.py
[2025-03-06T22:58:45.180+0000] {processor.py:208} INFO - Processing /opt/airflow/dags/lab1_ML.py took 0.362 seconds
[2025-03-06T22:59:15.550+0000] {processor.py:186} INFO - Started process (PID=590) to work on /opt/airflow/dags/lab1_ML.py
[2025-03-06T22:59:15.552+0000] {processor.py:914} INFO - Processing file /opt/airflow/dags/lab1_ML.py for tasks to queue
[2025-03-06T22:59:15.553+0000] {logging_mixin.py:190} INFO - [2025-03-06T22:59:15.553+0000] {dagbag.py:587} INFO - Filling up the DagBag from /opt/airflow/dags/lab1_ML.py
[2025-03-06T22:59:15.582+0000] {logging_mixin.py:190} INFO - [2025-03-06T22:59:15.582+0000] {base.py:84} INFO - Retrieving connection 'snowflake_conn'
[2025-03-06T22:59:15.584+0000] {logging_mixin.py:190} INFO - [2025-03-06T22:59:15.584+0000] {connection.py:413} INFO - Snowflake Connector for Python Version: 3.12.1, Python Version: 3.12.5, Platform: Linux-6.12.5-linuxkit-aarch64-with-glibc2.36
[2025-03-06T22:59:15.586+0000] {logging_mixin.py:190} INFO - [2025-03-06T22:59:15.586+0000] {connection.py:1196} INFO - Connecting to GLOBAL Snowflake domain
[2025-03-06T22:59:15.587+0000] {logging_mixin.py:190} INFO - [2025-03-06T22:59:15.587+0000] {connection.py:1277} INFO - This connection is in OCSP Fail Open Mode. TLS Certificates would be checked for validity and revocation status. Any other Certificate Revocation related exceptions or OCSP Responder failures would be disregarded in favor of connectivity.
