[2025-03-06T22:51:01.772+0000] {processor.py:186} INFO - Started process (PID=202) to work on /opt/airflow/dags/lab1_ETL.py
[2025-03-06T22:51:01.774+0000] {processor.py:914} INFO - Processing file /opt/airflow/dags/lab1_ETL.py for tasks to queue
[2025-03-06T22:51:01.778+0000] {logging_mixin.py:190} INFO - [2025-03-06T22:51:01.777+0000] {dagbag.py:587} INFO - Filling up the DagBag from /opt/airflow/dags/lab1_ETL.py
[2025-03-06T22:51:01.964+0000] {logging_mixin.py:190} INFO - [2025-03-06T22:51:01.963+0000] {base.py:84} INFO - Retrieving connection 'snowflake_conn'
[2025-03-06T22:51:01.965+0000] {logging_mixin.py:190} INFO - [2025-03-06T22:51:01.965+0000] {connection.py:413} INFO - Snowflake Connector for Python Version: 3.12.1, Python Version: 3.12.5, Platform: Linux-6.12.5-linuxkit-aarch64-with-glibc2.36
[2025-03-06T22:51:01.966+0000] {logging_mixin.py:190} INFO - [2025-03-06T22:51:01.966+0000] {connection.py:1196} INFO - Connecting to GLOBAL Snowflake domain
[2025-03-06T22:51:01.966+0000] {logging_mixin.py:190} INFO - [2025-03-06T22:51:01.966+0000] {connection.py:1277} INFO - This connection is in OCSP Fail Open Mode. TLS Certificates would be checked for validity and revocation status. Any other Certificate Revocation related exceptions or OCSP Responder failures would be disregarded in favor of connectivity.
[2025-03-06T22:51:02.400+0000] {logging_mixin.py:190} INFO - [2025-03-06T22:51:02.399+0000] {dagbag.py:386} ERROR - Failed to import: /opt/airflow/dags/lab1_ETL.py
Traceback (most recent call last):
  File "/home/airflow/.local/lib/python3.12/site-packages/airflow/models/dagbag.py", line 382, in parse
    loader.exec_module(new_module)
  File "<frozen importlib._bootstrap_external>", line 995, in exec_module
  File "<frozen importlib._bootstrap>", line 488, in _call_with_frames_removed
  File "/opt/airflow/dags/lab1_ETL.py", line 86, in <module>
    cur = return_snowflake_conn()
          ^^^^^^^^^^^^^^^^^^^^^^^
  File "/opt/airflow/dags/lab1_ETL.py", line 16, in return_snowflake_conn
    conn = hook.get_conn()
           ^^^^^^^^^^^^^^^
  File "/home/airflow/.local/lib/python3.12/site-packages/airflow/providers/snowflake/hooks/snowflake.py", line 300, in get_conn
    conn = connector.connect(**conn_config)
           ^^^^^^^^^^^^^^^^^^^^^^^^^^^^^^^^
  File "/home/airflow/.local/lib/python3.12/site-packages/snowflake/connector/__init__.py", line 55, in Connect
    return SnowflakeConnection(**kwargs)
           ^^^^^^^^^^^^^^^^^^^^^^^^^^^^^
  File "/home/airflow/.local/lib/python3.12/site-packages/snowflake/connector/connection.py", line 456, in __init__
    self.connect(**kwargs)
  File "/home/airflow/.local/lib/python3.12/site-packages/snowflake/connector/connection.py", line 771, in connect
    self.__open_connection()
  File "/home/airflow/.local/lib/python3.12/site-packages/snowflake/connector/connection.py", line 1099, in __open_connection
    self.authenticate_with_retry(self.auth_class)
  File "/home/airflow/.local/lib/python3.12/site-packages/snowflake/connector/connection.py", line 1386, in authenticate_with_retry
    self._authenticate(auth_instance)
  File "/home/airflow/.local/lib/python3.12/site-packages/snowflake/connector/connection.py", line 1414, in _authenticate
    auth.authenticate(
  File "/home/airflow/.local/lib/python3.12/site-packages/snowflake/connector/auth/_auth.py", line 401, in authenticate
    Error.errorhandler_wrapper(
  File "/home/airflow/.local/lib/python3.12/site-packages/snowflake/connector/errors.py", line 284, in errorhandler_wrapper
    handed_over = Error.hand_to_other_handler(
                  ^^^^^^^^^^^^^^^^^^^^^^^^^^^^
  File "/home/airflow/.local/lib/python3.12/site-packages/snowflake/connector/errors.py", line 342, in hand_to_other_handler
    connection.errorhandler(connection, cursor, error_class, error_value)
  File "/home/airflow/.local/lib/python3.12/site-packages/snowflake/connector/errors.py", line 215, in default_errorhandler
    raise error_class(
snowflake.connector.errors.DatabaseError: 250001 (08001): None: Failed to connect to DB: wbb10936.snowflakecomputing.com:443. Your free trial has ended and all of your virtual warehouses have been suspended. Add billing information in the Snowflake web UI to continue using the full set of Snowflake features.
[2025-03-06T22:51:02.401+0000] {processor.py:927} WARNING - No viable dags retrieved from /opt/airflow/dags/lab1_ETL.py
[2025-03-06T22:51:02.419+0000] {processor.py:208} INFO - Processing /opt/airflow/dags/lab1_ETL.py took 0.655 seconds
[2025-03-06T22:51:32.928+0000] {processor.py:186} INFO - Started process (PID=261) to work on /opt/airflow/dags/lab1_ETL.py
[2025-03-06T22:51:32.929+0000] {processor.py:914} INFO - Processing file /opt/airflow/dags/lab1_ETL.py for tasks to queue
[2025-03-06T22:51:32.933+0000] {logging_mixin.py:190} INFO - [2025-03-06T22:51:32.932+0000] {dagbag.py:587} INFO - Filling up the DagBag from /opt/airflow/dags/lab1_ETL.py
[2025-03-06T22:51:33.035+0000] {logging_mixin.py:190} INFO - [2025-03-06T22:51:33.035+0000] {base.py:84} INFO - Retrieving connection 'snowflake_conn'
[2025-03-06T22:51:33.035+0000] {logging_mixin.py:190} INFO - [2025-03-06T22:51:33.035+0000] {connection.py:413} INFO - Snowflake Connector for Python Version: 3.12.1, Python Version: 3.12.5, Platform: Linux-6.12.5-linuxkit-aarch64-with-glibc2.36
[2025-03-06T22:51:33.036+0000] {logging_mixin.py:190} INFO - [2025-03-06T22:51:33.036+0000] {connection.py:1196} INFO - Connecting to GLOBAL Snowflake domain
[2025-03-06T22:51:33.036+0000] {logging_mixin.py:190} INFO - [2025-03-06T22:51:33.036+0000] {connection.py:1277} INFO - This connection is in OCSP Fail Open Mode. TLS Certificates would be checked for validity and revocation status. Any other Certificate Revocation related exceptions or OCSP Responder failures would be disregarded in favor of connectivity.
[2025-03-06T22:51:33.379+0000] {logging_mixin.py:190} INFO - [2025-03-06T22:51:33.376+0000] {dagbag.py:386} ERROR - Failed to import: /opt/airflow/dags/lab1_ETL.py
Traceback (most recent call last):
  File "/home/airflow/.local/lib/python3.12/site-packages/airflow/models/dagbag.py", line 382, in parse
    loader.exec_module(new_module)
  File "<frozen importlib._bootstrap_external>", line 995, in exec_module
  File "<frozen importlib._bootstrap>", line 488, in _call_with_frames_removed
  File "/opt/airflow/dags/lab1_ETL.py", line 86, in <module>
    cur = return_snowflake_conn()
          ^^^^^^^^^^^^^^^^^^^^^^^
  File "/opt/airflow/dags/lab1_ETL.py", line 16, in return_snowflake_conn
    conn = hook.get_conn()
           ^^^^^^^^^^^^^^^
  File "/home/airflow/.local/lib/python3.12/site-packages/airflow/providers/snowflake/hooks/snowflake.py", line 300, in get_conn
    conn = connector.connect(**conn_config)
           ^^^^^^^^^^^^^^^^^^^^^^^^^^^^^^^^
  File "/home/airflow/.local/lib/python3.12/site-packages/snowflake/connector/__init__.py", line 55, in Connect
    return SnowflakeConnection(**kwargs)
           ^^^^^^^^^^^^^^^^^^^^^^^^^^^^^
  File "/home/airflow/.local/lib/python3.12/site-packages/snowflake/connector/connection.py", line 456, in __init__
    self.connect(**kwargs)
  File "/home/airflow/.local/lib/python3.12/site-packages/snowflake/connector/connection.py", line 771, in connect
    self.__open_connection()
  File "/home/airflow/.local/lib/python3.12/site-packages/snowflake/connector/connection.py", line 1099, in __open_connection
    self.authenticate_with_retry(self.auth_class)
  File "/home/airflow/.local/lib/python3.12/site-packages/snowflake/connector/connection.py", line 1386, in authenticate_with_retry
    self._authenticate(auth_instance)
  File "/home/airflow/.local/lib/python3.12/site-packages/snowflake/connector/connection.py", line 1414, in _authenticate
    auth.authenticate(
  File "/home/airflow/.local/lib/python3.12/site-packages/snowflake/connector/auth/_auth.py", line 401, in authenticate
    Error.errorhandler_wrapper(
  File "/home/airflow/.local/lib/python3.12/site-packages/snowflake/connector/errors.py", line 284, in errorhandler_wrapper
    handed_over = Error.hand_to_other_handler(
                  ^^^^^^^^^^^^^^^^^^^^^^^^^^^^
  File "/home/airflow/.local/lib/python3.12/site-packages/snowflake/connector/errors.py", line 342, in hand_to_other_handler
    connection.errorhandler(connection, cursor, error_class, error_value)
  File "/home/airflow/.local/lib/python3.12/site-packages/snowflake/connector/errors.py", line 215, in default_errorhandler
    raise error_class(
snowflake.connector.errors.DatabaseError: 250001 (08001): None: Failed to connect to DB: wbb10936.snowflakecomputing.com:443. Your free trial has ended and all of your virtual warehouses have been suspended. Add billing information in the Snowflake web UI to continue using the full set of Snowflake features.
[2025-03-06T22:51:33.381+0000] {processor.py:927} WARNING - No viable dags retrieved from /opt/airflow/dags/lab1_ETL.py
[2025-03-06T22:51:33.393+0000] {processor.py:208} INFO - Processing /opt/airflow/dags/lab1_ETL.py took 0.470 seconds
[2025-03-06T22:52:03.885+0000] {processor.py:186} INFO - Started process (PID=293) to work on /opt/airflow/dags/lab1_ETL.py
[2025-03-06T22:52:03.886+0000] {processor.py:914} INFO - Processing file /opt/airflow/dags/lab1_ETL.py for tasks to queue
[2025-03-06T22:52:03.888+0000] {logging_mixin.py:190} INFO - [2025-03-06T22:52:03.888+0000] {dagbag.py:587} INFO - Filling up the DagBag from /opt/airflow/dags/lab1_ETL.py
[2025-03-06T22:52:03.987+0000] {logging_mixin.py:190} INFO - [2025-03-06T22:52:03.987+0000] {base.py:84} INFO - Retrieving connection 'snowflake_conn'
[2025-03-06T22:52:03.988+0000] {logging_mixin.py:190} INFO - [2025-03-06T22:52:03.988+0000] {connection.py:413} INFO - Snowflake Connector for Python Version: 3.12.1, Python Version: 3.12.5, Platform: Linux-6.12.5-linuxkit-aarch64-with-glibc2.36
[2025-03-06T22:52:03.988+0000] {logging_mixin.py:190} INFO - [2025-03-06T22:52:03.988+0000] {connection.py:1196} INFO - Connecting to GLOBAL Snowflake domain
[2025-03-06T22:52:03.988+0000] {logging_mixin.py:190} INFO - [2025-03-06T22:52:03.988+0000] {connection.py:1277} INFO - This connection is in OCSP Fail Open Mode. TLS Certificates would be checked for validity and revocation status. Any other Certificate Revocation related exceptions or OCSP Responder failures would be disregarded in favor of connectivity.
[2025-03-06T22:52:04.249+0000] {logging_mixin.py:190} INFO - [2025-03-06T22:52:04.248+0000] {dagbag.py:386} ERROR - Failed to import: /opt/airflow/dags/lab1_ETL.py
Traceback (most recent call last):
  File "/home/airflow/.local/lib/python3.12/site-packages/airflow/models/dagbag.py", line 382, in parse
    loader.exec_module(new_module)
  File "<frozen importlib._bootstrap_external>", line 995, in exec_module
  File "<frozen importlib._bootstrap>", line 488, in _call_with_frames_removed
  File "/opt/airflow/dags/lab1_ETL.py", line 86, in <module>
    cur = return_snowflake_conn()
          ^^^^^^^^^^^^^^^^^^^^^^^
  File "/opt/airflow/dags/lab1_ETL.py", line 16, in return_snowflake_conn
    conn = hook.get_conn()
           ^^^^^^^^^^^^^^^
  File "/home/airflow/.local/lib/python3.12/site-packages/airflow/providers/snowflake/hooks/snowflake.py", line 300, in get_conn
    conn = connector.connect(**conn_config)
           ^^^^^^^^^^^^^^^^^^^^^^^^^^^^^^^^
  File "/home/airflow/.local/lib/python3.12/site-packages/snowflake/connector/__init__.py", line 55, in Connect
    return SnowflakeConnection(**kwargs)
           ^^^^^^^^^^^^^^^^^^^^^^^^^^^^^
  File "/home/airflow/.local/lib/python3.12/site-packages/snowflake/connector/connection.py", line 456, in __init__
    self.connect(**kwargs)
  File "/home/airflow/.local/lib/python3.12/site-packages/snowflake/connector/connection.py", line 771, in connect
    self.__open_connection()
  File "/home/airflow/.local/lib/python3.12/site-packages/snowflake/connector/connection.py", line 1099, in __open_connection
    self.authenticate_with_retry(self.auth_class)
  File "/home/airflow/.local/lib/python3.12/site-packages/snowflake/connector/connection.py", line 1386, in authenticate_with_retry
    self._authenticate(auth_instance)
  File "/home/airflow/.local/lib/python3.12/site-packages/snowflake/connector/connection.py", line 1414, in _authenticate
    auth.authenticate(
  File "/home/airflow/.local/lib/python3.12/site-packages/snowflake/connector/auth/_auth.py", line 401, in authenticate
    Error.errorhandler_wrapper(
  File "/home/airflow/.local/lib/python3.12/site-packages/snowflake/connector/errors.py", line 284, in errorhandler_wrapper
    handed_over = Error.hand_to_other_handler(
                  ^^^^^^^^^^^^^^^^^^^^^^^^^^^^
  File "/home/airflow/.local/lib/python3.12/site-packages/snowflake/connector/errors.py", line 342, in hand_to_other_handler
    connection.errorhandler(connection, cursor, error_class, error_value)
  File "/home/airflow/.local/lib/python3.12/site-packages/snowflake/connector/errors.py", line 215, in default_errorhandler
    raise error_class(
snowflake.connector.errors.DatabaseError: 250001 (08001): None: Failed to connect to DB: wbb10936.snowflakecomputing.com:443. Your free trial has ended and all of your virtual warehouses have been suspended. Add billing information in the Snowflake web UI to continue using the full set of Snowflake features.
[2025-03-06T22:52:04.250+0000] {processor.py:927} WARNING - No viable dags retrieved from /opt/airflow/dags/lab1_ETL.py
[2025-03-06T22:52:04.255+0000] {processor.py:208} INFO - Processing /opt/airflow/dags/lab1_ETL.py took 0.378 seconds
[2025-03-06T22:52:34.724+0000] {processor.py:186} INFO - Started process (PID=314) to work on /opt/airflow/dags/lab1_ETL.py
[2025-03-06T22:52:34.727+0000] {processor.py:914} INFO - Processing file /opt/airflow/dags/lab1_ETL.py for tasks to queue
[2025-03-06T22:52:34.728+0000] {logging_mixin.py:190} INFO - [2025-03-06T22:52:34.728+0000] {dagbag.py:587} INFO - Filling up the DagBag from /opt/airflow/dags/lab1_ETL.py
[2025-03-06T22:52:34.821+0000] {logging_mixin.py:190} INFO - [2025-03-06T22:52:34.821+0000] {base.py:84} INFO - Retrieving connection 'snowflake_conn'
[2025-03-06T22:52:34.821+0000] {logging_mixin.py:190} INFO - [2025-03-06T22:52:34.821+0000] {connection.py:413} INFO - Snowflake Connector for Python Version: 3.12.1, Python Version: 3.12.5, Platform: Linux-6.12.5-linuxkit-aarch64-with-glibc2.36
[2025-03-06T22:52:34.822+0000] {logging_mixin.py:190} INFO - [2025-03-06T22:52:34.822+0000] {connection.py:1196} INFO - Connecting to GLOBAL Snowflake domain
[2025-03-06T22:52:34.822+0000] {logging_mixin.py:190} INFO - [2025-03-06T22:52:34.822+0000] {connection.py:1277} INFO - This connection is in OCSP Fail Open Mode. TLS Certificates would be checked for validity and revocation status. Any other Certificate Revocation related exceptions or OCSP Responder failures would be disregarded in favor of connectivity.
[2025-03-06T22:52:35.078+0000] {logging_mixin.py:190} INFO - [2025-03-06T22:52:35.077+0000] {dagbag.py:386} ERROR - Failed to import: /opt/airflow/dags/lab1_ETL.py
Traceback (most recent call last):
  File "/home/airflow/.local/lib/python3.12/site-packages/airflow/models/dagbag.py", line 382, in parse
    loader.exec_module(new_module)
  File "<frozen importlib._bootstrap_external>", line 995, in exec_module
  File "<frozen importlib._bootstrap>", line 488, in _call_with_frames_removed
  File "/opt/airflow/dags/lab1_ETL.py", line 86, in <module>
    cur = return_snowflake_conn()
          ^^^^^^^^^^^^^^^^^^^^^^^
  File "/opt/airflow/dags/lab1_ETL.py", line 16, in return_snowflake_conn
    conn = hook.get_conn()
           ^^^^^^^^^^^^^^^
  File "/home/airflow/.local/lib/python3.12/site-packages/airflow/providers/snowflake/hooks/snowflake.py", line 300, in get_conn
    conn = connector.connect(**conn_config)
           ^^^^^^^^^^^^^^^^^^^^^^^^^^^^^^^^
  File "/home/airflow/.local/lib/python3.12/site-packages/snowflake/connector/__init__.py", line 55, in Connect
    return SnowflakeConnection(**kwargs)
           ^^^^^^^^^^^^^^^^^^^^^^^^^^^^^
  File "/home/airflow/.local/lib/python3.12/site-packages/snowflake/connector/connection.py", line 456, in __init__
    self.connect(**kwargs)
  File "/home/airflow/.local/lib/python3.12/site-packages/snowflake/connector/connection.py", line 771, in connect
    self.__open_connection()
  File "/home/airflow/.local/lib/python3.12/site-packages/snowflake/connector/connection.py", line 1099, in __open_connection
    self.authenticate_with_retry(self.auth_class)
  File "/home/airflow/.local/lib/python3.12/site-packages/snowflake/connector/connection.py", line 1386, in authenticate_with_retry
    self._authenticate(auth_instance)
  File "/home/airflow/.local/lib/python3.12/site-packages/snowflake/connector/connection.py", line 1414, in _authenticate
    auth.authenticate(
  File "/home/airflow/.local/lib/python3.12/site-packages/snowflake/connector/auth/_auth.py", line 401, in authenticate
    Error.errorhandler_wrapper(
  File "/home/airflow/.local/lib/python3.12/site-packages/snowflake/connector/errors.py", line 284, in errorhandler_wrapper
    handed_over = Error.hand_to_other_handler(
                  ^^^^^^^^^^^^^^^^^^^^^^^^^^^^
  File "/home/airflow/.local/lib/python3.12/site-packages/snowflake/connector/errors.py", line 342, in hand_to_other_handler
    connection.errorhandler(connection, cursor, error_class, error_value)
  File "/home/airflow/.local/lib/python3.12/site-packages/snowflake/connector/errors.py", line 215, in default_errorhandler
    raise error_class(
snowflake.connector.errors.DatabaseError: 250001 (08001): None: Failed to connect to DB: wbb10936.snowflakecomputing.com:443. Your free trial has ended and all of your virtual warehouses have been suspended. Add billing information in the Snowflake web UI to continue using the full set of Snowflake features.
[2025-03-06T22:52:35.079+0000] {processor.py:927} WARNING - No viable dags retrieved from /opt/airflow/dags/lab1_ETL.py
[2025-03-06T22:52:35.083+0000] {processor.py:208} INFO - Processing /opt/airflow/dags/lab1_ETL.py took 0.370 seconds
[2025-03-06T22:53:05.525+0000] {processor.py:186} INFO - Started process (PID=335) to work on /opt/airflow/dags/lab1_ETL.py
[2025-03-06T22:53:05.526+0000] {processor.py:914} INFO - Processing file /opt/airflow/dags/lab1_ETL.py for tasks to queue
[2025-03-06T22:53:05.527+0000] {logging_mixin.py:190} INFO - [2025-03-06T22:53:05.527+0000] {dagbag.py:587} INFO - Filling up the DagBag from /opt/airflow/dags/lab1_ETL.py
[2025-03-06T22:53:05.622+0000] {logging_mixin.py:190} INFO - [2025-03-06T22:53:05.621+0000] {base.py:84} INFO - Retrieving connection 'snowflake_conn'
[2025-03-06T22:53:05.622+0000] {logging_mixin.py:190} INFO - [2025-03-06T22:53:05.622+0000] {connection.py:413} INFO - Snowflake Connector for Python Version: 3.12.1, Python Version: 3.12.5, Platform: Linux-6.12.5-linuxkit-aarch64-with-glibc2.36
[2025-03-06T22:53:05.623+0000] {logging_mixin.py:190} INFO - [2025-03-06T22:53:05.623+0000] {connection.py:1196} INFO - Connecting to GLOBAL Snowflake domain
[2025-03-06T22:53:05.623+0000] {logging_mixin.py:190} INFO - [2025-03-06T22:53:05.623+0000] {connection.py:1277} INFO - This connection is in OCSP Fail Open Mode. TLS Certificates would be checked for validity and revocation status. Any other Certificate Revocation related exceptions or OCSP Responder failures would be disregarded in favor of connectivity.
[2025-03-06T22:53:05.866+0000] {logging_mixin.py:190} INFO - [2025-03-06T22:53:05.865+0000] {dagbag.py:386} ERROR - Failed to import: /opt/airflow/dags/lab1_ETL.py
Traceback (most recent call last):
  File "/home/airflow/.local/lib/python3.12/site-packages/airflow/models/dagbag.py", line 382, in parse
    loader.exec_module(new_module)
  File "<frozen importlib._bootstrap_external>", line 995, in exec_module
  File "<frozen importlib._bootstrap>", line 488, in _call_with_frames_removed
  File "/opt/airflow/dags/lab1_ETL.py", line 86, in <module>
    cur = return_snowflake_conn()
          ^^^^^^^^^^^^^^^^^^^^^^^
  File "/opt/airflow/dags/lab1_ETL.py", line 16, in return_snowflake_conn
    conn = hook.get_conn()
           ^^^^^^^^^^^^^^^
  File "/home/airflow/.local/lib/python3.12/site-packages/airflow/providers/snowflake/hooks/snowflake.py", line 300, in get_conn
    conn = connector.connect(**conn_config)
           ^^^^^^^^^^^^^^^^^^^^^^^^^^^^^^^^
  File "/home/airflow/.local/lib/python3.12/site-packages/snowflake/connector/__init__.py", line 55, in Connect
    return SnowflakeConnection(**kwargs)
           ^^^^^^^^^^^^^^^^^^^^^^^^^^^^^
  File "/home/airflow/.local/lib/python3.12/site-packages/snowflake/connector/connection.py", line 456, in __init__
    self.connect(**kwargs)
  File "/home/airflow/.local/lib/python3.12/site-packages/snowflake/connector/connection.py", line 771, in connect
    self.__open_connection()
  File "/home/airflow/.local/lib/python3.12/site-packages/snowflake/connector/connection.py", line 1099, in __open_connection
    self.authenticate_with_retry(self.auth_class)
  File "/home/airflow/.local/lib/python3.12/site-packages/snowflake/connector/connection.py", line 1386, in authenticate_with_retry
    self._authenticate(auth_instance)
  File "/home/airflow/.local/lib/python3.12/site-packages/snowflake/connector/connection.py", line 1414, in _authenticate
    auth.authenticate(
  File "/home/airflow/.local/lib/python3.12/site-packages/snowflake/connector/auth/_auth.py", line 401, in authenticate
    Error.errorhandler_wrapper(
  File "/home/airflow/.local/lib/python3.12/site-packages/snowflake/connector/errors.py", line 284, in errorhandler_wrapper
    handed_over = Error.hand_to_other_handler(
                  ^^^^^^^^^^^^^^^^^^^^^^^^^^^^
  File "/home/airflow/.local/lib/python3.12/site-packages/snowflake/connector/errors.py", line 342, in hand_to_other_handler
    connection.errorhandler(connection, cursor, error_class, error_value)
  File "/home/airflow/.local/lib/python3.12/site-packages/snowflake/connector/errors.py", line 215, in default_errorhandler
    raise error_class(
snowflake.connector.errors.DatabaseError: 250001 (08001): None: Failed to connect to DB: wbb10936.snowflakecomputing.com:443. Your free trial has ended and all of your virtual warehouses have been suspended. Add billing information in the Snowflake web UI to continue using the full set of Snowflake features.
[2025-03-06T22:53:05.867+0000] {processor.py:927} WARNING - No viable dags retrieved from /opt/airflow/dags/lab1_ETL.py
[2025-03-06T22:53:05.873+0000] {processor.py:208} INFO - Processing /opt/airflow/dags/lab1_ETL.py took 0.353 seconds
[2025-03-06T22:53:36.388+0000] {processor.py:186} INFO - Started process (PID=356) to work on /opt/airflow/dags/lab1_ETL.py
[2025-03-06T22:53:36.410+0000] {processor.py:914} INFO - Processing file /opt/airflow/dags/lab1_ETL.py for tasks to queue
[2025-03-06T22:53:36.412+0000] {logging_mixin.py:190} INFO - [2025-03-06T22:53:36.411+0000] {dagbag.py:587} INFO - Filling up the DagBag from /opt/airflow/dags/lab1_ETL.py
[2025-03-06T22:53:36.609+0000] {logging_mixin.py:190} INFO - [2025-03-06T22:53:36.609+0000] {base.py:84} INFO - Retrieving connection 'snowflake_conn'
[2025-03-06T22:53:36.609+0000] {logging_mixin.py:190} INFO - [2025-03-06T22:53:36.609+0000] {connection.py:413} INFO - Snowflake Connector for Python Version: 3.12.1, Python Version: 3.12.5, Platform: Linux-6.12.5-linuxkit-aarch64-with-glibc2.36
[2025-03-06T22:53:36.610+0000] {logging_mixin.py:190} INFO - [2025-03-06T22:53:36.610+0000] {connection.py:1196} INFO - Connecting to GLOBAL Snowflake domain
[2025-03-06T22:53:36.610+0000] {logging_mixin.py:190} INFO - [2025-03-06T22:53:36.610+0000] {connection.py:1277} INFO - This connection is in OCSP Fail Open Mode. TLS Certificates would be checked for validity and revocation status. Any other Certificate Revocation related exceptions or OCSP Responder failures would be disregarded in favor of connectivity.
[2025-03-06T22:53:36.907+0000] {logging_mixin.py:190} INFO - [2025-03-06T22:53:36.905+0000] {dagbag.py:386} ERROR - Failed to import: /opt/airflow/dags/lab1_ETL.py
Traceback (most recent call last):
  File "/home/airflow/.local/lib/python3.12/site-packages/airflow/models/dagbag.py", line 382, in parse
    loader.exec_module(new_module)
  File "<frozen importlib._bootstrap_external>", line 995, in exec_module
  File "<frozen importlib._bootstrap>", line 488, in _call_with_frames_removed
  File "/opt/airflow/dags/lab1_ETL.py", line 86, in <module>
    cur = return_snowflake_conn()
          ^^^^^^^^^^^^^^^^^^^^^^^
  File "/opt/airflow/dags/lab1_ETL.py", line 16, in return_snowflake_conn
    conn = hook.get_conn()
           ^^^^^^^^^^^^^^^
  File "/home/airflow/.local/lib/python3.12/site-packages/airflow/providers/snowflake/hooks/snowflake.py", line 300, in get_conn
    conn = connector.connect(**conn_config)
           ^^^^^^^^^^^^^^^^^^^^^^^^^^^^^^^^
  File "/home/airflow/.local/lib/python3.12/site-packages/snowflake/connector/__init__.py", line 55, in Connect
    return SnowflakeConnection(**kwargs)
           ^^^^^^^^^^^^^^^^^^^^^^^^^^^^^
  File "/home/airflow/.local/lib/python3.12/site-packages/snowflake/connector/connection.py", line 456, in __init__
    self.connect(**kwargs)
  File "/home/airflow/.local/lib/python3.12/site-packages/snowflake/connector/connection.py", line 771, in connect
    self.__open_connection()
  File "/home/airflow/.local/lib/python3.12/site-packages/snowflake/connector/connection.py", line 1099, in __open_connection
    self.authenticate_with_retry(self.auth_class)
  File "/home/airflow/.local/lib/python3.12/site-packages/snowflake/connector/connection.py", line 1386, in authenticate_with_retry
    self._authenticate(auth_instance)
  File "/home/airflow/.local/lib/python3.12/site-packages/snowflake/connector/connection.py", line 1414, in _authenticate
    auth.authenticate(
  File "/home/airflow/.local/lib/python3.12/site-packages/snowflake/connector/auth/_auth.py", line 401, in authenticate
    Error.errorhandler_wrapper(
  File "/home/airflow/.local/lib/python3.12/site-packages/snowflake/connector/errors.py", line 284, in errorhandler_wrapper
    handed_over = Error.hand_to_other_handler(
                  ^^^^^^^^^^^^^^^^^^^^^^^^^^^^
  File "/home/airflow/.local/lib/python3.12/site-packages/snowflake/connector/errors.py", line 342, in hand_to_other_handler
    connection.errorhandler(connection, cursor, error_class, error_value)
  File "/home/airflow/.local/lib/python3.12/site-packages/snowflake/connector/errors.py", line 215, in default_errorhandler
    raise error_class(
snowflake.connector.errors.DatabaseError: 250001 (08001): None: Failed to connect to DB: wbb10936.snowflakecomputing.com:443. Your free trial has ended and all of your virtual warehouses have been suspended. Add billing information in the Snowflake web UI to continue using the full set of Snowflake features.
[2025-03-06T22:53:36.908+0000] {processor.py:927} WARNING - No viable dags retrieved from /opt/airflow/dags/lab1_ETL.py
[2025-03-06T22:53:36.915+0000] {processor.py:208} INFO - Processing /opt/airflow/dags/lab1_ETL.py took 0.533 seconds
[2025-03-06T22:54:07.386+0000] {processor.py:186} INFO - Started process (PID=377) to work on /opt/airflow/dags/lab1_ETL.py
[2025-03-06T22:54:07.387+0000] {processor.py:914} INFO - Processing file /opt/airflow/dags/lab1_ETL.py for tasks to queue
[2025-03-06T22:54:07.388+0000] {logging_mixin.py:190} INFO - [2025-03-06T22:54:07.388+0000] {dagbag.py:587} INFO - Filling up the DagBag from /opt/airflow/dags/lab1_ETL.py
[2025-03-06T22:54:07.485+0000] {logging_mixin.py:190} INFO - [2025-03-06T22:54:07.484+0000] {base.py:84} INFO - Retrieving connection 'snowflake_conn'
[2025-03-06T22:54:07.485+0000] {logging_mixin.py:190} INFO - [2025-03-06T22:54:07.485+0000] {connection.py:413} INFO - Snowflake Connector for Python Version: 3.12.1, Python Version: 3.12.5, Platform: Linux-6.12.5-linuxkit-aarch64-with-glibc2.36
[2025-03-06T22:54:07.486+0000] {logging_mixin.py:190} INFO - [2025-03-06T22:54:07.486+0000] {connection.py:1196} INFO - Connecting to GLOBAL Snowflake domain
[2025-03-06T22:54:07.486+0000] {logging_mixin.py:190} INFO - [2025-03-06T22:54:07.486+0000] {connection.py:1277} INFO - This connection is in OCSP Fail Open Mode. TLS Certificates would be checked for validity and revocation status. Any other Certificate Revocation related exceptions or OCSP Responder failures would be disregarded in favor of connectivity.
[2025-03-06T22:54:07.929+0000] {logging_mixin.py:190} INFO - [2025-03-06T22:54:07.926+0000] {dagbag.py:386} ERROR - Failed to import: /opt/airflow/dags/lab1_ETL.py
Traceback (most recent call last):
  File "/home/airflow/.local/lib/python3.12/site-packages/airflow/models/dagbag.py", line 382, in parse
    loader.exec_module(new_module)
  File "<frozen importlib._bootstrap_external>", line 995, in exec_module
  File "<frozen importlib._bootstrap>", line 488, in _call_with_frames_removed
  File "/opt/airflow/dags/lab1_ETL.py", line 86, in <module>
    cur = return_snowflake_conn()
          ^^^^^^^^^^^^^^^^^^^^^^^
  File "/opt/airflow/dags/lab1_ETL.py", line 16, in return_snowflake_conn
    conn = hook.get_conn()
           ^^^^^^^^^^^^^^^
  File "/home/airflow/.local/lib/python3.12/site-packages/airflow/providers/snowflake/hooks/snowflake.py", line 300, in get_conn
    conn = connector.connect(**conn_config)
           ^^^^^^^^^^^^^^^^^^^^^^^^^^^^^^^^
  File "/home/airflow/.local/lib/python3.12/site-packages/snowflake/connector/__init__.py", line 55, in Connect
    return SnowflakeConnection(**kwargs)
           ^^^^^^^^^^^^^^^^^^^^^^^^^^^^^
  File "/home/airflow/.local/lib/python3.12/site-packages/snowflake/connector/connection.py", line 456, in __init__
    self.connect(**kwargs)
  File "/home/airflow/.local/lib/python3.12/site-packages/snowflake/connector/connection.py", line 771, in connect
    self.__open_connection()
  File "/home/airflow/.local/lib/python3.12/site-packages/snowflake/connector/connection.py", line 1099, in __open_connection
    self.authenticate_with_retry(self.auth_class)
  File "/home/airflow/.local/lib/python3.12/site-packages/snowflake/connector/connection.py", line 1386, in authenticate_with_retry
    self._authenticate(auth_instance)
  File "/home/airflow/.local/lib/python3.12/site-packages/snowflake/connector/connection.py", line 1414, in _authenticate
    auth.authenticate(
  File "/home/airflow/.local/lib/python3.12/site-packages/snowflake/connector/auth/_auth.py", line 401, in authenticate
    Error.errorhandler_wrapper(
  File "/home/airflow/.local/lib/python3.12/site-packages/snowflake/connector/errors.py", line 284, in errorhandler_wrapper
    handed_over = Error.hand_to_other_handler(
                  ^^^^^^^^^^^^^^^^^^^^^^^^^^^^
  File "/home/airflow/.local/lib/python3.12/site-packages/snowflake/connector/errors.py", line 342, in hand_to_other_handler
    connection.errorhandler(connection, cursor, error_class, error_value)
  File "/home/airflow/.local/lib/python3.12/site-packages/snowflake/connector/errors.py", line 215, in default_errorhandler
    raise error_class(
snowflake.connector.errors.DatabaseError: 250001 (08001): None: Failed to connect to DB: wbb10936.snowflakecomputing.com:443. Your free trial has ended and all of your virtual warehouses have been suspended. Add billing information in the Snowflake web UI to continue using the full set of Snowflake features.
[2025-03-06T22:54:07.933+0000] {processor.py:927} WARNING - No viable dags retrieved from /opt/airflow/dags/lab1_ETL.py
[2025-03-06T22:54:07.944+0000] {processor.py:208} INFO - Processing /opt/airflow/dags/lab1_ETL.py took 0.564 seconds
[2025-03-06T22:54:38.359+0000] {processor.py:186} INFO - Started process (PID=398) to work on /opt/airflow/dags/lab1_ETL.py
[2025-03-06T22:54:38.361+0000] {processor.py:914} INFO - Processing file /opt/airflow/dags/lab1_ETL.py for tasks to queue
[2025-03-06T22:54:38.361+0000] {logging_mixin.py:190} INFO - [2025-03-06T22:54:38.361+0000] {dagbag.py:587} INFO - Filling up the DagBag from /opt/airflow/dags/lab1_ETL.py
[2025-03-06T22:54:38.475+0000] {logging_mixin.py:190} INFO - [2025-03-06T22:54:38.475+0000] {base.py:84} INFO - Retrieving connection 'snowflake_conn'
[2025-03-06T22:54:38.476+0000] {logging_mixin.py:190} INFO - [2025-03-06T22:54:38.476+0000] {connection.py:413} INFO - Snowflake Connector for Python Version: 3.12.1, Python Version: 3.12.5, Platform: Linux-6.12.5-linuxkit-aarch64-with-glibc2.36
[2025-03-06T22:54:38.480+0000] {logging_mixin.py:190} INFO - [2025-03-06T22:54:38.480+0000] {connection.py:1196} INFO - Connecting to GLOBAL Snowflake domain
[2025-03-06T22:54:38.481+0000] {logging_mixin.py:190} INFO - [2025-03-06T22:54:38.480+0000] {connection.py:1277} INFO - This connection is in OCSP Fail Open Mode. TLS Certificates would be checked for validity and revocation status. Any other Certificate Revocation related exceptions or OCSP Responder failures would be disregarded in favor of connectivity.
[2025-03-06T22:54:38.708+0000] {logging_mixin.py:190} INFO - [2025-03-06T22:54:38.706+0000] {dagbag.py:386} ERROR - Failed to import: /opt/airflow/dags/lab1_ETL.py
Traceback (most recent call last):
  File "/home/airflow/.local/lib/python3.12/site-packages/airflow/models/dagbag.py", line 382, in parse
    loader.exec_module(new_module)
  File "<frozen importlib._bootstrap_external>", line 995, in exec_module
  File "<frozen importlib._bootstrap>", line 488, in _call_with_frames_removed
  File "/opt/airflow/dags/lab1_ETL.py", line 86, in <module>
    cur = return_snowflake_conn()
          ^^^^^^^^^^^^^^^^^^^^^^^
  File "/opt/airflow/dags/lab1_ETL.py", line 16, in return_snowflake_conn
    conn = hook.get_conn()
           ^^^^^^^^^^^^^^^
  File "/home/airflow/.local/lib/python3.12/site-packages/airflow/providers/snowflake/hooks/snowflake.py", line 300, in get_conn
    conn = connector.connect(**conn_config)
           ^^^^^^^^^^^^^^^^^^^^^^^^^^^^^^^^
  File "/home/airflow/.local/lib/python3.12/site-packages/snowflake/connector/__init__.py", line 55, in Connect
    return SnowflakeConnection(**kwargs)
           ^^^^^^^^^^^^^^^^^^^^^^^^^^^^^
  File "/home/airflow/.local/lib/python3.12/site-packages/snowflake/connector/connection.py", line 456, in __init__
    self.connect(**kwargs)
  File "/home/airflow/.local/lib/python3.12/site-packages/snowflake/connector/connection.py", line 771, in connect
    self.__open_connection()
  File "/home/airflow/.local/lib/python3.12/site-packages/snowflake/connector/connection.py", line 1099, in __open_connection
    self.authenticate_with_retry(self.auth_class)
  File "/home/airflow/.local/lib/python3.12/site-packages/snowflake/connector/connection.py", line 1386, in authenticate_with_retry
    self._authenticate(auth_instance)
  File "/home/airflow/.local/lib/python3.12/site-packages/snowflake/connector/connection.py", line 1414, in _authenticate
    auth.authenticate(
  File "/home/airflow/.local/lib/python3.12/site-packages/snowflake/connector/auth/_auth.py", line 401, in authenticate
    Error.errorhandler_wrapper(
  File "/home/airflow/.local/lib/python3.12/site-packages/snowflake/connector/errors.py", line 284, in errorhandler_wrapper
    handed_over = Error.hand_to_other_handler(
                  ^^^^^^^^^^^^^^^^^^^^^^^^^^^^
  File "/home/airflow/.local/lib/python3.12/site-packages/snowflake/connector/errors.py", line 342, in hand_to_other_handler
    connection.errorhandler(connection, cursor, error_class, error_value)
  File "/home/airflow/.local/lib/python3.12/site-packages/snowflake/connector/errors.py", line 215, in default_errorhandler
    raise error_class(
snowflake.connector.errors.DatabaseError: 250001 (08001): None: Failed to connect to DB: wbb10936.snowflakecomputing.com:443. Your free trial has ended and all of your virtual warehouses have been suspended. Add billing information in the Snowflake web UI to continue using the full set of Snowflake features.
[2025-03-06T22:54:38.709+0000] {processor.py:927} WARNING - No viable dags retrieved from /opt/airflow/dags/lab1_ETL.py
[2025-03-06T22:54:38.720+0000] {processor.py:208} INFO - Processing /opt/airflow/dags/lab1_ETL.py took 0.369 seconds
[2025-03-06T22:55:09.285+0000] {processor.py:186} INFO - Started process (PID=419) to work on /opt/airflow/dags/lab1_ETL.py
[2025-03-06T22:55:09.286+0000] {processor.py:914} INFO - Processing file /opt/airflow/dags/lab1_ETL.py for tasks to queue
[2025-03-06T22:55:09.288+0000] {logging_mixin.py:190} INFO - [2025-03-06T22:55:09.288+0000] {dagbag.py:587} INFO - Filling up the DagBag from /opt/airflow/dags/lab1_ETL.py
[2025-03-06T22:55:09.400+0000] {logging_mixin.py:190} INFO - [2025-03-06T22:55:09.400+0000] {base.py:84} INFO - Retrieving connection 'snowflake_conn'
[2025-03-06T22:55:09.400+0000] {logging_mixin.py:190} INFO - [2025-03-06T22:55:09.400+0000] {connection.py:413} INFO - Snowflake Connector for Python Version: 3.12.1, Python Version: 3.12.5, Platform: Linux-6.12.5-linuxkit-aarch64-with-glibc2.36
[2025-03-06T22:55:09.401+0000] {logging_mixin.py:190} INFO - [2025-03-06T22:55:09.401+0000] {connection.py:1196} INFO - Connecting to GLOBAL Snowflake domain
[2025-03-06T22:55:09.401+0000] {logging_mixin.py:190} INFO - [2025-03-06T22:55:09.401+0000] {connection.py:1277} INFO - This connection is in OCSP Fail Open Mode. TLS Certificates would be checked for validity and revocation status. Any other Certificate Revocation related exceptions or OCSP Responder failures would be disregarded in favor of connectivity.
[2025-03-06T22:55:09.638+0000] {logging_mixin.py:190} INFO - [2025-03-06T22:55:09.635+0000] {dagbag.py:386} ERROR - Failed to import: /opt/airflow/dags/lab1_ETL.py
Traceback (most recent call last):
  File "/home/airflow/.local/lib/python3.12/site-packages/airflow/models/dagbag.py", line 382, in parse
    loader.exec_module(new_module)
  File "<frozen importlib._bootstrap_external>", line 995, in exec_module
  File "<frozen importlib._bootstrap>", line 488, in _call_with_frames_removed
  File "/opt/airflow/dags/lab1_ETL.py", line 86, in <module>
    cur = return_snowflake_conn()
          ^^^^^^^^^^^^^^^^^^^^^^^
  File "/opt/airflow/dags/lab1_ETL.py", line 16, in return_snowflake_conn
    conn = hook.get_conn()
           ^^^^^^^^^^^^^^^
  File "/home/airflow/.local/lib/python3.12/site-packages/airflow/providers/snowflake/hooks/snowflake.py", line 300, in get_conn
    conn = connector.connect(**conn_config)
           ^^^^^^^^^^^^^^^^^^^^^^^^^^^^^^^^
  File "/home/airflow/.local/lib/python3.12/site-packages/snowflake/connector/__init__.py", line 55, in Connect
    return SnowflakeConnection(**kwargs)
           ^^^^^^^^^^^^^^^^^^^^^^^^^^^^^
  File "/home/airflow/.local/lib/python3.12/site-packages/snowflake/connector/connection.py", line 456, in __init__
    self.connect(**kwargs)
  File "/home/airflow/.local/lib/python3.12/site-packages/snowflake/connector/connection.py", line 771, in connect
    self.__open_connection()
  File "/home/airflow/.local/lib/python3.12/site-packages/snowflake/connector/connection.py", line 1099, in __open_connection
    self.authenticate_with_retry(self.auth_class)
  File "/home/airflow/.local/lib/python3.12/site-packages/snowflake/connector/connection.py", line 1386, in authenticate_with_retry
    self._authenticate(auth_instance)
  File "/home/airflow/.local/lib/python3.12/site-packages/snowflake/connector/connection.py", line 1414, in _authenticate
    auth.authenticate(
  File "/home/airflow/.local/lib/python3.12/site-packages/snowflake/connector/auth/_auth.py", line 401, in authenticate
    Error.errorhandler_wrapper(
  File "/home/airflow/.local/lib/python3.12/site-packages/snowflake/connector/errors.py", line 284, in errorhandler_wrapper
    handed_over = Error.hand_to_other_handler(
                  ^^^^^^^^^^^^^^^^^^^^^^^^^^^^
  File "/home/airflow/.local/lib/python3.12/site-packages/snowflake/connector/errors.py", line 342, in hand_to_other_handler
    connection.errorhandler(connection, cursor, error_class, error_value)
  File "/home/airflow/.local/lib/python3.12/site-packages/snowflake/connector/errors.py", line 215, in default_errorhandler
    raise error_class(
snowflake.connector.errors.DatabaseError: 250001 (08001): None: Failed to connect to DB: wbb10936.snowflakecomputing.com:443. Your free trial has ended and all of your virtual warehouses have been suspended. Add billing information in the Snowflake web UI to continue using the full set of Snowflake features.
[2025-03-06T22:55:09.641+0000] {processor.py:927} WARNING - No viable dags retrieved from /opt/airflow/dags/lab1_ETL.py
[2025-03-06T22:55:09.653+0000] {processor.py:208} INFO - Processing /opt/airflow/dags/lab1_ETL.py took 0.380 seconds
[2025-03-06T22:55:40.160+0000] {processor.py:186} INFO - Started process (PID=446) to work on /opt/airflow/dags/lab1_ETL.py
[2025-03-06T22:55:40.162+0000] {processor.py:914} INFO - Processing file /opt/airflow/dags/lab1_ETL.py for tasks to queue
[2025-03-06T22:55:40.168+0000] {logging_mixin.py:190} INFO - [2025-03-06T22:55:40.167+0000] {dagbag.py:587} INFO - Filling up the DagBag from /opt/airflow/dags/lab1_ETL.py
[2025-03-06T22:55:40.297+0000] {logging_mixin.py:190} INFO - [2025-03-06T22:55:40.297+0000] {base.py:84} INFO - Retrieving connection 'snowflake_conn'
[2025-03-06T22:55:40.297+0000] {logging_mixin.py:190} INFO - [2025-03-06T22:55:40.297+0000] {connection.py:413} INFO - Snowflake Connector for Python Version: 3.12.1, Python Version: 3.12.5, Platform: Linux-6.12.5-linuxkit-aarch64-with-glibc2.36
[2025-03-06T22:55:40.298+0000] {logging_mixin.py:190} INFO - [2025-03-06T22:55:40.298+0000] {connection.py:1196} INFO - Connecting to GLOBAL Snowflake domain
[2025-03-06T22:55:40.298+0000] {logging_mixin.py:190} INFO - [2025-03-06T22:55:40.298+0000] {connection.py:1277} INFO - This connection is in OCSP Fail Open Mode. TLS Certificates would be checked for validity and revocation status. Any other Certificate Revocation related exceptions or OCSP Responder failures would be disregarded in favor of connectivity.
[2025-03-06T22:55:40.556+0000] {logging_mixin.py:190} INFO - [2025-03-06T22:55:40.554+0000] {dagbag.py:386} ERROR - Failed to import: /opt/airflow/dags/lab1_ETL.py
Traceback (most recent call last):
  File "/home/airflow/.local/lib/python3.12/site-packages/airflow/models/dagbag.py", line 382, in parse
    loader.exec_module(new_module)
  File "<frozen importlib._bootstrap_external>", line 995, in exec_module
  File "<frozen importlib._bootstrap>", line 488, in _call_with_frames_removed
  File "/opt/airflow/dags/lab1_ETL.py", line 86, in <module>
    cur = return_snowflake_conn()
          ^^^^^^^^^^^^^^^^^^^^^^^
  File "/opt/airflow/dags/lab1_ETL.py", line 16, in return_snowflake_conn
    conn = hook.get_conn()
           ^^^^^^^^^^^^^^^
  File "/home/airflow/.local/lib/python3.12/site-packages/airflow/providers/snowflake/hooks/snowflake.py", line 300, in get_conn
    conn = connector.connect(**conn_config)
           ^^^^^^^^^^^^^^^^^^^^^^^^^^^^^^^^
  File "/home/airflow/.local/lib/python3.12/site-packages/snowflake/connector/__init__.py", line 55, in Connect
    return SnowflakeConnection(**kwargs)
           ^^^^^^^^^^^^^^^^^^^^^^^^^^^^^
  File "/home/airflow/.local/lib/python3.12/site-packages/snowflake/connector/connection.py", line 456, in __init__
    self.connect(**kwargs)
  File "/home/airflow/.local/lib/python3.12/site-packages/snowflake/connector/connection.py", line 771, in connect
    self.__open_connection()
  File "/home/airflow/.local/lib/python3.12/site-packages/snowflake/connector/connection.py", line 1099, in __open_connection
    self.authenticate_with_retry(self.auth_class)
  File "/home/airflow/.local/lib/python3.12/site-packages/snowflake/connector/connection.py", line 1386, in authenticate_with_retry
    self._authenticate(auth_instance)
  File "/home/airflow/.local/lib/python3.12/site-packages/snowflake/connector/connection.py", line 1414, in _authenticate
    auth.authenticate(
  File "/home/airflow/.local/lib/python3.12/site-packages/snowflake/connector/auth/_auth.py", line 401, in authenticate
    Error.errorhandler_wrapper(
  File "/home/airflow/.local/lib/python3.12/site-packages/snowflake/connector/errors.py", line 284, in errorhandler_wrapper
    handed_over = Error.hand_to_other_handler(
                  ^^^^^^^^^^^^^^^^^^^^^^^^^^^^
  File "/home/airflow/.local/lib/python3.12/site-packages/snowflake/connector/errors.py", line 342, in hand_to_other_handler
    connection.errorhandler(connection, cursor, error_class, error_value)
  File "/home/airflow/.local/lib/python3.12/site-packages/snowflake/connector/errors.py", line 215, in default_errorhandler
    raise error_class(
snowflake.connector.errors.DatabaseError: 250001 (08001): None: Failed to connect to DB: wbb10936.snowflakecomputing.com:443. Your free trial has ended and all of your virtual warehouses have been suspended. Add billing information in the Snowflake web UI to continue using the full set of Snowflake features.
[2025-03-06T22:55:40.559+0000] {processor.py:927} WARNING - No viable dags retrieved from /opt/airflow/dags/lab1_ETL.py
[2025-03-06T22:55:40.571+0000] {processor.py:208} INFO - Processing /opt/airflow/dags/lab1_ETL.py took 0.425 seconds
[2025-03-06T22:56:11.040+0000] {processor.py:186} INFO - Started process (PID=466) to work on /opt/airflow/dags/lab1_ETL.py
[2025-03-06T22:56:11.042+0000] {processor.py:914} INFO - Processing file /opt/airflow/dags/lab1_ETL.py for tasks to queue
[2025-03-06T22:56:11.043+0000] {logging_mixin.py:190} INFO - [2025-03-06T22:56:11.042+0000] {dagbag.py:587} INFO - Filling up the DagBag from /opt/airflow/dags/lab1_ETL.py
[2025-03-06T22:56:11.141+0000] {logging_mixin.py:190} INFO - [2025-03-06T22:56:11.141+0000] {base.py:84} INFO - Retrieving connection 'snowflake_conn'
[2025-03-06T22:56:11.142+0000] {logging_mixin.py:190} INFO - [2025-03-06T22:56:11.142+0000] {connection.py:413} INFO - Snowflake Connector for Python Version: 3.12.1, Python Version: 3.12.5, Platform: Linux-6.12.5-linuxkit-aarch64-with-glibc2.36
[2025-03-06T22:56:11.142+0000] {logging_mixin.py:190} INFO - [2025-03-06T22:56:11.142+0000] {connection.py:1196} INFO - Connecting to GLOBAL Snowflake domain
[2025-03-06T22:56:11.142+0000] {logging_mixin.py:190} INFO - [2025-03-06T22:56:11.142+0000] {connection.py:1277} INFO - This connection is in OCSP Fail Open Mode. TLS Certificates would be checked for validity and revocation status. Any other Certificate Revocation related exceptions or OCSP Responder failures would be disregarded in favor of connectivity.
[2025-03-06T22:56:11.410+0000] {logging_mixin.py:190} INFO - [2025-03-06T22:56:11.408+0000] {dagbag.py:386} ERROR - Failed to import: /opt/airflow/dags/lab1_ETL.py
Traceback (most recent call last):
  File "/home/airflow/.local/lib/python3.12/site-packages/airflow/models/dagbag.py", line 382, in parse
    loader.exec_module(new_module)
  File "<frozen importlib._bootstrap_external>", line 995, in exec_module
  File "<frozen importlib._bootstrap>", line 488, in _call_with_frames_removed
  File "/opt/airflow/dags/lab1_ETL.py", line 86, in <module>
    cur = return_snowflake_conn()
          ^^^^^^^^^^^^^^^^^^^^^^^
  File "/opt/airflow/dags/lab1_ETL.py", line 16, in return_snowflake_conn
    conn = hook.get_conn()
           ^^^^^^^^^^^^^^^
  File "/home/airflow/.local/lib/python3.12/site-packages/airflow/providers/snowflake/hooks/snowflake.py", line 300, in get_conn
    conn = connector.connect(**conn_config)
           ^^^^^^^^^^^^^^^^^^^^^^^^^^^^^^^^
  File "/home/airflow/.local/lib/python3.12/site-packages/snowflake/connector/__init__.py", line 55, in Connect
    return SnowflakeConnection(**kwargs)
           ^^^^^^^^^^^^^^^^^^^^^^^^^^^^^
  File "/home/airflow/.local/lib/python3.12/site-packages/snowflake/connector/connection.py", line 456, in __init__
    self.connect(**kwargs)
  File "/home/airflow/.local/lib/python3.12/site-packages/snowflake/connector/connection.py", line 771, in connect
    self.__open_connection()
  File "/home/airflow/.local/lib/python3.12/site-packages/snowflake/connector/connection.py", line 1099, in __open_connection
    self.authenticate_with_retry(self.auth_class)
  File "/home/airflow/.local/lib/python3.12/site-packages/snowflake/connector/connection.py", line 1386, in authenticate_with_retry
    self._authenticate(auth_instance)
  File "/home/airflow/.local/lib/python3.12/site-packages/snowflake/connector/connection.py", line 1414, in _authenticate
    auth.authenticate(
  File "/home/airflow/.local/lib/python3.12/site-packages/snowflake/connector/auth/_auth.py", line 401, in authenticate
    Error.errorhandler_wrapper(
  File "/home/airflow/.local/lib/python3.12/site-packages/snowflake/connector/errors.py", line 284, in errorhandler_wrapper
    handed_over = Error.hand_to_other_handler(
                  ^^^^^^^^^^^^^^^^^^^^^^^^^^^^
  File "/home/airflow/.local/lib/python3.12/site-packages/snowflake/connector/errors.py", line 342, in hand_to_other_handler
    connection.errorhandler(connection, cursor, error_class, error_value)
  File "/home/airflow/.local/lib/python3.12/site-packages/snowflake/connector/errors.py", line 215, in default_errorhandler
    raise error_class(
snowflake.connector.errors.DatabaseError: 250001 (08001): None: Failed to connect to DB: wbb10936.snowflakecomputing.com:443. Your free trial has ended and all of your virtual warehouses have been suspended. Add billing information in the Snowflake web UI to continue using the full set of Snowflake features.
[2025-03-06T22:56:11.411+0000] {processor.py:927} WARNING - No viable dags retrieved from /opt/airflow/dags/lab1_ETL.py
[2025-03-06T22:56:11.422+0000] {processor.py:208} INFO - Processing /opt/airflow/dags/lab1_ETL.py took 0.396 seconds
[2025-03-06T22:56:41.900+0000] {processor.py:186} INFO - Started process (PID=488) to work on /opt/airflow/dags/lab1_ETL.py
[2025-03-06T22:56:41.902+0000] {processor.py:914} INFO - Processing file /opt/airflow/dags/lab1_ETL.py for tasks to queue
[2025-03-06T22:56:41.903+0000] {logging_mixin.py:190} INFO - [2025-03-06T22:56:41.903+0000] {dagbag.py:587} INFO - Filling up the DagBag from /opt/airflow/dags/lab1_ETL.py
[2025-03-06T22:56:41.997+0000] {logging_mixin.py:190} INFO - [2025-03-06T22:56:41.997+0000] {base.py:84} INFO - Retrieving connection 'snowflake_conn'
[2025-03-06T22:56:41.998+0000] {logging_mixin.py:190} INFO - [2025-03-06T22:56:41.997+0000] {connection.py:413} INFO - Snowflake Connector for Python Version: 3.12.1, Python Version: 3.12.5, Platform: Linux-6.12.5-linuxkit-aarch64-with-glibc2.36
[2025-03-06T22:56:41.998+0000] {logging_mixin.py:190} INFO - [2025-03-06T22:56:41.998+0000] {connection.py:1196} INFO - Connecting to GLOBAL Snowflake domain
[2025-03-06T22:56:41.998+0000] {logging_mixin.py:190} INFO - [2025-03-06T22:56:41.998+0000] {connection.py:1277} INFO - This connection is in OCSP Fail Open Mode. TLS Certificates would be checked for validity and revocation status. Any other Certificate Revocation related exceptions or OCSP Responder failures would be disregarded in favor of connectivity.
[2025-03-06T22:56:42.231+0000] {logging_mixin.py:190} INFO - [2025-03-06T22:56:42.230+0000] {dagbag.py:386} ERROR - Failed to import: /opt/airflow/dags/lab1_ETL.py
Traceback (most recent call last):
  File "/home/airflow/.local/lib/python3.12/site-packages/airflow/models/dagbag.py", line 382, in parse
    loader.exec_module(new_module)
  File "<frozen importlib._bootstrap_external>", line 995, in exec_module
  File "<frozen importlib._bootstrap>", line 488, in _call_with_frames_removed
  File "/opt/airflow/dags/lab1_ETL.py", line 86, in <module>
    cur = return_snowflake_conn()
          ^^^^^^^^^^^^^^^^^^^^^^^
  File "/opt/airflow/dags/lab1_ETL.py", line 16, in return_snowflake_conn
    conn = hook.get_conn()
           ^^^^^^^^^^^^^^^
  File "/home/airflow/.local/lib/python3.12/site-packages/airflow/providers/snowflake/hooks/snowflake.py", line 300, in get_conn
    conn = connector.connect(**conn_config)
           ^^^^^^^^^^^^^^^^^^^^^^^^^^^^^^^^
  File "/home/airflow/.local/lib/python3.12/site-packages/snowflake/connector/__init__.py", line 55, in Connect
    return SnowflakeConnection(**kwargs)
           ^^^^^^^^^^^^^^^^^^^^^^^^^^^^^
  File "/home/airflow/.local/lib/python3.12/site-packages/snowflake/connector/connection.py", line 456, in __init__
    self.connect(**kwargs)
  File "/home/airflow/.local/lib/python3.12/site-packages/snowflake/connector/connection.py", line 771, in connect
    self.__open_connection()
  File "/home/airflow/.local/lib/python3.12/site-packages/snowflake/connector/connection.py", line 1099, in __open_connection
    self.authenticate_with_retry(self.auth_class)
  File "/home/airflow/.local/lib/python3.12/site-packages/snowflake/connector/connection.py", line 1386, in authenticate_with_retry
    self._authenticate(auth_instance)
  File "/home/airflow/.local/lib/python3.12/site-packages/snowflake/connector/connection.py", line 1414, in _authenticate
    auth.authenticate(
  File "/home/airflow/.local/lib/python3.12/site-packages/snowflake/connector/auth/_auth.py", line 401, in authenticate
    Error.errorhandler_wrapper(
  File "/home/airflow/.local/lib/python3.12/site-packages/snowflake/connector/errors.py", line 284, in errorhandler_wrapper
    handed_over = Error.hand_to_other_handler(
                  ^^^^^^^^^^^^^^^^^^^^^^^^^^^^
  File "/home/airflow/.local/lib/python3.12/site-packages/snowflake/connector/errors.py", line 342, in hand_to_other_handler
    connection.errorhandler(connection, cursor, error_class, error_value)
  File "/home/airflow/.local/lib/python3.12/site-packages/snowflake/connector/errors.py", line 215, in default_errorhandler
    raise error_class(
snowflake.connector.errors.DatabaseError: 250001 (08001): None: Failed to connect to DB: wbb10936.snowflakecomputing.com:443. Your free trial has ended and all of your virtual warehouses have been suspended. Add billing information in the Snowflake web UI to continue using the full set of Snowflake features.
[2025-03-06T22:56:42.232+0000] {processor.py:927} WARNING - No viable dags retrieved from /opt/airflow/dags/lab1_ETL.py
[2025-03-06T22:56:42.240+0000] {processor.py:208} INFO - Processing /opt/airflow/dags/lab1_ETL.py took 0.351 seconds
[2025-03-06T22:57:12.652+0000] {processor.py:186} INFO - Started process (PID=509) to work on /opt/airflow/dags/lab1_ETL.py
[2025-03-06T22:57:12.654+0000] {processor.py:914} INFO - Processing file /opt/airflow/dags/lab1_ETL.py for tasks to queue
[2025-03-06T22:57:12.655+0000] {logging_mixin.py:190} INFO - [2025-03-06T22:57:12.654+0000] {dagbag.py:587} INFO - Filling up the DagBag from /opt/airflow/dags/lab1_ETL.py
[2025-03-06T22:57:12.762+0000] {logging_mixin.py:190} INFO - [2025-03-06T22:57:12.762+0000] {base.py:84} INFO - Retrieving connection 'snowflake_conn'
[2025-03-06T22:57:12.763+0000] {logging_mixin.py:190} INFO - [2025-03-06T22:57:12.763+0000] {connection.py:413} INFO - Snowflake Connector for Python Version: 3.12.1, Python Version: 3.12.5, Platform: Linux-6.12.5-linuxkit-aarch64-with-glibc2.36
[2025-03-06T22:57:12.763+0000] {logging_mixin.py:190} INFO - [2025-03-06T22:57:12.763+0000] {connection.py:1196} INFO - Connecting to GLOBAL Snowflake domain
[2025-03-06T22:57:12.764+0000] {logging_mixin.py:190} INFO - [2025-03-06T22:57:12.764+0000] {connection.py:1277} INFO - This connection is in OCSP Fail Open Mode. TLS Certificates would be checked for validity and revocation status. Any other Certificate Revocation related exceptions or OCSP Responder failures would be disregarded in favor of connectivity.
[2025-03-06T22:57:13.020+0000] {logging_mixin.py:190} INFO - [2025-03-06T22:57:13.018+0000] {dagbag.py:386} ERROR - Failed to import: /opt/airflow/dags/lab1_ETL.py
Traceback (most recent call last):
  File "/home/airflow/.local/lib/python3.12/site-packages/airflow/models/dagbag.py", line 382, in parse
    loader.exec_module(new_module)
  File "<frozen importlib._bootstrap_external>", line 995, in exec_module
  File "<frozen importlib._bootstrap>", line 488, in _call_with_frames_removed
  File "/opt/airflow/dags/lab1_ETL.py", line 86, in <module>
    cur = return_snowflake_conn()
          ^^^^^^^^^^^^^^^^^^^^^^^
  File "/opt/airflow/dags/lab1_ETL.py", line 16, in return_snowflake_conn
    conn = hook.get_conn()
           ^^^^^^^^^^^^^^^
  File "/home/airflow/.local/lib/python3.12/site-packages/airflow/providers/snowflake/hooks/snowflake.py", line 300, in get_conn
    conn = connector.connect(**conn_config)
           ^^^^^^^^^^^^^^^^^^^^^^^^^^^^^^^^
  File "/home/airflow/.local/lib/python3.12/site-packages/snowflake/connector/__init__.py", line 55, in Connect
    return SnowflakeConnection(**kwargs)
           ^^^^^^^^^^^^^^^^^^^^^^^^^^^^^
  File "/home/airflow/.local/lib/python3.12/site-packages/snowflake/connector/connection.py", line 456, in __init__
    self.connect(**kwargs)
  File "/home/airflow/.local/lib/python3.12/site-packages/snowflake/connector/connection.py", line 771, in connect
    self.__open_connection()
  File "/home/airflow/.local/lib/python3.12/site-packages/snowflake/connector/connection.py", line 1099, in __open_connection
    self.authenticate_with_retry(self.auth_class)
  File "/home/airflow/.local/lib/python3.12/site-packages/snowflake/connector/connection.py", line 1386, in authenticate_with_retry
    self._authenticate(auth_instance)
  File "/home/airflow/.local/lib/python3.12/site-packages/snowflake/connector/connection.py", line 1414, in _authenticate
    auth.authenticate(
  File "/home/airflow/.local/lib/python3.12/site-packages/snowflake/connector/auth/_auth.py", line 401, in authenticate
    Error.errorhandler_wrapper(
  File "/home/airflow/.local/lib/python3.12/site-packages/snowflake/connector/errors.py", line 284, in errorhandler_wrapper
    handed_over = Error.hand_to_other_handler(
                  ^^^^^^^^^^^^^^^^^^^^^^^^^^^^
  File "/home/airflow/.local/lib/python3.12/site-packages/snowflake/connector/errors.py", line 342, in hand_to_other_handler
    connection.errorhandler(connection, cursor, error_class, error_value)
  File "/home/airflow/.local/lib/python3.12/site-packages/snowflake/connector/errors.py", line 215, in default_errorhandler
    raise error_class(
snowflake.connector.errors.DatabaseError: 250001 (08001): None: Failed to connect to DB: wbb10936.snowflakecomputing.com:443. Your free trial has ended and all of your virtual warehouses have been suspended. Add billing information in the Snowflake web UI to continue using the full set of Snowflake features.
[2025-03-06T22:57:13.022+0000] {processor.py:927} WARNING - No viable dags retrieved from /opt/airflow/dags/lab1_ETL.py
[2025-03-06T22:57:13.036+0000] {processor.py:208} INFO - Processing /opt/airflow/dags/lab1_ETL.py took 0.389 seconds
[2025-03-06T22:57:43.364+0000] {processor.py:186} INFO - Started process (PID=530) to work on /opt/airflow/dags/lab1_ETL.py
[2025-03-06T22:57:43.364+0000] {processor.py:914} INFO - Processing file /opt/airflow/dags/lab1_ETL.py for tasks to queue
[2025-03-06T22:57:43.366+0000] {logging_mixin.py:190} INFO - [2025-03-06T22:57:43.365+0000] {dagbag.py:587} INFO - Filling up the DagBag from /opt/airflow/dags/lab1_ETL.py
[2025-03-06T22:57:43.451+0000] {logging_mixin.py:190} INFO - [2025-03-06T22:57:43.451+0000] {base.py:84} INFO - Retrieving connection 'snowflake_conn'
[2025-03-06T22:57:43.452+0000] {logging_mixin.py:190} INFO - [2025-03-06T22:57:43.452+0000] {connection.py:413} INFO - Snowflake Connector for Python Version: 3.12.1, Python Version: 3.12.5, Platform: Linux-6.12.5-linuxkit-aarch64-with-glibc2.36
[2025-03-06T22:57:43.452+0000] {logging_mixin.py:190} INFO - [2025-03-06T22:57:43.452+0000] {connection.py:1196} INFO - Connecting to GLOBAL Snowflake domain
[2025-03-06T22:57:43.452+0000] {logging_mixin.py:190} INFO - [2025-03-06T22:57:43.452+0000] {connection.py:1277} INFO - This connection is in OCSP Fail Open Mode. TLS Certificates would be checked for validity and revocation status. Any other Certificate Revocation related exceptions or OCSP Responder failures would be disregarded in favor of connectivity.
[2025-03-06T22:57:43.751+0000] {logging_mixin.py:190} INFO - [2025-03-06T22:57:43.750+0000] {dagbag.py:386} ERROR - Failed to import: /opt/airflow/dags/lab1_ETL.py
Traceback (most recent call last):
  File "/home/airflow/.local/lib/python3.12/site-packages/airflow/models/dagbag.py", line 382, in parse
    loader.exec_module(new_module)
  File "<frozen importlib._bootstrap_external>", line 995, in exec_module
  File "<frozen importlib._bootstrap>", line 488, in _call_with_frames_removed
  File "/opt/airflow/dags/lab1_ETL.py", line 86, in <module>
    cur = return_snowflake_conn()
          ^^^^^^^^^^^^^^^^^^^^^^^
  File "/opt/airflow/dags/lab1_ETL.py", line 16, in return_snowflake_conn
    conn = hook.get_conn()
           ^^^^^^^^^^^^^^^
  File "/home/airflow/.local/lib/python3.12/site-packages/airflow/providers/snowflake/hooks/snowflake.py", line 300, in get_conn
    conn = connector.connect(**conn_config)
           ^^^^^^^^^^^^^^^^^^^^^^^^^^^^^^^^
  File "/home/airflow/.local/lib/python3.12/site-packages/snowflake/connector/__init__.py", line 55, in Connect
    return SnowflakeConnection(**kwargs)
           ^^^^^^^^^^^^^^^^^^^^^^^^^^^^^
  File "/home/airflow/.local/lib/python3.12/site-packages/snowflake/connector/connection.py", line 456, in __init__
    self.connect(**kwargs)
  File "/home/airflow/.local/lib/python3.12/site-packages/snowflake/connector/connection.py", line 771, in connect
    self.__open_connection()
  File "/home/airflow/.local/lib/python3.12/site-packages/snowflake/connector/connection.py", line 1099, in __open_connection
    self.authenticate_with_retry(self.auth_class)
  File "/home/airflow/.local/lib/python3.12/site-packages/snowflake/connector/connection.py", line 1386, in authenticate_with_retry
    self._authenticate(auth_instance)
  File "/home/airflow/.local/lib/python3.12/site-packages/snowflake/connector/connection.py", line 1414, in _authenticate
    auth.authenticate(
  File "/home/airflow/.local/lib/python3.12/site-packages/snowflake/connector/auth/_auth.py", line 401, in authenticate
    Error.errorhandler_wrapper(
  File "/home/airflow/.local/lib/python3.12/site-packages/snowflake/connector/errors.py", line 284, in errorhandler_wrapper
    handed_over = Error.hand_to_other_handler(
                  ^^^^^^^^^^^^^^^^^^^^^^^^^^^^
  File "/home/airflow/.local/lib/python3.12/site-packages/snowflake/connector/errors.py", line 342, in hand_to_other_handler
    connection.errorhandler(connection, cursor, error_class, error_value)
  File "/home/airflow/.local/lib/python3.12/site-packages/snowflake/connector/errors.py", line 215, in default_errorhandler
    raise error_class(
snowflake.connector.errors.DatabaseError: 250001 (08001): None: Failed to connect to DB: wbb10936.snowflakecomputing.com:443. Your free trial has ended and all of your virtual warehouses have been suspended. Add billing information in the Snowflake web UI to continue using the full set of Snowflake features.
[2025-03-06T22:57:43.755+0000] {processor.py:927} WARNING - No viable dags retrieved from /opt/airflow/dags/lab1_ETL.py
[2025-03-06T22:57:43.761+0000] {processor.py:208} INFO - Processing /opt/airflow/dags/lab1_ETL.py took 0.402 seconds
[2025-03-06T22:58:14.081+0000] {processor.py:186} INFO - Started process (PID=551) to work on /opt/airflow/dags/lab1_ETL.py
[2025-03-06T22:58:14.082+0000] {processor.py:914} INFO - Processing file /opt/airflow/dags/lab1_ETL.py for tasks to queue
[2025-03-06T22:58:14.084+0000] {logging_mixin.py:190} INFO - [2025-03-06T22:58:14.084+0000] {dagbag.py:587} INFO - Filling up the DagBag from /opt/airflow/dags/lab1_ETL.py
[2025-03-06T22:58:14.188+0000] {logging_mixin.py:190} INFO - [2025-03-06T22:58:14.187+0000] {base.py:84} INFO - Retrieving connection 'snowflake_conn'
[2025-03-06T22:58:14.188+0000] {logging_mixin.py:190} INFO - [2025-03-06T22:58:14.188+0000] {connection.py:413} INFO - Snowflake Connector for Python Version: 3.12.1, Python Version: 3.12.5, Platform: Linux-6.12.5-linuxkit-aarch64-with-glibc2.36
[2025-03-06T22:58:14.189+0000] {logging_mixin.py:190} INFO - [2025-03-06T22:58:14.189+0000] {connection.py:1196} INFO - Connecting to GLOBAL Snowflake domain
[2025-03-06T22:58:14.189+0000] {logging_mixin.py:190} INFO - [2025-03-06T22:58:14.189+0000] {connection.py:1277} INFO - This connection is in OCSP Fail Open Mode. TLS Certificates would be checked for validity and revocation status. Any other Certificate Revocation related exceptions or OCSP Responder failures would be disregarded in favor of connectivity.
[2025-03-06T22:58:14.426+0000] {logging_mixin.py:190} INFO - [2025-03-06T22:58:14.424+0000] {dagbag.py:386} ERROR - Failed to import: /opt/airflow/dags/lab1_ETL.py
Traceback (most recent call last):
  File "/home/airflow/.local/lib/python3.12/site-packages/airflow/models/dagbag.py", line 382, in parse
    loader.exec_module(new_module)
  File "<frozen importlib._bootstrap_external>", line 995, in exec_module
  File "<frozen importlib._bootstrap>", line 488, in _call_with_frames_removed
  File "/opt/airflow/dags/lab1_ETL.py", line 86, in <module>
    cur = return_snowflake_conn()
          ^^^^^^^^^^^^^^^^^^^^^^^
  File "/opt/airflow/dags/lab1_ETL.py", line 16, in return_snowflake_conn
    conn = hook.get_conn()
           ^^^^^^^^^^^^^^^
  File "/home/airflow/.local/lib/python3.12/site-packages/airflow/providers/snowflake/hooks/snowflake.py", line 300, in get_conn
    conn = connector.connect(**conn_config)
           ^^^^^^^^^^^^^^^^^^^^^^^^^^^^^^^^
  File "/home/airflow/.local/lib/python3.12/site-packages/snowflake/connector/__init__.py", line 55, in Connect
    return SnowflakeConnection(**kwargs)
           ^^^^^^^^^^^^^^^^^^^^^^^^^^^^^
  File "/home/airflow/.local/lib/python3.12/site-packages/snowflake/connector/connection.py", line 456, in __init__
    self.connect(**kwargs)
  File "/home/airflow/.local/lib/python3.12/site-packages/snowflake/connector/connection.py", line 771, in connect
    self.__open_connection()
  File "/home/airflow/.local/lib/python3.12/site-packages/snowflake/connector/connection.py", line 1099, in __open_connection
    self.authenticate_with_retry(self.auth_class)
  File "/home/airflow/.local/lib/python3.12/site-packages/snowflake/connector/connection.py", line 1386, in authenticate_with_retry
    self._authenticate(auth_instance)
  File "/home/airflow/.local/lib/python3.12/site-packages/snowflake/connector/connection.py", line 1414, in _authenticate
    auth.authenticate(
  File "/home/airflow/.local/lib/python3.12/site-packages/snowflake/connector/auth/_auth.py", line 401, in authenticate
    Error.errorhandler_wrapper(
  File "/home/airflow/.local/lib/python3.12/site-packages/snowflake/connector/errors.py", line 284, in errorhandler_wrapper
    handed_over = Error.hand_to_other_handler(
                  ^^^^^^^^^^^^^^^^^^^^^^^^^^^^
  File "/home/airflow/.local/lib/python3.12/site-packages/snowflake/connector/errors.py", line 342, in hand_to_other_handler
    connection.errorhandler(connection, cursor, error_class, error_value)
  File "/home/airflow/.local/lib/python3.12/site-packages/snowflake/connector/errors.py", line 215, in default_errorhandler
    raise error_class(
snowflake.connector.errors.DatabaseError: 250001 (08001): None: Failed to connect to DB: wbb10936.snowflakecomputing.com:443. Your free trial has ended and all of your virtual warehouses have been suspended. Add billing information in the Snowflake web UI to continue using the full set of Snowflake features.
[2025-03-06T22:58:14.428+0000] {processor.py:927} WARNING - No viable dags retrieved from /opt/airflow/dags/lab1_ETL.py
[2025-03-06T22:58:14.439+0000] {processor.py:208} INFO - Processing /opt/airflow/dags/lab1_ETL.py took 0.365 seconds
[2025-03-06T22:58:44.830+0000] {processor.py:186} INFO - Started process (PID=572) to work on /opt/airflow/dags/lab1_ETL.py
[2025-03-06T22:58:44.832+0000] {processor.py:914} INFO - Processing file /opt/airflow/dags/lab1_ETL.py for tasks to queue
[2025-03-06T22:58:44.833+0000] {logging_mixin.py:190} INFO - [2025-03-06T22:58:44.832+0000] {dagbag.py:587} INFO - Filling up the DagBag from /opt/airflow/dags/lab1_ETL.py
[2025-03-06T22:58:44.929+0000] {logging_mixin.py:190} INFO - [2025-03-06T22:58:44.928+0000] {base.py:84} INFO - Retrieving connection 'snowflake_conn'
[2025-03-06T22:58:44.929+0000] {logging_mixin.py:190} INFO - [2025-03-06T22:58:44.929+0000] {connection.py:413} INFO - Snowflake Connector for Python Version: 3.12.1, Python Version: 3.12.5, Platform: Linux-6.12.5-linuxkit-aarch64-with-glibc2.36
[2025-03-06T22:58:44.930+0000] {logging_mixin.py:190} INFO - [2025-03-06T22:58:44.930+0000] {connection.py:1196} INFO - Connecting to GLOBAL Snowflake domain
[2025-03-06T22:58:44.930+0000] {logging_mixin.py:190} INFO - [2025-03-06T22:58:44.930+0000] {connection.py:1277} INFO - This connection is in OCSP Fail Open Mode. TLS Certificates would be checked for validity and revocation status. Any other Certificate Revocation related exceptions or OCSP Responder failures would be disregarded in favor of connectivity.
[2025-03-06T22:58:45.165+0000] {logging_mixin.py:190} INFO - [2025-03-06T22:58:45.163+0000] {dagbag.py:386} ERROR - Failed to import: /opt/airflow/dags/lab1_ETL.py
Traceback (most recent call last):
  File "/home/airflow/.local/lib/python3.12/site-packages/airflow/models/dagbag.py", line 382, in parse
    loader.exec_module(new_module)
  File "<frozen importlib._bootstrap_external>", line 995, in exec_module
  File "<frozen importlib._bootstrap>", line 488, in _call_with_frames_removed
  File "/opt/airflow/dags/lab1_ETL.py", line 86, in <module>
    cur = return_snowflake_conn()
          ^^^^^^^^^^^^^^^^^^^^^^^
  File "/opt/airflow/dags/lab1_ETL.py", line 16, in return_snowflake_conn
    conn = hook.get_conn()
           ^^^^^^^^^^^^^^^
  File "/home/airflow/.local/lib/python3.12/site-packages/airflow/providers/snowflake/hooks/snowflake.py", line 300, in get_conn
    conn = connector.connect(**conn_config)
           ^^^^^^^^^^^^^^^^^^^^^^^^^^^^^^^^
  File "/home/airflow/.local/lib/python3.12/site-packages/snowflake/connector/__init__.py", line 55, in Connect
    return SnowflakeConnection(**kwargs)
           ^^^^^^^^^^^^^^^^^^^^^^^^^^^^^
  File "/home/airflow/.local/lib/python3.12/site-packages/snowflake/connector/connection.py", line 456, in __init__
    self.connect(**kwargs)
  File "/home/airflow/.local/lib/python3.12/site-packages/snowflake/connector/connection.py", line 771, in connect
    self.__open_connection()
  File "/home/airflow/.local/lib/python3.12/site-packages/snowflake/connector/connection.py", line 1099, in __open_connection
    self.authenticate_with_retry(self.auth_class)
  File "/home/airflow/.local/lib/python3.12/site-packages/snowflake/connector/connection.py", line 1386, in authenticate_with_retry
    self._authenticate(auth_instance)
  File "/home/airflow/.local/lib/python3.12/site-packages/snowflake/connector/connection.py", line 1414, in _authenticate
    auth.authenticate(
  File "/home/airflow/.local/lib/python3.12/site-packages/snowflake/connector/auth/_auth.py", line 401, in authenticate
    Error.errorhandler_wrapper(
  File "/home/airflow/.local/lib/python3.12/site-packages/snowflake/connector/errors.py", line 284, in errorhandler_wrapper
    handed_over = Error.hand_to_other_handler(
                  ^^^^^^^^^^^^^^^^^^^^^^^^^^^^
  File "/home/airflow/.local/lib/python3.12/site-packages/snowflake/connector/errors.py", line 342, in hand_to_other_handler
    connection.errorhandler(connection, cursor, error_class, error_value)
  File "/home/airflow/.local/lib/python3.12/site-packages/snowflake/connector/errors.py", line 215, in default_errorhandler
    raise error_class(
snowflake.connector.errors.DatabaseError: 250001 (08001): None: Failed to connect to DB: wbb10936.snowflakecomputing.com:443. Your free trial has ended and all of your virtual warehouses have been suspended. Add billing information in the Snowflake web UI to continue using the full set of Snowflake features.
[2025-03-06T22:58:45.169+0000] {processor.py:927} WARNING - No viable dags retrieved from /opt/airflow/dags/lab1_ETL.py
[2025-03-06T22:58:45.181+0000] {processor.py:208} INFO - Processing /opt/airflow/dags/lab1_ETL.py took 0.355 seconds
[2025-03-06T22:59:15.550+0000] {processor.py:186} INFO - Started process (PID=593) to work on /opt/airflow/dags/lab1_ETL.py
[2025-03-06T22:59:15.551+0000] {processor.py:914} INFO - Processing file /opt/airflow/dags/lab1_ETL.py for tasks to queue
[2025-03-06T22:59:15.554+0000] {logging_mixin.py:190} INFO - [2025-03-06T22:59:15.554+0000] {dagbag.py:587} INFO - Filling up the DagBag from /opt/airflow/dags/lab1_ETL.py
[2025-03-06T22:59:15.650+0000] {logging_mixin.py:190} INFO - [2025-03-06T22:59:15.650+0000] {base.py:84} INFO - Retrieving connection 'snowflake_conn'
[2025-03-06T22:59:15.651+0000] {logging_mixin.py:190} INFO - [2025-03-06T22:59:15.651+0000] {connection.py:413} INFO - Snowflake Connector for Python Version: 3.12.1, Python Version: 3.12.5, Platform: Linux-6.12.5-linuxkit-aarch64-with-glibc2.36
[2025-03-06T22:59:15.651+0000] {logging_mixin.py:190} INFO - [2025-03-06T22:59:15.651+0000] {connection.py:1196} INFO - Connecting to GLOBAL Snowflake domain
[2025-03-06T22:59:15.652+0000] {logging_mixin.py:190} INFO - [2025-03-06T22:59:15.651+0000] {connection.py:1277} INFO - This connection is in OCSP Fail Open Mode. TLS Certificates would be checked for validity and revocation status. Any other Certificate Revocation related exceptions or OCSP Responder failures would be disregarded in favor of connectivity.
